Workbook

Sheet RATIOS
A1: RATIO AFLUENCIA/AFORO
C3: P2K | G3: PSP | K3: PRG | O3: PSI | S3: CBA | W3: PV | AA3: PLP
C4: 2024 | D4: 2025 | E4: 2026 | F4: DIF | G4: 2024 | H4: 2025 | I4: 2026 | J4: DIF | K4: 2024 | L4: 2025 | M4: 2026 | N4: DIF | O4: 2024 | P4: 2025 | Q4: 2026 | R4: DIF | S4: 2024 | T4: 2025 | U4: 2026 | V4: DIF | W4: 2024 | X4: 2025 | Y4: 2026 | Z4: DIF | AA4: 2024 | AB4: 2025 | AC4: 2026 | AD4: DIF
A6: ENE | C6: =(MENSUAL!$H$6/'[1]MENSUAL-2024'!$D$6) -> 2.7780385 | D6: =MENSUAL!$I$6/'[1]MENSUAL-2024'!$E$6 -> 2.8735858 | E6: =+MENSUAL!J6/AFORO!F6 -> 3.1739537 | F6: =E6/D6-1 -> 0.10452722 | G6: =MENSUAL!$P$6/'[1]MENSUAL-2024'!$I$6 -> 1.0981989 | H6: =MENSUAL!$Q$6/'[1]MENSUAL-2024'!$J$6 -> 1.1495867 | I6: =+MENSUAL!R6/AFORO!L6 -> 1.313595 | J6: =I6/H6-1 -> 0.14266726 | K6: =MENSUAL!$X$6/'[1]MENSUAL-2024'!$N$6 -> 1.5068248 | L6: =MENSUAL!$Y$6/'[1]MENSUAL-2024'!$O$6 -> 1.9332573 | M6: =+MENSUAL!Z6/AFORO!R6 -> 1.5910389 | N6: =M6/L6-1 -> -0.17701649 | O6: =MENSUAL!$AF$6/'[1]MENSUAL-2024'!$X$6 -> 2.1438661 | P6: =MENSUAL!$AG$6/'[1]MENSUAL-2024'!$Y$6 -> 2.2655373 | Q6: =+MENSUAL!AH6/AFORO!AD6 -> 2.2176081 | R6: =Q6/P6-1 -> -0.021155776 | S6: =MENSUAL!$AM$6/'[1]MENSUAL-2024'!$AL$6 -> 3.1354664 | T6: =MENSUAL!$AN$6/'[1]MENSUAL-2024'!$AM$6 -> 3.3668127 | U6: =+MENSUAL!AO6/AFORO!AT6 -> 3.4446051 | V6: =U6/T6-1 -> 0.023105664 | W6: =MENSUAL!$AS$6/'[1]MENSUAL-2024'!$AQ$6 -> 1.705609 | X6: =MENSUAL!$AT$6/'[1]MENSUAL-2024'!$AR$6 -> 1.8352373 | Y6: =+MENSUAL!AU6/AFORO!AZ6 -> 2.0982848 | Z6: =Y6/X6-1 -> 0.14333156 | AA6: =MENSUAL!$BA$6/'[1]MENSUAL-2024'!$AV$6 -> 0.81230924 | AB6: =MENSUAL!$BB$6/'[1]MENSUAL-2024'!$AW$6 -> 0.92754009 | AC6: =+MENSUAL!BC6/AFORO!BF6 -> 0.88054874 | AD6: =AC6/AB6-1 -> -0.050662333
A7: FEB | C7: =(MENSUAL!$H$7/'[1]MENSUAL-2024'!$D$7) -> 2.6823571 | D7: =MENSUAL!$I$7/'[1]MENSUAL-2024'!$E$7 -> 3.1238057 | F7: =D7/C7-1 -> 0.16457486 | G7: =MENSUAL!$P$7/'[1]MENSUAL-2024'!$I$7 -> 1.0304674 | H7: =MENSUAL!$Q$7/'[1]MENSUAL-2024'!$J$7 -> 1.1340138 | J7: =H7/G7-1 -> 0.1004849 | K7: =MENSUAL!$X$7/'[1]MENSUAL-2024'!$N$7 -> 1.5206705 | L7: =MENSUAL!$Y$7/'[1]MENSUAL-2024'!$O$7 -> 1.9402605 | N7: =L7/K7-1 -> 0.27592435 | O7: =MENSUAL!$AF$7/'[1]MENSUAL-2024'!$X$7 -> 2.0693856 | P7: =MENSUAL!$AG$7/'[1]MENSUAL-2024'!$Y$7 -> 2.2441029 | R7: =P7/O7-1 -> 0.08442953 | S7: =MENSUAL!$AM$7/'[1]MENSUAL-2024'!$AL$7 -> 3.0047558 | T7: =MENSUAL!$AN$7/'[1]MENSUAL-2024'!$AM$7 -> 3.4026405 | V7: =T7/S7-1 -> 0.13241831 | W7: =MENSUAL!$AS$7/'[1]MENSUAL-2024'!$AQ$7 -> 1.6250605 | X7: =MENSUAL!$AT$7/'[1]MENSUAL-2024'!$AR$7 -> 1.8937259 | Z7: =X7/W7-1 -> 0.16532637 | AA7: =MENSUAL!$BA$7/'[1]MENSUAL-2024'!$AV$7 -> 1.0273944 | AB7: =MENSUAL!$BB$7/'[1]MENSUAL-2024'!$AW$7 -> 0.80901618 | AD7: =AB7/AA7-1 -> -0.21255538
A8: MAR | C8: =MENSUAL!$H$8/'[1]MENSUAL-2024'!$D$8 -> 2.6757449 | D8: =MENSUAL!I8/AFORO!E8 -> 3.0169947 | F8: =D8/C8-1 -> 0.12753447 | G8: =MENSUAL!$P$8/'[1]MENSUAL-2024'!$I$8 -> 1.165263 | H8: =MENSUAL!Q8/AFORO!K8 -> 1.1446136 | J8: =H8/G8-1 -> -0.017720779 | K8: =MENSUAL!$X$8/'[1]MENSUAL-2024'!$N$8 -> 1.5743067 | L8: =MENSUAL!Y8/AFORO!Q8 -> 1.6883697 | N8: =L8/K8-1 -> 0.072452811 | O8: =MENSUAL!$AF$8/'[1]MENSUAL-2024'!$X$8 -> 2.1880271 | P8: =MENSUAL!AG8/AFORO!AC8 -> 2.2337073 | R8: =P8/O8-1 -> 0.020877362 | S8: =MENSUAL!$AM$8/'[1]MENSUAL-2024'!$AL$8 -> 3.1900682 | T8: =MENSUAL!AN8/AFORO!AS8 -> 3.4627397 | V8: =T8/S8-1 -> 0.085475138 | W8: =MENSUAL!$AS$8/'[1]MENSUAL-2024'!$AQ$8 -> 1.8773154 | X8: =MENSUAL!AT8/AFORO!AY8 -> 2.0671164 | Z8: =X8/W8-1 -> 0.10110239 | AA8: =MENSUAL!$BA$8/'[1]MENSUAL-2024'!$AV$8 -> 1.117771 | AB8: =MENSUAL!BB8/AFORO!BE8 -> 0.97608151 | AD8: =AB8/AA8-1 -> -0.12676076
A9: ABR | C9: =MENSUAL!$H$9/'[1]MENSUAL-2024'!$D$9 -> 2.7491254 | D9: =MENSUAL!I9/AFORO!E9 -> 3.2902019 | F9: =D9/C9-1 -> 0.19681768 | G9: =MENSUAL!$P$9/'[1]MENSUAL-2024'!$I$9 -> 1.06028 | H9: =MENSUAL!Q9/AFORO!K9 -> 1.2666047 | J9: =H9/G9-1 -> 0.1945946 | K9: =MENSUAL!$X$9/'[1]MENSUAL-2024'!$N$9 -> 1.5417966 | L9: =MENSUAL!Y9/AFORO!Q9 -> 1.9981712 | N9: =L9/K9-1 -> 0.29600185 | O9: =MENSUAL!$AF$9/'[1]MENSUAL-2024'!$X$9 -> 2.0888667 | P9: =MENSUAL!AG9/AFORO!AC9 -> 2.3099527 | R9: =P9/O9-1 -> 0.10584014 | S9: =MENSUAL!$AM$9/'[1]MENSUAL-2024'!$AL$9 -> 3.0249723 | T9: =MENSUAL!AN9/AFORO!AS9 -> 3.5237853 | V9: =T9/S9-1 -> 0.16489838 | W9: =MENSUAL!$AS$9/'[1]MENSUAL-2024'!$AQ$9 -> 1.789389 | X9: =MENSUAL!AT9/AFORO!AY9 -> 2.0144171 | Z9: =X9/W9-1 -> 0.12575695 | AA9: =MENSUAL!$BA$9/'[1]MENSUAL-2024'!$AV$9 -> 1.2291999 | AB9: =MENSUAL!BB9/AFORO!BE9 -> 1.0313924 | AD9: =AB9/AA9-1 -> -0.16092384
A10: MAY | C10: =MENSUAL!$H$10/'[1]MENSUAL-2024'!$D$10 -> 2.7030321 | D10: =MENSUAL!I10/AFORO!E10 -> 2.7071137 | F10: =D10/C10-1 -> 0.0015100251 | G10: =MENSUAL!$P$10/'[1]MENSUAL-2024'!$I$10 -> 1.0493193 | H10: =MENSUAL!Q10/AFORO!K10 -> 1.2908736 | J10: =H10/G10-1 -> 0.23020088 | K10: =MENSUAL!$X$10/'[1]MENSUAL-2024'!$N$10 -> 1.5461314 | L10: =MENSUAL!Y10/AFORO!Q10 -> 1.7683979 | N10: =L10/K10-1 -> 0.14375659 | O10: =MENSUAL!$AF$10/'[1]MENSUAL-2024'!$X$10 -> 2.1302378 | P10: =MENSUAL!AG10/AFORO!AC10 -> 2.2929428 | R10: =P10/O10-1 -> 0.076378821 | S10: =MENSUAL!$AM$10/'[1]MENSUAL-2024'!$AL$10 -> 2.9169726 | T10: =MENSUAL!AN10/AFORO!AS10 -> 3.3195747 | V10: =T10/S10-1 -> 0.1380205 | W10: =MENSUAL!$AS$10/'[1]MENSUAL-2024'!$AQ$10 -> 1.7244302 | X10: =MENSUAL!AT10/AFORO!AY10 -> 1.9797484 | Z10: =X10/W10-1 -> 0.14805948 | AA10: =MENSUAL!$BA$10/'[1]MENSUAL-2024'!$AV$10 -> 1.2592012 | AB10: =MENSUAL!BB10/AFORO!BE10 -> 0.98409918 | AD10: =AB10/AA10-1 -> -0.21847347
A11: JUN | C11: =MENSUAL!$H$11/'[1]MENSUAL-2024'!$D$11 -> 2.787661 | D11: =MENSUAL!I11/AFORO!E11 -> 2.9251827 | F11: =D11/C11-1 -> 0.049332288 | G11: =MENSUAL!$P$11/'[1]MENSUAL-2024'!$I$11 -> 1.1815229 | H11: =MENSUAL!Q11/AFORO!K11 -> 1.3002543 | J11: =H11/G11-1 -> 0.10049008 | K11: =MENSUAL!$X$11/'[1]MENSUAL-2024'!$N$11 -> 1.6986125 | L11: =MENSUAL!Y11/AFORO!Q11 -> 1.563779 | N11: =L11/K11-1 -> -0.079378588 | O11: =MENSUAL!$AF$11/'[1]MENSUAL-2024'!$X$11 -> 2.2865388 | P11: =MENSUAL!AG11/AFORO!AC11 -> 2.2527884 | R11: =P11/O11-1 -> -0.014760475 | S11: =MENSUAL!$AM$11/'[1]MENSUAL-2024'!$AL$11 -> 2.9347264 | T11: =MENSUAL!AN11/AFORO!AS11 -> 3.318187 | V11: =T11/S11-1 -> 0.13066317 | W11: =MENSUAL!$AS$11/'[1]MENSUAL-2024'!$AQ$11 -> 1.8141248 | X11: =MENSUAL!AT11/AFORO!AY11 -> 1.9911495 | Z11: =X11/W11-1 -> 0.097581321 | AA11: =MENSUAL!$BA$11/'[1]MENSUAL-2024'!$AV$11 -> 1.1489434 | AB11: =MENSUAL!BB11/AFORO!BE11 -> 1.0303691 | AD11: =AB11/AA11-1 -> -0.10320288
A12: JUL | C12: =MENSUAL!$H$12/'[1]MENSUAL-2024'!$D$12 -> 2.6571551 | D12: =MENSUAL!I12/AFORO!E12 -> 2.8466892 | F12: =D12/C12-1 -> 0.071329722 | G12: =MENSUAL!$P$12/'[1]MENSUAL-2024'!$I$12 -> 1.1695498 | H12: =MENSUAL!Q12/AFORO!K12 -> 1.3485234 | J12: =H12/G12-1 -> 0.15302776 | K12: =MENSUAL!$X$12/'[1]MENSUAL-2024'!$N$12 -> 1.6378655 | L12: =MENSUAL!Y12/AFORO!Q12 -> 1.6251929 | N12: =L12/K12-1 -> -0.0077372385 | O12: =MENSUAL!$AF$12/'[1]MENSUAL-2024'!$X$12 -> 2.899696 | P12: =MENSUAL!AG12/AFORO!AC12 -> 2.3444732 | R12: =P12/O12-1 -> -0.19147624 | S12: =MENSUAL!$AM$12/'[1]MENSUAL-2024'!$AL$12 -> 3.0067047 | T12: =MENSUAL!AN12/AFORO!AS12 -> 3.4788031 | V12: =T12/S12-1 -> 0.15701523 | W12: =MENSUAL!$AS$12/'[1]MENSUAL-2024'!$AQ$12 -> 1.8863506 | X12: =MENSUAL!AT12/AFORO!AY12 -> 2.0003235 | Z12: =X12/W12-1 -> 0.060419796 | AA12: =MENSUAL!$BA$12/'[1]MENSUAL-2024'!$AV$12 -> 0.94272457 | AB12: =MENSUAL!BB12/AFORO!BE12 -> 0.97803239 | AD12: =AB12/AA12-1 -> 0.037452953
A13: AGO | C13: =MENSUAL!$H$13/'[1]MENSUAL-2024'!$D$14 -> 2.932543 | D13: =MENSUAL!I13/AFORO!E13 -> 2.9638473 | F13: =D13/C13-1 -> 0.010674818 | G13: =MENSUAL!$P$13/'[1]MENSUAL-2024'!$I$13 -> 1.1851075 | H13: =MENSUAL!Q13/AFORO!K13 -> 1.3101684 | J13: =H13/G13-1 -> 0.10552703 | K13: =MENSUAL!$X$13/'[1]MENSUAL-2024'!$N$13 -> 1.6160784 | L13: =MENSUAL!Y13/AFORO!Q13 -> 1.6882075 | N13: =L13/K13-1 -> 0.044632151 | O13: =MENSUAL!$AF$13/'[1]MENSUAL-2024'!$X$13 -> 2.3241897 | P13: =MENSUAL!AG13/AFORO!AC13 -> 2.3945898 | R13: =P13/O13-1 -> 0.030290158 | S13: =MENSUAL!$AM$13/'[1]MENSUAL-2024'!$AL$13 -> 3.018169 | T13: =MENSUAL!AN13/AFORO!AS13 -> 3.5783939 | V13: =T13/S13-1 -> 0.18561746 | W13: =MENSUAL!$AS$13/'[1]MENSUAL-2024'!$AQ$13 -> 1.8057265 | X13: =MENSUAL!AT13/AFORO!AY13 -> 2.0064226 | Z13: =X13/W13-1 -> 0.11114426 | AA13: =MENSUAL!$BA$13/'[1]MENSUAL-2024'!$AV$13 -> 1.2211084 | AB13: =MENSUAL!BB13/AFORO!BE13 -> 0.9530729 | AD13: =AB13/AA13-1 -> -0.21950183
A14: SEP | C14: =MENSUAL!$H$14/'[1]MENSUAL-2024'!$D$14 -> 2.6660735 | D14: =MENSUAL!I14/AFORO!E14 -> 2.8438276 | F14: =D14/C14-1 -> 0.066672629 | G14: =MENSUAL!$P$14/'[1]MENSUAL-2024'!$I$14 -> 1.109726 | H14: =MENSUAL!Q14/AFORO!K14 -> 1.1759995 | J14: =H14/G14-1 -> 0.059720585 | K14: =MENSUAL!$X$14/'[1]MENSUAL-2024'!$N$14 -> 1.7229801 | L14: =MENSUAL!Y14/AFORO!Q14 -> 1.5782449 | N14: =L14/K14-1 -> -0.084002813 | O14: =MENSUAL!$AF$14/'[1]MENSUAL-2024'!$X$14 -> 2.2209218 | P14: =MENSUAL!AG14/AFORO!AC14 -> 2.2584476 | R14: =P14/O14-1 -> 0.016896514 | S14: =MENSUAL!$AM$14/'[1]MENSUAL-2024'!$AL$14 -> 3.2453252 | T14: =MENSUAL!AN14/AFORO!AS14 -> 3.3775288 | V14: =T14/S14-1 -> 0.040736632 | W14: =MENSUAL!$AS$14/'[1]MENSUAL-2024'!$AQ$14 -> 1.8316138 | X14: =MENSUAL!AT14/AFORO!AY14 -> 1.9218014 | Z14: =X14/W14-1 -> 0.049239431 | AA14: =MENSUAL!$BA$14/'[1]MENSUAL-2024'!$AV$14 -> 1.0871905 | AB14: =MENSUAL!BB14/AFORO!BE14 -> 0.93556926 | AD14: =AB14/AA14-1 -> -0.13946151
A15: OCT | C15: =MENSUAL!$H$15/'[1]MENSUAL-2024'!$D$15 -> 2.7062841 | D15: =MENSUAL!I15/AFORO!E15 -> 2.9580996 | F15: =D15/C15-1 -> 0.09304845 | G15: =MENSUAL!$P$15/'[1]MENSUAL-2024'!$I$15 -> 1.0432223 | H15: =MENSUAL!Q15/AFORO!K15 -> 1.0924357 | J15: =H15/G15-1 -> 0.047174368 | K15: =MENSUAL!$X$15/'[1]MENSUAL-2024'!$N$15 -> 1.8129288 | L15: =MENSUAL!Y15/AFORO!Q15 -> 1.6006642 | N15: =L15/K15-1 -> -0.11708378 | O15: =MENSUAL!$AF$15/'[1]MENSUAL-2024'!$X$15 -> 2.2095707 | P15: =MENSUAL!AG15/AFORO!AC15 -> 2.2851388 | R15: =P15/O15-1 -> 0.034200364 | S15: =MENSUAL!$AM$15/'[1]MENSUAL-2024'!$AL$15 -> 3.2632762 | T15: =MENSUAL!AN15/AFORO!AS15 -> 3.3984458 | V15: =T15/S15-1 -> 0.041421459 | W15: =MENSUAL!$AS$15/'[1]MENSUAL-2024'!$AQ$15 -> 1.8836337 | X15: =MENSUAL!AT15/AFORO!AY15 -> 1.9120056 | Z15: =X15/W15-1 -> 0.015062288 | AA15: =MENSUAL!$BA$15/'[1]MENSUAL-2024'!$AV$15 -> 1.094872 | AB15: =MENSUAL!BB15/AFORO!BE15 -> 0.87440514 | AD15: =AB15/AA15-1 -> -0.2013631
A16: NOV | C16: =MENSUAL!$H$16/'[1]MENSUAL-2024'!$D$16 -> 3.0268557 | D16: =MENSUAL!I16/AFORO!E16 -> 2.9147515 | F16: =D16/C16-1 -> -0.037036536 | G16: =MENSUAL!$P$16/'[1]MENSUAL-2024'!$I$16 -> 1.1436608 | H16: =MENSUAL!Q16/AFORO!K16 -> 1.1536919 | J16: =H16/G16-1 -> 0.0087710497 | K16: =MENSUAL!$X$16/'[1]MENSUAL-2024'!$N$16 -> 1.7208682 | L16: =MENSUAL!Y16/AFORO!Q16 -> 1.6544535 | N16: =L16/K16-1 -> -0.038593745 | O16: =MENSUAL!$AF$16/'[1]MENSUAL-2024'!$X$16 -> 2.3186709 | P16: =MENSUAL!AG16/AFORO!AC16 -> 2.5543829 | R16: =P16/O16-1 -> 0.10165824 | S16: =MENSUAL!$AM$16/'[1]MENSUAL-2024'!$AL$16 -> 3.4958065 | T16: =MENSUAL!AN16/AFORO!AS16 -> 3.5950588 | V16: =T16/S16-1 -> 0.028391818 | W16: =MENSUAL!$AS$16/'[1]MENSUAL-2024'!$AQ$16 -> 1.8463398 | X16: =MENSUAL!AT16/AFORO!AY16 -> 2.0025941 | Z16: =X16/W16-1 -> 0.084629236 | AA16: =MENSUAL!$BA$16/'[1]MENSUAL-2024'!$AV$16 -> 0.95253934 | AB16: =MENSUAL!BB16/AFORO!BE16 -> 0.88865629 | AD16: =AB16/AA16-1 -> -0.067066048
A17: DIC | C17: =MENSUAL!$H$17/'[1]MENSUAL-2024'!$D$17 -> 3.140462 | D17: =MENSUAL!I17/AFORO!E17 -> 3.3962103 | F17: =D17/C17-1 -> 0.081436553 | G17: =MENSUAL!$P$17/'[1]MENSUAL-2024'!$I$17 -> 1.2600062 | H17: =MENSUAL!Q17/AFORO!K17 -> 1.3274247 | J17: =H17/G17-1 -> 0.053506465 | K17: =MENSUAL!$X$17/'[1]MENSUAL-2024'!$N$17 -> 1.8430838 | L17: =MENSUAL!Y17/AFORO!Q17 -> 1.7466339 | N17: =L17/K17-1 -> -0.052330674 | O17: =MENSUAL!$AF$17/'[1]MENSUAL-2024'!$X$17 -> 2.5100323 | P17: =MENSUAL!AG17/AFORO!AC17 -> 2.3417068 | R17: =P17/O17-1 -> -0.067061111 | S17: =MENSUAL!$AM$17/'[1]MENSUAL-2024'!$AL$17 -> 3.53438 | T17: =MENSUAL!AN17/AFORO!AS17 -> 3.5727523 | V17: =T17/S17-1 -> 0.010856871 | W17: =MENSUAL!$AS$17/'[1]MENSUAL-2024'!$AQ$17 -> 1.9875725 | X17: =MENSUAL!AT17/AFORO!AY17 -> 2.1748499 | Z17: =X17/W17-1 -> 0.094224202 | AA17: =MENSUAL!$BA$17/'[1]MENSUAL-2024'!$AV$17 -> 1.0652892 | AB17: =MENSUAL!BB17/AFORO!BE17 -> 0.96426873 | AD17: =AB17/AA17-1 -> -0.094829114
A18: Prom U12M | C18: 2.98 | D18: 2.99 | G18: 1.21 | H18: 1.22 | K18: 1.77 | L18: 1.77 | O18: 2.3 | P18: 2.3 | S18: 3.43 | T18: 3.43 | W18: 1.95 | X18: 1.95 | AA18: 0.98 | AB18: 0.98

Sheet SEMANAL-2026
B1: AFLUENCIA PLAZAS
B3: FECHA | C3: SEM | D3: P2K | I3: PSP | N3: PRG | S3: PSI | X3: CBA | AC3: PV | AH3: PLP | AM3: SUMA
D4: 2023 | E4: 2024 | F4: 2025 | G4: 2026 | H4: %Dif | I4: 2023 | J4: 2024 | K4: 2025 | L4: 2026 | M4: %Dif | N4: 2023 | O4: 2024 | P4: 2025 | Q4: 2026 | R4: %Dif | S4: 2023 | T4: 2024 | U4: 2025 | V4: 2026 | W4: %Dif | X4: 2023 | Y4: 2024 | Z4: 2025 | AA4: 2026 | AB4: %Dif | AC4: 2023 | AD4: 2024 | AE4: 2025 | AF4: 2026 | AG4: %Dif | AH4: 2023 | AI4: 2024 | AJ4: 2025 | AK4: 2026 | AL4: %Dif | AM4: 2023 | AN4: 2024 | AO4: 2025 | AP4: 2026 | AQ4: %Dif S.A.
B6: 46026 | C6: 1 | D6: 167896 | E6: 156713 | F6: 178990 | G6: 180807 | H6: =G6/F6-1 -> 0.010151405 | I6: 60260 | J6: 52568 | K6: 60929 | L6: 63348 | M6: =L6/K6-1 -> 0.039701948 | N6: 70982 | O6: 64851 | P6: 75352 | Q6: 65955 | R6: =Q6/P6-1 -> -0.12470804 | S6: 50247 | T6: 53269 | U6: 55379 | V6: 50662 | W6: =V6/U6-1 -> -0.085176692 | X6: 87311 | Y6: 99648 | Z6: 111930 | AA6: 123601 | AB6: =AA6/Z6-1 -> 0.10427053 | AC6: 41218 | AD6: 42258 | AE6: 50572 | AF6: 45373 | AG6: =AF6/AE6-1 -> -0.10280392 | AH6: 39524 | AI6: 40129 | AJ6: 36900 | AK6: 35281 | AL6: =AK6/AJ6-1 -> -0.043875339 | AM6: =D6+I6+N6+S6+X6+AC6+AH6 -> 517438 | AN6: =E6+J6+O6+T6+Y6+AD6+AI6 -> 509436 | AO6: =F6+K6+P6+U6+Z6+AE6+AJ6 -> 570052 | AP6: =G6+L6+Q6+V6+AA6+AF6+AK6 -> 565027 | AQ6: =AP6/AO6-1 -> -0.0088149853
B7: 46033 | C7: 2 | D7: 182118 | E7: 163645 | F7: 172033 | G7: 167972 | H7: =G7/F7-1 -> -0.023605936 | I7: 56811 | J7: 50737 | K7: 53401 | L7: 58801 | M7: =L7/K7-1 -> 0.1011217 | N7: 68752 | O7: 70867 | P7: 67435 | Q7: 63093 | R7: =Q7/P7-1 -> -0.064387929 | S7: 54534 | T7: 53623 | U7: 47649 | V7: 46077 | W7: =V7/U7-1 -> -0.032991249 | X7: 101582 | Y7: 100879 | Z7: 108059 | AA7: 117305 | AB7: =AA7/Z7-1 -> 0.085564368 | AC7: 43464 | AD7: 43739 | AE7: 46133 | AF7: 45455 | AG7: =AF7/AE7-1 -> -0.014696638 | AH7: 37832 | AI7: 40695 | AJ7: 38776 | AK7: 38677 | AL7: =AK7/AJ7-1 -> -0.0025531256 | AM7: =D7+I7+N7+S7+X7+AC7+AH7 -> 545093 | AN7: =E7+J7+O7+T7+Y7+AD7+AI7 -> 524185 | AO7: =F7+K7+P7+U7+Z7+AE7+AJ7 -> 533486 | AP7: =G7+L7+Q7+V7+AA7+AF7+AK7 -> 537380 | AQ7: =AP7/AO7-1 -> 0.0072991606
B8: 46040 | C8: 3 | D8: 182798 | E8: 156581 | F8: 168260 | G8: 169726 | H8: =G8/F8-1 -> 0.0087127065 | I8: 55380 | J8: 49255 | K8: 49952 | L8: 59166 | M8: =L8/K8-1 -> 0.18445708 | N8: 72416 | O8: 64457 | P8: 57657 | Q8: 56771 | R8: =Q8/P8-1 -> -0.015366738 | S8: 53307 | T8: 58480 | U8: 50457 | V8: 47828 | W8: =V8/U8-1 -> -0.052103772 | X8: 102396 | Y8: 98887 | Z8: 110990 | AA8: 116809 | AB8: =AA8/Z8-1 -> 0.052428147 | AC8: 42136 | AD8: 41858 | AE8: 47375 | AF8: 47941 | AG8: =AF8/AE8-1 -> 0.01194723 | AH8: 37792 | AI8: 41769 | AJ8: 40246 | AK8: 37047 | AL8: =AK8/AJ8-1 -> -0.07948616 | AM8: =D8+I8+N8+S8+X8+AC8+AH8 -> 546225 | AN8: =E8+J8+O8+T8+Y8+AD8+AI8 -> 511287 | AO8: =F8+K8+P8+U8+Z8+AE8+AJ8 -> 524937 | AP8: =G8+L8+Q8+V8+AA8+AF8+AK8 -> 535288 | AQ8: =AP8/AO8-1 -> 0.019718557
B9: 46047 | C9: 4 | D9: 201189 | E9: 158722 | F9: 165512 | G9: 166083 | H9: =G9/F9-1 -> 0.0034499009 | I9: 53718 | J9: 55398 | K9: 49739 | L9: 58232 | M9: =L9/K9-1 -> 0.17075132 | N9: 71461 | O9: 61952 | P9: 59251 | Q9: 51245 | R9: =Q9/P9-1 -> -0.13512008 | S9: 49593 | T9: 54477 | U9: 48530 | V9: 45368 | W9: =V9/U9-1 -> -0.065155574 | X9: 97977 | Y9: 97913 | Z9: 108702 | AA9: 110237 | AB9: =AA9/Z9-1 -> 0.014121175 | AC9: 40952 | AD9: 44641 | AE9: 42077 | AF9: 51447 | AG9: =AF9/AE9-1 -> 0.22268698 | AH9: 36897 | AI9: 38283 | AJ9: 36849 | AK9: 35584 | AL9: =AK9/AJ9-1 -> -0.03432929 | AM9: =D9+I9+N9+S9+X9+AC9+AH9 -> 551787 | AN9: =E9+J9+O9+T9+Y9+AD9+AI9 -> 511386 | AO9: =F9+K9+P9+U9+Z9+AE9+AJ9 -> 510660 | AP9: =G9+L9+Q9+V9+AA9+AF9+AK9 -> 518196 | AQ9: =AP9/AO9-1 -> 0.014757373
B10: 46054 | C10: 5 | D10: 195691 | E10: 158722 | F10: 180664 | G10: 165406 | H10: =G10/F10-1 -> -0.084455121 | I10: 51778 | J10: 49065 | K10: 50801 | L10: 57033 | M10: =L10/K10-1 -> 0.12267475 | N10: 69228 | O10: 64018 | P10: 59887 | Q10: 55468 | R10: =Q10/P10-1 -> -0.073788969 | S10: 54354 | T10: 56372 | U10: 48431 | V10: 44635 | W10: =V10/U10-1 -> -0.07837955 | X10: 97189 | Y10: 94631 | Z10: 109219 | AA10: 108222 | AB10: =AA10/Z10-1 -> -0.0091284483 | AC10: 39324 | AD10: 42655 | AE10: 51447 | AF10: 50295 | AG10: =AF10/AE10-1 -> -0.022391976 | AH10: 38692 | AI10: 42402 | AJ10: 37812 | AK10: 36863 | AL10: =AK10/AJ10-1 -> -0.025097853 | AM10: =D10+I10+N10+S10+X10+AC10+AH10 -> 546256 | AN10: =E10+J10+O10+T10+Y10+AD10+AI10 -> 507865 | AO10: =F10+K10+P10+U10+Z10+AE10+AJ10 -> 538261 | AP10: =G10+L10+Q10+V10+AA10+AF10+AK10 -> 517922 | AQ10: =AP10/AO10-1 -> -0.037786501
B11: 46061 | C11: 6 | D11: 214925 | E11: 158830 | F11: 199855 | G11: 175760 | H11: =G11/F11-1 -> -0.12056241 | I11: 50148 | J11: 46655 | K11: 50394 | L11: 56767 | M11: =L11/K11-1 -> 0.12646347 | N11: 74275 | O11: 64287 | P11: 59644 | Q11: 56054 | R11: =Q11/P11-1 -> -0.060190463 | S11: 50587 | T11: 57650 | U11: 52970 | V11: 49916 | W11: =V11/U11-1 -> -0.057655277 | X11: 97495 | Y11: 98349 | Z11: 112307 | AA11: 109388 | AB11: =AA11/Z11-1 -> -0.025991256 | AC11: 41374 | AD11: 44243 | AE11: 49578 | AF11: 51418 | AG11: =AF11/AE11-1 -> 0.037113236 | AH11: 37078 | AI11: 39447 | AJ11: 36315 | AK11: 34864 | AL11: =AK11/AJ11-1 -> -0.039955941 | AM11: =D11+I11+N11+S11+X11+AC11+AH11 -> 565882 | AN11: =E11+J11+O11+T11+Y11+AD11+AI11 -> 509461 | AO11: =F11+K11+P11+U11+Z11+AE11+AJ11 -> 561063 | AP11: =G11+L11+Q11+V11+AA11+AF11+AK11 -> 534167 | AQ11: =AP11/AO11-1 -> -0.047937576
B12: 46068 | C12: 7 | D12: 209579 | E12: 168886 | F12: 212525 | G12: 170738 | H12: =G12/F12-1 -> -0.19662157 | I12: 58145 | J12: 54906 | K12: 59965 | L12: 63442 | M12: =L12/K12-1 -> 0.057983824 | N12: 70539 | O12: 74269 | P12: 68212 | Q12: 62893 | R12: =Q12/P12-1 -> -0.077977482 | S12: 59010 | T12: 63258 | U12: 56488 | V12: 51117 | W12: =V12/U12-1 -> -0.095082141 | X12: 103392 | Y12: 104168 | Z12: 127665 | AA12: 125508 | AB12: =AA12/Z12-1 -> -0.016895782 | AC12: 44140 | AD12: 39760 | AE12: 55843 | AF12: 58171 | AG12: =AF12/AE12-1 -> 0.041688305 | AH12: 37956 | AI12: 39154 | AJ12: 34962 | AK12: 35842 | AL12: =AK12/AJ12-1 -> 0.025170185 | AM12: =D12+I12+N12+S12+X12+AC12+AH12 -> 582761 | AN12: =E12+J12+O12+T12+Y12+AD12+AI12 -> 544401 | AO12: =F12+K12+P12+U12+Z12+AE12+AJ12 -> 615660 | AP12: =G12+L12+Q12+V12+AA12+AF12+AK12 -> 567711 | AQ12: =AP12/AO12-1 -> -0.077882273
B13: 46075 | C13: 8 | D13: 174459 | E13: 164125 | F13: 172613 | G13: 133616 | H13: =G13/F13-1 -> -0.22592157 | I13: 52625 | J13: 52261 | K13: 49516 | L13: 50710 | M13: =L13/K13-1 -> 0.024113418 | N13: 61214 | O13: 71690 | P13: 61705 | Q13: 46809 | R13: =Q13/P13-1 -> -0.24140669 | S13: 50475 | T13: 52261 | U13: 48399 | V13: 47029 | W13: =V13/U13-1 -> -0.02830637 | X13: 99088 | Y13: 93310 | Z13: 103623 | AA13: 106667 | AB13: =AA13/Z13-1 -> 0.029375718 | AC13: 44783 | AD13: 42727 | AE13: 47610 | AF13: 51907 | AG13: =AF13/AE13-1 -> 0.090254148 | AH13: 34804 | AI13: 39242 | AJ13: 32928 | AK13: 32418 | AL13: =AK13/AJ13-1 -> -0.015488338 | AM13: =D13+I13+N13+S13+X13+AC13+AH13 -> 517448 | AN13: =E13+J13+O13+T13+Y13+AD13+AI13 -> 515616 | AO13: =F13+K13+P13+U13+Z13+AE13+AJ13 -> 516394 | AP13: =G13+L13+Q13+V13+AA13+AF13+AK13 -> 469156 | AQ13: =AP13/AO13-1 -> -0.091476663
B14: 46082 | C14: 9 | D14: 154577 | E14: 166481 | F14: 170684 | G14: 156918 | H14: =G14/F14-1 -> -0.080651965 | I14: 53016 | J14: 50353 | K14: 50101 | L14: 54890 | M14: =L14/K14-1 -> 0.095586914 | N14: 59870 | O14: 68194 | P14: 58939 | Q14: 54378 | R14: =Q14/P14-1 -> -0.077385093 | S14: 56456 | T14: 57345 | U14: 49914 | V14: 47031 | W14: =V14/U14-1 -> -0.057759346 | X14: 103334 | Y14: 92366 | Z14: 110513 | AA14: 108905 | AB14: =AA14/Z14-1 -> -0.014550324 | AC14: 37978 | AD14: 44487 | AE14: 51917 | AF14: 55918 | AG14: =AF14/AE14-1 -> 0.077065316 | AH14: 39522 | AI14: 43111 | AJ14: 35860 | AK14: 34526 | AL14: =AK14/AJ14-1 -> -0.037200223 | AM14: =D14+I14+N14+S14+X14+AC14+AH14 -> 504753 | AN14: =E14+J14+O14+T14+Y14+AD14+AI14 -> 522337 | AO14: =F14+K14+P14+U14+Z14+AE14+AJ14 -> 527928 | AP14: =G14+L14+Q14+V14+AA14+AF14+AK14 -> 512566 | AQ14: =AP14/AO14-1 -> -0.029098665
B15: 46089 | C15: 10 | D15: 194993 | E15: 155032 | F15: 169280 | G15: 163282 | H15: =G15/F15-1 -> -0.03543242 | I15: 52474 | J15: 49374 | K15: 49513 | L15: 58001 | M15: =L15/K15-1 -> 0.17142973 | N15: 77148 | O15: 70168 | P15: 57896 | Q15: 56949 | R15: =Q15/P15-1 -> -0.016356916 | S15: 53709 | T15: 55362 | U15: 49380 | V15: 47139 | W15: =V15/U15-1 -> -0.045382746 | X15: 104277 | Y15: 93411 | Z15: 113847 | AA15: 108282 | AB15: =AA15/Z15-1 -> -0.048881393 | AC15: 44643 | AD15: 47284 | AE15: 46312 | AF15: 51567 | AG15: =AF15/AE15-1 -> 0.11346951 | AH15: 38404 | AI15: 42141 | AJ15: 36573 | AK15: 34858 | AL15: =AK15/AJ15-1 -> -0.046892516 | AM15: =D15+I15+N15+S15+X15+AC15+AH15 -> 565648 | AN15: =E15+J15+O15+T15+Y15+AD15+AI15 -> 512772 | AO15: =F15+K15+P15+U15+Z15+AE15+AJ15 -> 522801 | AP15: =G15+L15+Q15+V15+AA15+AF15+AK15 -> 520078 | AQ15: =AP15/AO15-1 -> -0.0052084828
B16: 46096 | C16: 11 | D16: 196880 | E16: 154396 | F16: 172760 | G16: 162017 | H16: =G16/F16-1 -> -0.062184533 | I16: 52085 | J16: 50607 | K16: 50536 | L16: 58990 | M16: =L16/K16-1 -> 0.16728669 | N16: 84229 | O16: 74089 | P16: 55196 | Q16: 57937 | R16: =Q16/P16-1 -> 0.049659396 | S16: 55954 | T16: 56340 | U16: 48705 | V16: 45486 | W16: =V16/U16-1 -> -0.066091777 | X16: 98879 | Y16: 98082 | Z16: 109862 | AA16: 111976 | AB16: =AA16/Z16-1 -> 0.019242322 | AC16: 46516 | AD16: 39928 | AE16: 46284 | AF16: 51979 | AG16: =AF16/AE16-1 -> 0.12304468 | AH16: 39812 | AI16: 41601 | AJ16: 35967 | AK16: 34892 | AL16: =AK16/AJ16-1 -> -0.029888509 | AM16: =D16+I16+N16+S16+X16+AC16+AH16 -> 574355 | AN16: =E16+J16+O16+T16+Y16+AD16+AI16 -> 515043 | AO16: =F16+K16+P16+U16+Z16+AE16+AJ16 -> 519310 | AP16: =G16+L16+Q16+V16+AA16+AF16+AK16 -> 523277 | AQ16: =AP16/AO16-1 -> 0.0076389825
B17: 46103 | C17: 12 | D17: 201163 | E17: 148847 | F17: 190380 | G17: 169947 | H17: =G17/F17-1 -> -0.10732745 | I17: 54203 | J17: 55338 | K17: 53727 | L17: 63438 | M17: =L17/K17-1 -> 0.18074711 | N17: 82743 | O17: 72295 | P17: 54348 | Q17: 62342 | R17: =Q17/P17-1 -> 0.14708913 | S17: 53632 | T17: 57308 | U17: 51854 | V17: 49080 | W17: =V17/U17-1 -> -0.053496355 | X17: 96243 | Y17: 94449 | Z17: 116137 | AA17: 119670 | AB17: =AA17/Z17-1 -> 0.030420968 | AC17: 42543 | AD17: 43900 | AE17: 58882 | AF17: 55265 | AG17: =AF17/AE17-1 -> -0.061427941 | AH17: 37937 | AI17: 37493 | AJ17: 36352 | AK17: 35129 | AL17: =AK17/AJ17-1 -> -0.033643266 | AM17: =D17+I17+N17+S17+X17+AC17+AH17 -> 568464 | AN17: =E17+J17+O17+T17+Y17+AD17+AI17 -> 509630 | AO17: =F17+K17+P17+U17+Z17+AE17+AJ17 -> 561680 | AP17: =G17+L17+Q17+V17+AA17+AF17+AK17 -> 554871 | AQ17: =AP17/AO17-1 -> -0.012122561
B18: 46110 | C18: 13 | D18: 157801 | E18: 166224 | F18: 192543 | G18: 159417 | H18: =G18/F18-1 -> -0.17204469 | I18: 53332 | J18: 57206 | K18: 49058 | L18: 58644 | M18: =L18/K18-1 -> 0.19540136 | N18: 80144 | O18: 73773 | P18: 54818 | Q18: 58237 | R18: =Q18/P18-1 -> 0.062370024 | S18: 54650 | T18: 59149 | U18: 48664 | V18: 42504 | W18: =V18/U18-1 -> -0.12658228 | X18: 109826 | Y18: 98350 | Z18: 115422 | AA18: 113869 | AB18: =AA18/Z18-1 -> -0.013454974 | AC18: 44700 | AD18: 44390 | AE18: 56920 | AF18: 51056 | AG18: =AF18/AE18-1 -> -0.10302178 | AH18: 39481 | AI18: 34409 | AJ18: 37209 | AK18: 36115 | AL18: =AK18/AJ18-1 -> -0.029401489 | AM18: =D18+I18+N18+S18+X18+AC18+AH18 -> 539934 | AN18: =E18+J18+O18+T18+Y18+AD18+AI18 -> 533501 | AO18: =F18+K18+P18+U18+Z18+AE18+AJ18 -> 554634 | AP18: =AK18+AF18+AA18+V18+Q18+L18+G18 -> 519842 | AQ18: =AP18/AO18-1 -> -0.062729656
B19: 46117 | C19: 14 | D19: 183755 | E19: 167291 | F19: 209861 | G19: 187065 | H19: =G19/F19-1 -> -0.10862428 | I19: 78617 | J19: 54500 | K19: 60025 | L19: 83624 | M19: =L19/K19-1 -> 0.39315285 | N19: 88711 | O19: 72013 | P19: 65713 | Q19: 73160 | R19: =Q19/P19-1 -> 0.11332613 | S19: 61543 | T19: 57675 | U19: 55841 | V19: 54418 | W19: =V19/U19-1 -> -0.025483068 | X19: 108540 | Y19: 98430 | Z19: 117214 | AA19: 110467 | AB19: =AA19/Z19-1 -> -0.057561383 | AC19: 51025 | AD19: 46846 | AE19: 61434 | AF19: 57334 | AG19: =AF19/AE19-1 -> -0.066738288 | AH19: 41136 | AI19: 37787 | AJ19: 40462 | AK19: 37183 | AL19: =AK19/AJ19-1 -> -0.081039 | AM19: =D19+I19+N19+S19+X19+AC19+AH19 -> 613327 | AN19: =E19+J19+O19+T19+Y19+AD19+AI19 -> 534542 | AO19: =F19+K19+P19+U19+Z19+AE19+AJ19 -> 610550 | AP19: =AK19+AF19+AA19+V19+Q19+L19+G19 -> 603251 | AQ19: =AP19/AO19-1 -> -0.011954795
B20: 46124 | C20: 15 | D20: 180647 | E20: 157056 | F20: 207732 | G20: 178570 | H20: =G20/F20-1 -> -0.1403828 | I20: 73811 | J20: 48685 | K20: 59030 | L20: 74992 | M20: =L20/K20-1 -> 0.27040488 | N20: 75561 | O20: 65724 | P20: 65639 | Q20: 64807 | R20: =Q20/P20-1 -> -0.012675391 | S20: 65087 | T20: 51648 | U20: 49330 | V20: 50130 | W20: =V20/U20-1 -> 0.016217312 | X20: 113820 | Y20: 99534 | Z20: 115999 | AA20: 117760 | AB20: =AA20/Z20-1 -> 0.015181165 | AC20: 53285 | AD20: 41617 | AE20: 58644 | AF20: 62006 | AG20: =AF20/AE20-1 -> 0.057328968 | AH20: 44449 | AI20: 34538 | AJ20: 42308 | AK20: 37451 | AL20: =AK20/AJ20-1 -> -0.11480098 | AM20: =D20+I20+N20+S20+X20+AC20+AH20 -> 606660 | AN20: =E20+J20+O20+T20+Y20+AD20+AI20 -> 498802 | AO20: =F20+K20+P20+U20+Z20+AE20+AJ20 -> 598682 | AP20: =AK20+AF20+AA20+V20+Q20+L20+G20 -> 585716 | AQ20: =AP20/AO20-1 -> -0.021657574
B21: 46131 | C21: 16 | D21: 166235 | E21: 159213 | F21: 233694 | G21: 170923 | H21: =G21/F21-1 -> -0.26860339 | I21: 58142 | J21: 47877 | K21: 61366 | L21: 60941 | M21: =L21/K21-1 -> -0.0069256592 | N21: 73748 | O21: 68291 | P21: 65699 | Q21: 61436 | R21: =Q21/P21-1 -> -0.064886832 | S21: 61693 | T21: 57439 | U21: 52648 | V21: 49889 | W21: =V21/U21-1 -> -0.05240465 | X21: 113224 | Y21: 103408 | Z21: 108262 | AA21: 122275 | AB21: =AA21/Z21-1 -> 0.129436 | AC21: 47907 | AD21: 42271 | AE21: 48150 | AF21: 53723 | AG21: =AF21/AE21-1 -> 0.11574247 | AH21: 40179 | AI21: 38288 | AJ21: 36130 | AK21: 36888 | AL21: =AK21/AJ21-1 -> 0.020979795 | AM21: =D21+I21+N21+S21+X21+AC21+AH21 -> 561128 | AN21: =E21+J21+O21+T21+Y21+AD21+AI21 -> 516787 | AO21: =F21+K21+P21+U21+Z21+AE21+AJ21 -> 605949 | AP21: =AK21+AF21+AA21+V21+Q21+L21+G21 -> 556075 | AQ21: =AP21/AO21-1 -> -0.082307257
B22: 46138 | C22: 17 | D22: 159538 | E22: 165535 | F22: 170449 | G22: 172413 | H22: =G22/F22-1 -> 0.011522508 | I22: 59063 | J22: 50435 | K22: 61233 | L22: 63887 | M22: =L22/K22-1 -> 0.043342642 | N22: 71424 | O22: 70851 | P22: 61173 | Q22: 63669 | R22: =Q22/P22-1 -> 0.040802315 | S22: 64791 | T22: 55843 | U22: 53011 | V22: 50959 | W22: =V22/U22-1 -> -0.038708947 | X22: 119861 | Y22: 108317 | Z22: 128313 | AA22: 125340 | AB22: =AA22/Z22-1 -> -0.023169905 | AC22: 48438 | AD22: 46927 | AE22: 65325 | AF22: 54799 | AG22: =AF22/AE22-1 -> -0.1611328 | AH22: 49477 | AI22: 40891 | AJ22: 34341 | AK22: 38138 | AL22: =AK22/AJ22-1 -> 0.11056754 | AM22: =D22+I22+N22+S22+X22+AC22+AH22 -> 572592 | AN22: =E22+J22+O22+T22+Y22+AD22+AI22 -> 538799 | AO22: =F22+K22+P22+U22+Z22+AE22+AJ22 -> 573845 | AP22: =AK22+AF22+AA22+V22+Q22+L22+G22 -> 569205 | AQ22: =AP22/AO22-1 -> -0.0080858071
B23: 46145 | C23: 18 | D23: 180837 | E23: 176677 | F23: 174913 | G23: 191993 | H23: =G23/F23-1 -> 0.097648545 | I23: 61962 | J23: 53218 | K23: 61810 | L23: 72084 | M23: =L23/K23-1 -> 0.16621906 | N23: 77485 | O23: 76371 | P23: 66765 | Q23: 67824 | R23: =Q23/P23-1 -> 0.015861604 | S23: 63248 | T23: 62723 | U23: 62722 | V23: 58041 | W23: =V23/U23-1 -> -0.074630911 | X23: 111792 | Y23: 114999 | Z23: 130964 | AA23: 116696 | AB23: =AA23/Z23-1 -> -0.10894597 | AC23: 50424 | AD23: 52075 | AE23: 61073 | AF23: 66160 | AG23: =AF23/AE23-1 -> 0.083293763 | AH23: 46396 | AI23: 44537 | AJ23: 45807 | AK23: 45985 | AL23: =AK23/AJ23-1 -> 0.003885869 | AM23: =D23+I23+N23+S23+X23+AC23+AH23 -> 592144 | AN23: =E23+J23+O23+T23+Y23+AD23+AI23 -> 580600 | AO23: =F23+K23+P23+U23+Z23+AE23+AJ23 -> 604054 | AP23: =AK23+AF23+AA23+V23+Q23+L23+G23 -> 618783 | AQ23: =AP23/AO23-1 -> 0.024383582
B24: 46152 | C24: 19 | D24: 165887 | E24: 175535 | F24: 163442 | G24: 178828 | H24: =G24/F24-1 -> 0.09413737 | I24: 60498 | J24: 52487 | K24: 55872 | L24: 68819 | M24: =L24/K24-1 -> 0.23172609 | N24: 76618 | O24: 79085 | P24: 76367 | Q24: 65874 | R24: =Q24/P24-1 -> -0.13740228 | S24: 58462 | T24: 58166 | U24: 54377 | V24: 50131 | W24: =V24/U24-1 -> -0.078084484 | X24: 112006 | Y24: 109423 | Z24: 121111 | AA24: 122630 | AB24: =AA24/Z24-1 -> 0.012542213 | AC24: 45404 | AD24: 42586 | AE24: 46755 | AF24: 59481 | AG24: =AF24/AE24-1 -> 0.27218479 | AH24: 43632 | AI24: 38322 | AJ24: 40777 | AK24: 42073 | AL24: =AK24/AJ24-1 -> 0.031782623 | AM24: =D24+I24+N24+S24+X24+AC24+AH24 -> 562507 | AN24: =E24+J24+O24+T24+Y24+AD24+AI24 -> 555604 | AO24: =F24+K24+P24+U24+Z24+AE24+AJ24 -> 558701 | AP24: =AK24+AF24+AA24+V24+Q24+L24+G24 -> 587836 | AQ24: =AP24/AO24-1 -> 0.05214775
B25: 46159 | C25: 20 | D25: 167632 | E25: 165720 | F25: 174473 | G25: 177432 | H25: =G25/F25-1 -> 0.016959644 | I25: 60465 | J25: 50159 | K25: 59468 | L25: 64662 | M25: =L25/K25-1 -> 0.087341091 | N25: 67577 | O25: 75436 | P25: 60875 | Q25: 60666 | R25: =Q25/P25-1 -> -0.0034332649 | S25: 66315 | T25: 61438 | U25: 54772 | V25: 48980 | W25: =V25/U25-1 -> -0.10574746 | X25: 110371 | Y25: 107235 | Z25: 123879 | AA25: 124897 | AB25: =AA25/Z25-1 -> 0.0082176963 | AC25: 46715 | AD25: 44125 | AE25: 51223 | AF25: 57326 | AG25: =AF25/AE25-1 -> 0.1191457 | AH25: 44922 | AI25: 40039 | AJ25: 40794 | AK25: 39617 | AL25: =AK25/AJ25-1 -> -0.028852282 | AM25: =D25+I25+N25+S25+X25+AC25+AH25 -> 563997 | AN25: =E25+J25+O25+T25+Y25+AD25+AI25 -> 544152 | AO25: =F25+K25+P25+U25+Z25+AE25+AJ25 -> 565484 | AP25: =AK25+AF25+AA25+V25+Q25+L25+G25 -> 573580 | AQ25: =AP25/AO25-1 -> 0.014316939
B26: 46166 | C26: 21 | D26: 174045 | E26: 158250 | F26: 184173 | G26: 167825 | H26: =G26/F26-1 -> -0.088764368 | I26: 63453 | J26: 49232 | K26: 75337 | L26: 63778 | M26: =L26/K26-1 -> -0.15343059 | N26: 87095 | O26: 74953 | P26: 69482 | Q26: 62199 | R26: =Q26/P26-1 -> -0.10481851 | S26: 70250 | T26: 56866 | U26: 59545 | V26: 45815 | W26: =V26/U26-1 -> -0.23058191 | X26: 102486 | Y26: 103405 | Z26: 114957 | AA26: 121629 | AB26: =AA26/Z26-1 -> 0.058039093 | AC26: 45182 | AD26: 42259 | AE26: 59290 | AF26: 54816 | AG26: =AF26/AE26-1 -> -0.075459605 | AH26: 42349 | AI26: 39727 | AJ26: 40053 | AK26: 38143 | AL26: =AK26/AJ26-1 -> -0.047686815 | AM26: =D26+I26+N26+S26+X26+AC26+AH26 -> 584860 | AN26: =E26+J26+O26+T26+Y26+AD26+AI26 -> 524692 | AO26: =F26+K26+P26+U26+Z26+AE26+AJ26 -> 602837 | AP26: =AK26+AF26+AA26+V26+Q26+L26+G26 -> 554205 | AQ26: =AP26/AO26-1 -> -0.08067189
B27: 46173 | C27: 22 | D27: 175894 | E27: 173777 | F27: 190576 | G27: 184376 | H27: =G27/F27-1 -> -0.032532953 | I27: 69331 | J27: 52425 | K27: 72363 | L27: 69060 | M27: =L27/K27-1 -> -0.045644874 | N27: 77741 | O27: 78498 | P27: 69981 | Q27: 66383 | R27: =Q27/P27-1 -> -0.051413955 | S27: 74808 | T27: 60968 | U27: 60519 | V27: 47215 | W27: =V27/U27-1 -> -0.21983179 | X27: 103277 | Y27: 96723 | Z27: 117925 | AA27: 116562 | AB27: =AA27/Z27-1 -> -0.011558194 | AC27: 50779 | AD27: 41460 | AE27: 58175 | AF27: 60356 | AG27: =AF27/AE27-1 -> 0.037490331 | AH27: 43611 | AI27: 44109 | AJ27: 42685 | AK27: 41040 | AL27: =AK27/AJ27-1 -> -0.038538128 | AM27: =D27+I27+N27+S27+X27+AC27+AH27 -> 595441 | AN27: =E27+J27+O27+T27+Y27+AD27+AI27 -> 547960 | AO27: =F27+K27+P27+U27+Z27+AE27+AJ27 -> 612224 | AP27: =AK27+AF27+AA27+V27+Q27+L27+G27 -> 584992 | AQ27: =AP27/AO27-1 -> -0.044480452
B28: 46180 | C28: 23 | D28: 173003 | E28: 174493 | F28: 200332 | G28: 186199 | H28: =G28/F28-1 -> -0.070547891 | I28: 64747 | J28: 50103 | K28: 62470 | L28: 71513 | M28: =L28/K28-1 -> 0.14475748 | N28: 71909 | O28: 76440 | P28: =61102+48813 -> 109915 | Q28: =67054+52166 -> 119220 | R28: =Q28/P28-1 -> 0.084656325 | S28: 67634 | T28: 56788 | U28: 53424 | V28: 48844 | W28: =V28/U28-1 -> -0.08572926 | X28: 100411 | Y28: 96449 | Z28: 116540 | AA28: 141236 | AB28: =AA28/Z28-1 -> 0.21191007 | AC28: 56250 | AD28: 52610 | AE28: 51656 | AF28: 61177 | AG28: =AF28/AE28-1 -> 0.18431547 | AH28: 43313 | AI28: 43825 | AJ28: 44266 | AK28: 40077 | AL28: =AK28/AJ28-1 -> -0.094632449 | AM28: =D28+I28+N28+S28+X28+AC28+AH28 -> 577267 | AN28: =E28+J28+O28+T28+Y28+AD28+AI28 -> 550708 | AO28: =F28+K28+P28+U28+Z28+AE28+AJ28 -> 638603 | AP28: =AK28+AF28+AA28+V28+Q28+L28+G28 -> 668266 | AQ28: =AP28/AO28-1 -> 0.046449829
B29: 46187 | C29: 24 | D29: 174156 | E29: 186942 | F29: 190834 | G29: 177074 | H29: =G29/F29-1 -> -0.072104552 | I29: 64225 | J29: 66269 | K29: 63968 | L29: 70817 | M29: =L29/K29-1 -> 0.10706916 | N29: 73459 | O29: 91427 | P29: =65666+48607 -> 114273 | Q29: =65517+52023 -> 117540 | R29: =Q29/P29-1 -> 0.028589431 | S29: 72524 | T29: 69449 | U29: 53275 | V29: 46552 | W29: =V29/U29-1 -> -0.12619427 | X29: 107931 | Y29: 108225 | Z29: 118438 | AA29: 127417 | AB29: =AA29/Z29-1 -> 0.075811817 | AC29: 53724 | AD29: 58170 | AE29: 51979 | AF29: 63024 | AG29: =AF29/AE29-1 -> 0.21248966 | AH29: 42485 | AI29: 45803 | AJ29: 42089 | AK29: 37106 | AL29: =AK29/AJ29-1 -> -0.11839198 | AM29: =D29+I29+N29+S29+X29+AC29+AH29 -> 588504 | AN29: =E29+J29+O29+T29+Y29+AD29+AI29 -> 626285 | AO29: =F29+K29+P29+U29+Z29+AE29+AJ29 -> 634856 | AP29: =AK29+AF29+AA29+V29+Q29+L29+G29 -> 639530 | AQ29: =AP29/AO29-1 -> 0.0073622995
B30: 46194 | C30: 25 | D30: 165916 | E30: 185341 | F30: 183050 | G30: 189860 | H30: =G30/F30-1 -> 0.03720295 | I30: 59075 | J30: 67843 | K30: 65304 | L30: 79557 | M30: =L30/K30-1 -> 0.21825616 | N30: 78349 | O30: 90005 | P30: =49536+64916 -> 114452 | Q30: =54204+75403 -> 129607 | R30: =Q30/P30-1 -> 0.13241359 | S30: 70088 | T30: 68994 | U30: 51319 | V30: 53650 | W30: =V30/U30-1 -> 0.045421774 | X30: 109405 | Y30: 105253 | Z30: 118100 | AA30: 129738 | AB30: =AA30/Z30-1 -> 0.098543607 | AC30: 46241 | AD30: 54278 | AE30: 53771 | AF30: 64053 | AG30: =AF30/AE30-1 -> 0.19121831 | AH30: 41967 | AI30: 41513 | AJ30: 40063 | AK30: 42192 | AL30: =AK30/AJ30-1 -> 0.053141302 | AM30: =D30+I30+N30+S30+X30+AC30+AH30 -> 571041 | AN30: =E30+J30+O30+T30+Y30+AD30+AI30 -> 613227 | AO30: =F30+K30+P30+U30+Z30+AE30+AJ30 -> 626059 | AP30: =AK30+AF30+AA30+V30+Q30+L30+G30 -> 688657 | AQ30: =AP30/AO30-1 -> 0.099987381
B31: 46201 | C31: 26 | D31: 161999 | E31: 175138 | F31: 180242 | G31: 181828 | H31: =G31/F31-1 -> 0.008799281 | I31: 59291 | J31: 61416 | K31: 64056 | L31: 75284 | M31: =L31/K31-1 -> 0.17528413 | N31: 75522 | O31: 91638 | P31: =50063+63654 -> 113717 | Q31: =71781+52358 -> 124139 | R31: =Q31/P31-1 -> 0.091648566 | S31: 65860 | T31: 65836 | U31: 51693 | V31: 50559 | W31: =V31/U31-1 -> -0.021937206 | X31: 116808 | Y31: 111659 | Z31: 125952 | AA31: 133650 | AB31: =AA31/Z31-1 -> 0.061118521 | AC31: 51153 | AD31: 51694 | AE31: 54834 | AF31: 67999 | AG31: =AF31/AE31-1 -> 0.24008827 | AH31: 45620 | AI31: 41708 | AJ31: 38560 | AK31: 38282 | AL31: =AK31/AJ31-1 -> -0.0072095436 | AM31: =D31+I31+N31+S31+X31+AC31+AH31 -> 576253 | AN31: =E31+J31+O31+T31+Y31+AD31+AI31 -> 599089 | AO31: =F31+K31+P31+U31+Z31+AE31+AJ31 -> 629054 | AP31: =AK31+AF31+AA31+V31+Q31+L31+G31 -> 671741 | AQ31: =AP31/AO31-1 -> 0.067859039
B32: 46208 | C32: 27 | D32: 164017 | E32: 184616 | F32: 196889 | G32: 180531 | H32: =G32/F32-1 -> -0.083082346 | I32: 60436 | J32: 65288 | K32: 72735 | L32: 65545 | M32: =L32/K32-1 -> -0.098851997 | N32: 77668 | O32: 92455 | P32: =53889+72293 -> 126182 | Q32: =53887+69441 -> 123328 | R32: =Q32/P32-1 -> -0.022618123 | S32: 65516 | T32: 86338 | U32: 55673 | V32: 52986 | W32: =V32/U32-1 -> -0.04826397 | X32: 113291 | Y32: 113609 | Z32: 128100 | AA32: 128175 | AB32: =AA32/Z32-1 -> 0.00058548009 | AC32: 50674 | AD32: 56662 | AE32: 56802 | AF32: 58795 | AG32: =AF32/AE32-1 -> 0.035086793 | AH32: 47492 | AI32: 43121 | AJ32: 44555 | AK32: 39305 | AL32: =AK32/AJ32-1 -> -0.11783189 | AM32: =D32+I32+N32+S32+X32+AC32+AH32 -> 579094 | AN32: =E32+J32+O32+T32+Y32+AD32+AI32 -> 642089 | AO32: =F32+K32+P32+U32+Z32+AE32+AJ32 -> 680936 | AP32: =AK32+AF32+AA32+V32+Q32+L32+G32 -> 648665 | AQ32: =AP32/AO32-1 -> -0.047392119
B33: 46215 | C33: 28 | D33: 172276 | E33: 178549 | F33: 193117 | G33: 183964 | H33: =G33/F33-1 -> -0.047396138 | I33: 59402 | J33: 57681 | K33: 71163 | L33: 67475 | M33: =L33/K33-1 -> -0.051824684 | N33: 84712 | O33: 85401 | P33: =76536+53379 -> 129915 | Q33: =72272+54411 -> 126683 | R33: =Q33/P33-1 -> -0.024877805 | S33: 67923 | T33: 95847 | U33: 52978 | V33: 48912 | W33: =V33/U33-1 -> -0.076748839 | X33: 115322 | Y33: 108256 | Z33: 121009 | AA33: 130953 | AB33: =AA33/Z33-1 -> 0.082175706 | AC33: 49722 | AD33: 52555 | AE33: 53318 | AF33: 63804 | AG33: =AF33/AE33-1 -> 0.19666904 | AH33: 46171 | AI33: 41007 | AJ33: 39692 | AK33: 37787 | AL33: =AK33/AJ33-1 -> -0.047994558 | AM33: =D33+I33+N33+S33+X33+AC33+AH33 -> 595528 | AN33: =E33+J33+O33+T33+Y33+AD33+AI33 -> 619296 | AO33: =F33+K33+P33+U33+Z33+AE33+AJ33 -> 661192 | AP33: =AK33+AF33+AA33+V33+Q33+L33+G33 -> 659578 | AQ33: =AP33/AO33-1 -> -0.0024410459
B34: 46222 | C34: 29 | D34: 165018 | E34: 170891 | F34: 181047 | G34: 165749 | H34: =G34/F34-1 -> -0.084497396 | I34: 67803 | J34: 55440 | K34: 64967 | L34: 66276 | M34: =L34/K34-1 -> 0.020148691 | N34: 84063 | O34: 82263 | P34: =49996+68214 -> 118210 | Q34: =53917+66908 -> 120825 | R34: =Q34/P34-1 -> 0.022121648 | S34: 71524 | T34: 86807 | U34: 56161 | V34: 51205 | W34: =V34/U34-1 -> -0.088246292 | X34: 114283 | Y34: 114264 | Z34: 124456 | AA34: 130801 | AB34: =AA34/Z34-1 -> 0.050981873 | AC34: 54320 | AD34: 48708 | AE34: 51537 | AF34: 60671 | AG34: =AF34/AE34-1 -> 0.17723189 | AH34: 47865 | AI34: 44522 | AJ34: 42994 | AK34: 42047 | AL34: =AK34/AJ34-1 -> -0.022026329 | AM34: =D34+I34+N34+S34+X34+AC34+AH34 -> 604876 | AN34: =E34+J34+O34+T34+Y34+AD34+AI34 -> 602895 | AO34: =F34+K34+P34+U34+Z34+AE34+AJ34 -> 639372 | AP34: =AK34+AF34+AA34+V34+Q34+L34+G34 -> 637574 | AQ34: =AP34/AO34-1 -> -0.0028121344
B35: 46229 | C35: 30 | D35: 173387 | E35: 173014 | F35: =181534+17043 -> 198577 | G35: =168572+15697 -> 184269 | H35: =G35/F35-1 -> -0.072052655 | I35: 68292 | J35: 59805 | K35: 64457 | L35: 67322 | M35: =L35/K35-1 -> 0.044448237 | N35: 86773 | O35: 84636 | P35: =66552+50412 -> 116964 | Q35: =68234+54523 -> 122757 | R35: =Q35/P35-1 -> 0.04952806 | S35: 68347 | T35: 64013 | U35: 49443 | V35: 47145 | W35: =V35/U35-1 -> -0.046477762 | X35: 109576 | Y35: 113644 | Z35: 123079 | AA35: 129595 | AB35: =AA35/Z35-1 -> 0.052941607 | AC35: 58195 | AD35: 49854 | AE35: 51849 | AF35: 63707 | AG35: =AF35/AE35-1 -> 0.22870258 | AH35: 42908 | AI35: 43347 | AJ35: 38677 | AK35: 38563 | AL35: =AK35/AJ35-1 -> -0.0029474882 | AM35: =D35+I35+N35+S35+X35+AC35+AH35 -> 607478 | AN35: =E35+J35+O35+T35+Y35+AD35+AI35 -> 588313 | AO35: =F35+K35+P35+U35+Z35+AE35+AJ35 -> 643046 | AP35: =AK35+AF35+AA35+V35+Q35+L35+G35 -> 653358 | AQ35: =AP35/AO35-1 -> 0.016036178
B36: 46236 | C36: 31 | D36: 165369 | E36: 171814 | F36: 185966 | H36: =G36/F36-1 -> -1 | I36: 62636 | J36: 62008 | K36: 64482 | M36: =L36/K36-1 -> -1 | N36: 85731 | O36: 84604 | P36: 66787 | R36: =Q36/P36-1 -> -1 | S36: 68276 | T36: 63023 | U36: 52307 | W36: =V36/U36-1 -> -1 | X36: 104315 | Y36: 90549 | Z36: 124208 | AB36: =AA36/Z36-1 -> -1 | AC36: 41545 | AD36: 50221 | AE36: 53388 | AG36: =AF36/AE36-1 -> -1 | AH36: 49029 | AI36: 43700 | AJ36: 42609 | AL36: =AK36/AJ36-1 -> -1 | AM36: =D36+I36+N36+S36+X36+AC36+AH36 -> 576901 | AN36: =E36+J36+O36+T36+Y36+AD36+AI36 -> 565919 | AO36: =F36+K36+P36+U36+Z36+AE36+AJ36 -> 589747 | AQ36: =AP36/AO36-1 -> -1
B37: 46243 | C37: 32 | D37: 162568 | E37: 169181 | F37: 192287 | H37: =G37/F37-1 -> -1 | I37: 58004 | J37: 61024 | K37: 65074 | M37: =L37/K37-1 -> -1 | N37: 74570 | O37: 77289 | P37: 65419 | R37: =Q37/P37-1 -> -1 | S37: 68667 | T37: 58730 | U37: 53781 | W37: =V37/U37-1 -> -1 | X37: 105717 | Y37: 97591 | Z37: 120130 | AB37: =AA37/Z37-1 -> -1 | AC37: 45059 | AD37: 46336 | AE37: 54113 | AG37: =AF37/AE37-1 -> -1 | AH37: 49132 | AI37: 45599 | AJ37: 39405 | AL37: =AK37/AJ37-1 -> -1 | AM37: =D37+I37+N37+S37+X37+AC37+AH37 -> 563717 | AN37: =E37+J37+O37+T37+Y37+AD37+AI37 -> 555750 | AO37: =F37+K37+P37+U37+Z37+AE37+AJ37 -> 590209 | AQ37: =AP37/AO37-1 -> -1
B38: 46250 | C38: 33 | D38: 163754 | E38: 173875 | F38: 190068 | H38: =G38/F38-1 -> -1 | I38: 47257 | J38: 65049 | K38: 62262 | M38: =L38/K38-1 -> -1 | N38: 74099 | O38: 82889 | P38: 66001 | R38: =Q38/P38-1 -> -1 | S38: 80514 | T38: 62517 | U38: 56189 | W38: =V38/U38-1 -> -1 | X38: 106042 | Y38: 108637 | Z38: 123513 | AB38: =AA38/Z38-1 -> -1 | AC38: 42905 | AD38: 51768 | AE38: 52319 | AG38: =AF38/AE38-1 -> -1 | AH38: 45772 | AI38: 47644 | AJ38: 40733 | AL38: =AK38/AJ38-1 -> -1 | AM38: =D38+I38+N38+S38+X38+AC38+AH38 -> 560343 | AN38: =E38+J38+O38+T38+Y38+AD38+AI38 -> 592379 | AO38: =F38+K38+P38+U38+Z38+AE38+AJ38 -> 591085 | AQ38: =AP38/AO38-1 -> -1
B39: 46257 | C39: 34 | D39: 182836 | E39: 182115 | F39: 188246 | H39: =G39/F39-1 -> -1 | I39: 59669 | J39: 60468 | K39: 57293 | M39: =L39/K39-1 -> -1 | N39: 84853 | O39: 80855 | P39: 65600 | R39: =Q39/P39-1 -> -1 | S39: 84343 | T39: 77405 | U39: 57607 | W39: =V39/U39-1 -> -1 | X39: 105353 | Y39: 122277 | Z39: 121160 | AB39: =AA39/Z39-1 -> -1 | AC39: 42196 | AD39: 46468 | AE39: 49506 | AG39: =AF39/AE39-1 -> -1 | AH39: 49565 | AI39: 47577 | AJ39: 39987 | AL39: =AK39/AJ39-1 -> -1 | AM39: =D39+I39+N39+S39+X39+AC39+AH39 -> 608815 | AN39: =E39+J39+O39+T39+Y39+AD39+AI39 -> 617165 | AO39: =F39+K39+P39+U39+Z39+AE39+AJ39 -> 579399 | AQ39: =AP39/AO39-1 -> -1
B40: 46264 | C40: 35 | D40: 169082 | E40: 176071 | F40: 214526 | H40: =G40/F40-1 -> -1 | I40: 50370 | J40: 53091 | K40: 57341 | M40: =L40/K40-1 -> -1 | N40: 75806 | O40: 74376 | P40: 72693 | R40: =Q40/P40-1 -> -1 | S40: 75990 | T40: 61725 | U40: 65518 | W40: =V40/U40-1 -> -1 | X40: 104261 | Y40: 100741 | Z40: 117120 | AB40: =AA40/Z40-1 -> -1 | AC40: 44759 | AD40: 44196 | AE40: 47183 | AG40: =AF40/AE40-1 -> -1 | AH40: 44177 | AI40: 43277 | AJ40: 41360 | AL40: =AK40/AJ40-1 -> -1 | AM40: =D40+I40+N40+S40+X40+AC40+AH40 -> 564445 | AN40: =E40+J40+O40+T40+Y40+AD40+AI40 -> 553477 | AO40: =F40+K40+P40+U40+Z40+AE40+AJ40 -> 615741 | AQ40: =AP40/AO40-1 -> -1
B41: 46271 | C41: 36 | D41: 189122 | E41: 168326 | F41: 200890 | H41: =G41/F41-1 -> -1 | I41: 60130 | J41: 56208 | K41: 56794 | M41: =L41/K41-1 -> -1 | N41: 86797 | O41: 70738 | P41: 67200 | R41: =Q41/P41-1 -> -1 | S41: 77957 | T41: 62074 | U41: 57285 | W41: =V41/U41-1 -> -1 | X41: 120020 | Y41: 114877 | Z41: 113937 | AB41: =AA41/Z41-1 -> -1 | AC41: 52697 | AD41: 46963 | AE41: 51213 | AG41: =AF41/AE41-1 -> -1 | AH41: 53221 | AI41: 44087 | AJ41: 38079 | AL41: =AK41/AJ41-1 -> -1 | AM41: =D41+I41+N41+S41+X41+AC41+AH41 -> 639944 | AN41: =E41+J41+O41+T41+Y41+AD41+AI41 -> 563273 | AO41: =F41+K41+P41+U41+Z41+AE41+AJ41 -> 585398 | AQ41: =AP41/AO41-1 -> -1
B42: 46278 | C42: 37 | D42: 163013 | E42: 157476 | F42: 179180 | H42: =G42/F42-1 -> -1 | I42: 47970 | J42: 50079 | K42: 58396 | M42: =L42/K42-1 -> -1 | N42: 66743 | O42: 67099 | P42: 62167 | R42: =Q42/P42-1 -> -1 | S42: 63902 | T42: 42639 | U42: 54928 | W42: =V42/U42-1 -> -1 | X42: 100765 | Y42: 44936 | Z42: 114891 | AB42: =AA42/Z42-1 -> -1 | AC42: 42948 | AD42: 42177 | AE42: 49440 | AG42: =AF42/AE42-1 -> -1 | AH42: 46191 | AI42: 40207 | AJ42: 37270 | AL42: =AK42/AJ42-1 -> -1 | AM42: =D42+I42+N42+S42+X42+AC42+AH42 -> 531532 | AN42: =E42+J42+O42+T42+Y42+AD42+AI42 -> 444613 | AO42: =F42+K42+P42+U42+Z42+AE42+AJ42 -> 556272 | AQ42: =AP42/AO42-1 -> -1
...

Sheet MENSUAL
B1: AFLUENCIA PLAZAS
D3: P2K | L3: PSP | U3: PRG | AB3: PSI | AK3: CBA | AQ3: PV | AW3: PLP | BF3: TOTAL | BO3: PORTAFOLIO ARCO
D4: 2019 | E4: 2021 | F4: 2022 | G4: 2023 | H4: 2024 | I4: 2025 | J4: 2026 | K4: DIF A.A. | L4: 2019 | M4: 2021 | N4: 2022 | O4: 2023 | P4: 2024 | Q4: 2025 | R4: 2026 | S4: DIF A.A. | T4: DIF vs 19 | U4: 2021 | V4: 2022 | W4: 2023 | X4: 2024 | Y4: 2025 | Z4: 2026 | AA4: DIF A.A. | AB4: 2019 | AC4: 2021 | AD4: 2022 | AE4: 2023 | AF4: 2024 | AG4: 2025 | AH4: 2026 | AI4: DIF A.A. | AJ4: DIF vs 19 | AK4: 2022 | AL4: 2023 | AM4: 2024 | AN4: 2025 | AO4: 2026 | AP4: DIF A.A. | AQ4: 2022 | AR4: 2023 | AS4: 2024 | AT4: 2025 | AU4: 2026 | AV4: DIF A.A. | AW4: 2019 | AX4: 2021 | AY4: 2022 | AZ4: 2023 | BA4: 2024 | BB4: 2025 | BC4: 2026 | BD4: DIF A.A. | BE4: DIF vs 19 | BF4: 2019 | BG4: 2021 | BH4: 2022 | BI4: 2023 | BJ4: 2024 | BK4: 2025 | BL4: 2026 | BM4: %DIF | BO4: 2022 | BP4: 2023 | BQ4: 2024 | BR4: 2025 | BS4: 2026 | BT4: % DIF
B6: Ene | E6: 482267 | F6: 752821 | G6: 678734 | H6: 696132 | I6: 743934 | J6: 740093 | K6: =J6/I6-1 -> -0.0051630924 | L6: 249843 | M6: 110865 | N6: 174664 | O6: 242250 | P6: 224082 | Q6: 227640 | R6: 259636 | S6: =R6/Q6-1 -> 0.14055526 | T6: =(#REF!-#REF!)/#REF! -> #REF! | U6: 222835 | V6: 292262 | W6: 310126 | X6: 286360 | Y6: 306893 | Z6: 263519 | AA6: =Z6/Y6-1 -> -0.14133265 | AB6: 259830 | AC6: 181024 | AD6: 242902 | AE6: 228128 | AF6: 243138 | AG6: 213434 | AH6: 201055 | AI6: =AH6/AG6-1 -> -0.057999194 | AJ6: =(#REF!-#REF!)/#REF! -> #REF! | AK6: 0 | AL6: 421720 | AM6: 435093 | AN6: 475835 | AO6: 497897 | AP6: =AO6/AN6-1 -> 0.046364811 | AQ6: 76838 | AR6: 183628 | AS6: 188625 | AT6: 209485 | AU6: 214814 | AV6: =AU6/AT6-1 -> 0.025438576 | AW6: 198967 | AX6: 118212 | AY6: 147318 | AZ6: 164737 | BA6: 154632 | BB6: 167408 | BC6: 161173 | BD6: =BC6/BB6-1 -> -0.037244337 | BE6: =(BA6-AW6)/AW6 -> -0.2228259 | BF6: =D6+L6+AB6+AW6 -> 708640 | BG6: =E6+M6+U6+AC6+AX6 -> 1115203 | BH6: =F6+N6+V6+AD6+AK6+AQ6+AY6 -> 1686805 | BI6: =G6+O6+W6+AE6+AL6+AR6+AZ6 -> 2229323 | BJ6: =H6+P6+X6+AF6+AM6+AS6+BA6 -> 2228062 | BK6: =I6+Q6+Y6+AG6+AN6+AT6+BB6 -> 2344629 | BL6: =J6+R6+Z6+AH6+AO6+AU6+BC6 -> 2338187 | BM6: =BL6/BK6-1 -> -0.0027475562 | BO6: =F6+N6+V6+AD6+AK6+AQ6 -> 1539487 | BP6: =G6+O6+W6+AE6+AL6+AR6 -> 2064586 | BQ6: =H6+P6+X6+AF6+AM6+AS6 -> 2073430 | BR6: =I6+Q6+Y6+AG6+AN6+AT6 -> 2177221 | BS6: =BL6-BC6 -> 2177014 | BT6: =BS6/BR6-1 -> -9.5075328e-05
B7: Feb | E7: 520120 | F7: 753665 | G7: 661160 | H7: 650426 | I7: 763733 | J7: 637417 | K7: =J7/I7-1 -> -0.16539288 | L7: 195031 | M7: 114747 | N7: 180596 | O7: 214033 | P7: 201917 | Q7: 210304 | R7: 225989 | S7: =R7/Q7-1 -> 0.074582509 | T7: =(#REF!-#REF!)/#REF! -> #REF! | U7: 244975 | V7: 280076 | W7: 283588 | X7: 274516 | Y7: 284351 | Z7: 220264 | AA7: =Z7/Y7-1 -> -0.2253799 | AB7: 235904 | AC7: 181823 | AD7: 226652 | AE7: 214347 | AF7: 230662 | AG7: 206159 | AH7: 190497 | AI7: =AH7/AG7-1 -> -0.075970489 | AJ7: =(#REF!-#REF!)/#REF! -> #REF! | AK7: 0 | AL7: 399175 | AM7: 401195 | AN7: 452820 | AO7: 449272 | AP7: =AO7/AN7-1 -> -0.007835343 | AQ7: 85678 | AR7: 172325 | AS7: 171179 | AT7: 203585 | AU7: 216079 | AV7: =AU7/AT7-1 -> 0.061369944 | AW7: 170315 | AX7: 101054 | AY7: 144817 | AZ7: 148918 | BA7: 142102 | BB7: 140247 | BC7: 137690 | BD7: =BC7/BB7-1 -> -0.018232119 | BE7: =(BA7-AW7)/AW7 -> -0.16565188 | BF7: =D7+L7+AB7+AW7 -> 601250 | BG7: =E7+M7+U7+AC7+AX7 -> 1162719 | BH7: =F7+N7+V7+AD7+AK7+AQ7+AY7 -> 1671484 | BI7: =G7+O7+W7+AE7+AL7+AR7+AZ7 -> 2093546 | BJ7: =H7+P7+X7+AF7+AM7+AS7+BA7 -> 2071997 | BK7: =I7+Q7+Y7+AG7+AN7+AT7+BB7 -> 2261199 | BL7: =J7+R7+Z7+AH7+AO7+AU7+BC7 -> 2077208 | BM7: =BL7/BK7-1 -> -0.081368778 | BO7: =F7+N7+V7+AD7+AK7+AQ7 -> 1526667 | BP7: =G7+O7+W7+AE7+AL7+AR7 -> 1944628 | BQ7: =H7+P7+X7+AF7+AM7+AS7 -> 1929895 | BR7: =I7+Q7+Y7+AG7+AN7+AT7 -> 2120952 | BS7: =BL7-BC7 -> 1939518 | BT7: =BS7/BR7-1 -> -0.085543662
B8: Mar | E8: 593586 | F8: 849273 | G8: 709505 | H8: 708853 | I8: 809164 | J8: 725704 | K8: =J8/I8-1 -> -0.10314349 | L8: 218923 | M8: 157203 | N8: 224286 | O8: 231610 | P8: 241982 | Q8: 228735 | R8: 265327 | S8: =R8/Q8-1 -> 0.15997552 | T8: =(#REF!-#REF!)/#REF! -> #REF! | U8: 247166 | V8: 333510 | W8: 349287 | X8: 326083 | Y8: 280293 | Z8: 262109 | AA8: =Z8/Y8-1 -> -0.06487497 | AB8: 316594 | AC8: 230551 | AD8: 246517 | AE8: 238550 | AF8: 257638 | AG8: 224979 | AH8: 208718 | AI8: =AH8/AG8-1 -> -0.072277857 | AJ8: =(#REF!-#REF!)/#REF! -> #REF! | AK8: 0 | AL8: 448071 | AM8: 428155 | AN8: 509788 | AO8: 507958 | AP8: =AO8/AN8-1 -> -0.0035897275 | AQ8: 122242 | AR8: 198118 | AS8: 206148 | AT8: 238076 | AU8: 233906 | AV8: =AU8/AT8-1 -> -0.017515415 | AW8: 203722 | AX8: 147401 | AY8: 167384 | AZ8: 171191 | BA8: 157542 | BB8: 164010 | BC8: 157705 | BD8: =BC8/BB8-1 -> -0.038442778 | BE8: =(BA8-AW8)/AW8 -> -0.22668146 | BF8: =D8+L8+AB8+AW8 -> 739239 | BG8: =E8+M8+U8+AC8+AX8 -> 1375907 | BH8: =F8+N8+V8+AD8+AK8+AQ8+AY8 -> 1943212 | BI8: =G8+O8+W8+AE8+AL8+AR8+AZ8 -> 2346332 | BJ8: =H8+P8+X8+AF8+AM8+AS8+BA8 -> 2326401 | BK8: =I8+Q8+Y8+AG8+AN8+AT8+BB8 -> 2455045 | BL8: =J8+R8+Z8+AH8+AO8+AU8+BC8 -> 2361427 | BM8: =BL8/BK8-1 -> -0.038132906 | BO8: =F8+N8+V8+AD8+AK8+AQ8 -> 1775828 | BP8: =G8+O8+W8+AE8+AL8+AR8 -> 2175141 | BQ8: =H8+P8+X8+AF8+AM8+AS8 -> 2168859 | BR8: =I8+Q8+Y8+AG8+AN8+AT8 -> 2291035 | BS8: =BL8-BC8 -> 2203722 | BT8: =BS8/BR8-1 -> -0.038110723
B9: Abr | E9: 619980 | F9: 846339 | G9: 759696 | H9: 696227 | I9: 865991 | J9: 764187 | K9: =J9/I9-1 -> -0.1175578 | L9: 233301 | M9: 165241 | N9: 236347 | O9: 291669 | P9: 215099 | Q9: 257730 | R9: 300036 | S9: =R9/Q9-1 -> 0.16414853 | T9: =(#REF!-#REF!)/#REF! -> #REF! | U9: 274260 | V9: 323452 | W9: 337512 | X9: 295732 | Y9: 337619 | Z9: 280883 | AA9: =Z9/Y9-1 -> -0.16804741 | AB9: 347108 | AC9: 238188 | AD9: 253439 | AE9: 273503 | AF9: 243142 | AG9: 232372 | AH9: 222881 | AI9: =AH9/AG9-1 -> -0.040843992 | AJ9: =(#REF!-#REF!)/#REF! -> #REF! | AK9: 0 | AL9: 492565 | AM9: 445043 | AN9: 513338 | AO9: 509544 | AP9: =AO9/AN9-1 -> -0.0073908419 | AQ9: 123629 | AR9: 217541 | AS9: 194537 | AT9: 220625 | AU9: 247647 | AV9: =AU9/AT9-1 -> 0.12247932 | AW9: 218492 | AX9: 142542 | AY9: 177057 | AZ9: 188529 | BA9: 163947 | BB9: 174788 | BC9: 165525 | BD9: =BC9/BB9-1 -> -0.052995629 | BE9: =(BA9-AW9)/AW9 -> -0.24964301 | BF9: =D9+L9+AB9+AW9 -> 798901 | BG9: =E9+M9+U9+AC9+AX9 -> 1440211 | BH9: =F9+N9+V9+AD9+AK9+AQ9+AY9 -> 1960263 | BI9: =G9+O9+W9+AE9+AL9+AR9+AZ9 -> 2561015 | BJ9: =H9+P9+X9+AF9+AM9+AS9+BA9 -> 2253727 | BK9: =I9+Q9+Y9+AG9+AN9+AT9+BB9 -> 2602463 | BL9: =J9+R9+Z9+AH9+AO9+AU9+BC9 -> 2490703 | BM9: =BL9/BK9-1 -> -0.042943934 | BO9: =F9+N9+V9+AD9+AK9+AQ9 -> 1783206 | BP9: =G9+O9+W9+AE9+AL9+AR9 -> 2372486 | BQ9: =H9+P9+X9+AF9+AM9+AS9 -> 2089780 | BR9: =I9+Q9+Y9+AG9+AN9+AT9 -> 2427675 | BS9: =BL9-BC9 -> 2325178 | BT9: =BS9/BR9-1 -> -0.042220231
B10: May | E10: 620027 | F10: 829202 | G10: 746208 | H10: 736633 | I10: 785377 | J10: 812605 | K10: =J10/I10-1 -> 0.034668701 | L10: 233823 | M10: 175254 | N10: 255246 | O10: 268229 | P10: 222143 | Q10: 290595 | R10: 306345 | S10: =R10/Q10-1 -> 0.054199143 | T10: =(#REF!-#REF!)/#REF! -> #REF! | U10: 327330 | V10: 362060 | W10: 338979 | X10: 332075 | Y10: 330098 | Z10: 291001 | AA10: =Z10/Y10-1 -> -0.11844058 | AB10: 362913 | AC10: 256566 | AD10: 264743 | AE10: 288261 | AF10: 256225 | AG10: 249823 | AH10: 218502 | AI10: =AH10/AG10-1 -> -0.12537276 | AJ10: =(#REF!-#REF!)/#REF! -> #REF! | AK10: 0 | AL10: 476245 | AM10: 463962 | AN10: 528224 | AO10: 534464 | AP10: =AO10/AN10-1 -> 0.01181317 | AQ10: 135928 | AR10: 204879 | AS10: 194126 | AT10: 243123 | AU10: 264620 | AV10: =AU10/AT10-1 -> 0.088420265 | AW10: 215742 | AX10: 167216 | AY10: 194679 | AZ10: 194366 | BA10: 175238 | BB10: 180347 | BC10: 179911 | BD10: =BC10/BB10-1 -> -0.0024175617 | BE10: =(BA10-AW10)/AW10 -> -0.18774277 | BF10: =D10+L10+AB10+AW10 -> 812478 | BG10: =E10+M10+U10+AC10+AX10 -> 1546393 | BH10: =F10+N10+V10+AD10+AK10+AQ10+AY10 -> 2041858 | BI10: =G10+O10+W10+AE10+AL10+AR10+AZ10 -> 2517167 | BJ10: =H10+P10+X10+AF10+AM10+AS10+BA10 -> 2380402 | BK10: =I10+Q10+Y10+AG10+AN10+AT10+BB10 -> 2607587 | BL10: =J10+R10+Z10+AH10+AO10+AU10+BC10 -> 2607448 | BM10: =BL10/BK10-1 -> -5.3305987e-05 | BO10: =F10+N10+V10+AD10+AK10+AQ10 -> 1847179 | BP10: =G10+O10+W10+AE10+AL10+AR10 -> 2322801 | BQ10: =H10+P10+X10+AF10+AM10+AS10 -> 2205164 | BR10: =I10+Q10+Y10+AG10+AN10+AT10 -> 2427240 | BS10: =BL10-BC10 -> 2427537 | BT10: =BS10/BR10-1 -> 0.0001223612
B11: Jun | E11: 635304 | F11: 864854 | G11: 723640 | H11: 788108 | I11: 814248 | J11: 784503 | K11: =J11/I11-1 -> -0.036530639 | L11: 272424 | M11: 206365 | N11: 265836 | O11: 270798 | P11: 267407 | Q11: 277144 | R11: 312646 | S11: =R11/Q11-1 -> 0.12809947 | T11: =(#REF!-#REF!)/#REF! -> #REF! | U11: 345577 | V11: 369031 | W11: 318698 | X11: 382925 | Y11: 278079 | Z11: 296819 | AA11: =Z11/Y11-1 -> 0.067390921 | AB11: 433996 | AC11: 263396 | AD11: 252771 | AE11: 297612 | AF11: 284466 | AG11: 231875 | AH11: 214139 | AI11: =AH11/AG11-1 -> -0.076489488 | AJ11: =(#REF!-#REF!)/#REF! -> #REF! | AK11: 13790 | AL11: 460942 | AM11: 454055 | AN11: 519137 | AO11: 566311 | AP11: =AO11/AN11-1 -> 0.09087004 | AQ11: 171303 | AR11: 224107 | AS11: 228255 | AT11: 230376 | AU11: 272155 | AV11: =AU11/AT11-1 -> 0.18135136 | AW11: 216646 | AX11: 143638 | AY11: 170460 | AZ11: 183931 | BA11: 188776 | BB11: 179446 | BC11: 168680 | BD11: =BC11/BB11-1 -> -0.059995765 | BE11: =(BA11-AW11)/AW11 -> -0.12864304 | BF11: =D11+L11+AB11+AW11 -> 923066 | BG11: =E11+M11+U11+AC11+AX11 -> 1594280 | BH11: =F11+N11+V11+AD11+AK11+AQ11+AY11 -> 2108045 | BI11: =G11+O11+W11+AE11+AL11+AR11+AZ11 -> 2479728 | BJ11: =H11+P11+X11+AF11+AM11+AS11+BA11 -> 2593992 | BK11: =I11+Q11+Y11+AG11+AN11+AT11+BB11 -> 2530305 | BL11: =J11+R11+Z11+AH11+AO11+AU11+BC11 -> 2615253 | BM11: =BL11/BK11-1 -> 0.033572237 | BO11: =F11+N11+V11+AD11+AK11+AQ11 -> 1937585 | BP11: =G11+O11+W11+AE11+AL11+AR11 -> 2295797 | BQ11: =H11+P11+X11+AF11+AM11+AS11 -> 2405216 | BR11: =I11+Q11+Y11+AG11+AN11+AT11 -> 2350859 | BS11: =BL11-BC11 -> 2446573 | BT11: =BS11/BR11-1 -> 0.040714479
B12: Jul | E12: 673929 | F12: 977317 | G12: 756748 | H12: 770567 | I12: 821731 | K12: =J12/I12-1 -> -1 | L12: 278819 | M12: 192131 | N12: 287915 | O12: 288307 | P12: 260495 | Q12: 296218 | S12: =R12/Q12-1 -> -1 | U12: 363520 | V12: 394020 | W12: 375316 | X12: 376940 | Y12: 308525 | AA12: =Z12/Y12-1 -> -1 | AB12: 453996 | AC12: 212913 | AD12: 289959 | AE12: 307240 | AF12: 362520 | AG12: 234942 | AI12: =AH12/AG12-1 -> -1 | AJ12: =(#REF!-#REF!)/#REF! -> #REF! | AK12: 411007 | AL12: 503512 | AM12: 486566 | AN12: 545038 | AP12: =AO12/AN12-1 -> -1 | AQ12: 167002 | AR12: 233715 | AS12: 230380 | AT12: 234948 | AV12: =AU12/AT12-1 -> -1 | AW12: 231086 | AX12: 114392 | AY12: 185599 | AZ12: 207706 | BA12: 190782 | BB12: 182672 | BD12: =BC12/BB12-1 -> -1 | BE12: =(BA12-AW12)/AW12 -> -0.17441126 | BF12: =D12+L12+AB12+AW12 -> 963901 | BG12: =E12+M12+U12+AC12+AX12 -> 1556885 | BH12: =F12+N12+V12+AD12+AK12+AQ12+AY12 -> 2712819 | BI12: =G12+O12+W12+AE12+AL12+AR12+AZ12 -> 2672544 | BJ12: =H12+P12+X12+AF12+AM12+AS12+BA12 -> 2678250 | BK12: =I12+Q12+Y12+AG12+AN12+AT12+BB12 -> 2624074 | BM12: =BL12/BK12-1 -> -1 | BO12: =F12+N12+V12+AD12+AK12+AQ12 -> 2527220 | BP12: =G12+O12+W12+AE12+AL12+AR12 -> 2464838 | BQ12: =H12+P12+X12+AF12+AM12+AS12 -> 2487468 | BR12: =I12+Q12+Y12+AG12+AN12+AT12 -> 2441402 | BT12: =BS12/BR12-1 -> -1
B13: Ago | E13: 607072 | F13: 905401 | G13: 720064 | H13: 776206 | I13: 882284 | K13: =J13/I13-1 -> -1 | L13: 260598 | M13: 190738 | N13: 234655 | O13: 238933 | P13: 267890 | Q13: 276815 | S13: =R13/Q13-1 -> -1 | U13: 324926 | V13: 359306 | W13: 328028 | X13: 352617 | Y13: 305287 | AA13: =Z13/Y13-1 -> -1 | AB13: 510333 | AC13: 205668 | AD13: 284438 | AE13: 331145 | AF13: 292060 | AG13: 259631 | AI13: =AH13/AG13-1 -> -1 | AJ13: =(#REF!-#REF!)/#REF! -> #REF! | AK13: 471096 | AL13: 470420 | AM13: 463298 | AN13: 545816 | AP13: =AO13/AN13-1 -> -1 | AQ13: 134968 | AR13: 194172 | AS13: 210703 | AT13: 226802 | AV13: =AU13/AT13-1 -> -1 | AW13: 217147 | AX13: 125426 | AY13: 154824 | AZ13: 208605 | BA13: 200633 | BB13: 181223 | BD13: =BC13/BB13-1 -> -1 | BE13: =(BA13-AW13)/AW13 -> -0.076049865 | BF13: =D13+L13+AB13+AW13 -> 988078 | BG13: =E13+M13+U13+AC13+AX13 -> 1453830 | BH13: =F13+N13+V13+AD13+AK13+AQ13+AY13 -> 2544688 | BI13: =G13+O13+W13+AE13+AL13+AR13+AZ13 -> 2491367 | BJ13: =H13+P13+X13+AF13+AM13+AS13+BA13 -> 2563407 | BK13: =I13+Q13+Y13+AG13+AN13+AT13+BB13 -> 2677858 | BM13: =BL13/BK13-1 -> -1 | BO13: =F13+N13+V13+AD13+AK13+AQ13 -> 2389864 | BP13: =G13+O13+W13+AE13+AL13+AR13 -> 2282762 | BQ13: =H13+P13+X13+AF13+AM13+AS13 -> 2362774 | BR13: =I13+Q13+Y13+AG13+AN13+AT13 -> 2496635 | BT13: =BS13/BR13-1 -> -1
B14: Sep | E14: 552098 | F14: 856406 | G14: 701920 | H14: 705675 | I14: 774889 | K14: =J14/I14-1 -> -1 | L14: 229394 | M14: 173877 | N14: 211442 | O14: 217226 | P14: 226383 | Q14: 233049 | S14: =R14/Q14-1 -> -1 | U14: 291140 | V14: 320068 | W14: 308186 | X14: 295815 | Y14: 266171 | AA14: =Z14/Y14-1 -> -1 | AB14: 456661 | AC14: 220589 | AD14: 316958 | AE14: 276234 | AF14: 228655 | AG14: 228783 | AI14: =AH14/AG14-1 -> -1 | AJ14: =(#REF!-#REF!)/#REF! -> #REF! | AK14: 445193 | AL14: 441126 | AM14: 345718 | AN14: 488340 | AP14: =AO14/AN14-1 -> -1 | AQ14: 172818 | AR14: 194944 | AS14: 193684 | AT14: 207691 | AV14: =AU14/AT14-1 -> -1 | AW14: 192476 | AX14: 147790 | AY14: 156334 | AZ14: 193822 | BA14: 182436 | BB14: 160815 | BD14: =BC14/BB14-1 -> -1 | BE14: =(BA14-AW14)/AW14 -> -0.052162348 | BF14: =D14+L14+AB14+AW14 -> 878531 | BG14: =E14+M14+U14+AC14+AX14 -> 1385494 | BH14: =F14+N14+V14+AD14+AK14+AQ14+AY14 -> 2479219 | BI14: =G14+O14+W14+AE14+AL14+AR14+AZ14 -> 2333458 | BJ14: =H14+P14+X14+AF14+AM14+AS14+BA14 -> 2178366 | BK14: =I14+Q14+Y14+AG14+AN14+AT14+BB14 -> 2359738 | BM14: =BL14/BK14-1 -> -1 | BO14: =F14+N14+V14+AD14+AK14+AQ14 -> 2322885 | BP14: =G14+O14+W14+AE14+AL14+AR14 -> 2139636 | BQ14: =H14+P14+X14+AF14+AM14+AS14 -> 1995930 | BR14: =I14+Q14+Y14+AG14+AN14+AT14 -> 2198923 | BT14: =BS14/BR14-1 -> -1
B15: Oct | D15: 776387 | E15: 638481 | F15: 862777 | G15: 895302 | H15: 745768 | I15: 835391 | K15: =J15/I15-1 -> -1 | L15: 232904 | M15: 162379 | N15: 213243 | O15: 219134 | P15: 211964 | Q15: 213900 | S15: =R15/Q15-1 -> -1 | U15: 363652 | V15: 348781 | W15: 341046 | X15: 322656 | Y15: 275199 | AA15: =Z15/Y15-1 -> -1 | AB15: 361017 | AC15: 268200 | AD15: 331410 | AE15: 270476 | AF15: 238996 | AG15: 230863 | AI15: =AH15/AG15-1 -> -1 | AJ15: =(#REF!-#REF!)/#REF! -> #REF! | AK15: 465086 | AL15: 440077 | AM15: 438568 | AN15: 510365 | AP15: =AO15/AN15-1 -> -1 | AQ15: 186548 | AR15: 195794 | AS15: 207454 | AT15: 209204 | AV15: =AU15/AT15-1 -> -1 | AW15: 197805 | AX15: 173410 | AY15: 175109 | AZ15: 175380 | BA15: 184833 | BB15: 167390 | BD15: =BC15/BB15-1 -> -1 | BE15: =(BA15-AW15)/AW15 -> -0.065579738 | BF15: =D15+L15+AB15+AW15 -> 1568113 | BG15: =E15+M15+U15+AC15+AX15 -> 1606122 | BH15: =F15+N15+V15+AD15+AK15+AQ15+AY15 -> 2582954 | BI15: =G15+O15+W15+AE15+AL15+AR15+AZ15 -> 2537209 | BJ15: =H15+P15+X15+AF15+AM15+AS15+BA15 -> 2350239 | BK15: =I15+Q15+Y15+AG15+AN15+AT15+BB15 -> 2442312 | BM15: =BL15/BK15-1 -> -1 | BO15: =F15+N15+V15+AD15+AK15+AQ15 -> 2407845 | BP15: =G15+O15+W15+AE15+AL15+AR15 -> 2361829 | BQ15: =H15+P15+X15+AF15+AM15+AS15 -> 2165406 | BR15: =I15+Q15+Y15+AG15+AN15+AT15 -> 2274922 | BT15: =BS15/BR15-1 -> -1
