Workbook
Name File_Name: OFFSET(#REF!,0,0,1,1)
Name File_Name: OFFSET(#REF!,0,0,1,1)
Name File_Name: OFFSET(#REF!,0,0,1,1)
Name File_Name: OFFSET(#REF!,0,0,1,1)
Name File_Name: OFFSET(#REF!,0,0,1,1)
Name File_Name: OFFSET(#REF!,0,0,1,1)
Name File_Name: OFFSET(#REF!,0,0,1,1)
Name File_Name: OFFSET(#REF!,0,0,1,1)
Name File_Name: OFFSET(#REF!,0,0,1,1)
Name File_Name: OFFSET(#REF!,0,0,1,1)
Name File_Name: OFFSET(#REF!,0,0,1,1)
Name File_Name: OFFSET(#REF!,0,0,1,1)
Name File_Name: OFFSET(#REF!,0,0,1,1)
Name File_Name: OFFSET(#REF!,0,0,1,1)
Name File_Name: OFFSET(#REF!,0,0,1,1)
Name File_Name: OFFSET(#REF!,0,0,1,1)
Name File_Name: OFFSET(#REF!,0,0,1,1)
Name File_Name: OFFSET(#REF!,0,0,1,1)
Name File_Name: OFFSET(#REF!,0,0,1,1)
Name File_Name: OFFSET(#REF!,0,0,1,1)
Name File_Name: OFFSET(#REF!,0,0,1,1)
Name File_Name: OFFSET(#REF!,0,0,1,1)
Name File_Name: OFFSET(#REF!,0,0,1,1)
Name File_Name: OFFSET(#REF!,0,0,1,1)
Name File_Name: OFFSET(#REF!,0,0,1,1)
Name File_Name: OFFSET(#REF!,0,0,1,1)
Name File_Name: OFFSET(#REF!,0,0,1,1)
Name File_Name: OFFSET(#REF!,0,0,1,1)
Name File_Name: OFFSET(#REF!,0,0,1,1)
Name pepe1: OFFSET(#REF!,0,0,1,1)
Name pepe1: OFFSET(#REF!,0,0,1,1)
Name pepe1: OFFSET(#REF!,0,0,1,1)
Name pepe1: OFFSET(#REF!,0,0,1,1)
Name pepe1: OFFSET(#REF!,0,0,1,1)
Name pepe1: OFFSET(#REF!,0,0,1,1)
Name pepe1: OFFSET(#REF!,0,0,1,1)
Name pepe1: OFFSET(#REF!,0,0,1,1)
Name pepe1: OFFSET(#REF!,0,0,1,1)
Name pepe1: OFFSET(#REF!,0,0,1,1)
Name pepe1: OFFSET(#REF!,0,0,1,1)
Name pepe1: OFFSET(#REF!,0,0,1,1)
Name pepe1: OFFSET(#REF!,0,0,1,1)
Name pepe1: OFFSET(#REF!,0,0,1,1)
Name pepe1: OFFSET(#REF!,0,0,1,1)
Name pepe1: OFFSET(#REF!,0,0,1,1)
Name pepe1: OFFSET(#REF!,0,0,1,1)
Name pepe1: OFFSET(#REF!,0,0,1,1)
Name pepe1: OFFSET(#REF!,0,0,1,1)
Name pepe1: OFFSET(#REF!,0,0,1,1)
Name pepe1: OFFSET(#REF!,0,0,1,1)
Name pepe1: OFFSET(#REF!,0,0,1,1)
Name pepe1: OFFSET(#REF!,0,0,1,1)
Name pepe1: OFFSET(#REF!,0,0,1,1)
Name pepe1: OFFSET(#REF!,0,0,1,1)
Name pepe1: OFFSET(#REF!,0,0,1,1)
Name pepe1: OFFSET(#REF!,0,0,1,1)
Name pepe1: OFFSET(#REF!,0,0,1,1)
Name pepe1: OFFSET(#REF!,0,0,1,1)
Name run: OFFSET(#REF!,0,0,1,1)
Name run: OFFSET(#REF!,0,0,1,1)

Sheet 2026R
C2: MENSUAL | S2: ACUMULADO
A5: ESTADO DE RESULTADOS | C5: P2K | D5: PSP | E5: PRG | F5: PC | G5: PLA | H5: PSI | I5: PPA | J5: PPB | K5: CBA | L5: TORR | M5: HOT | N5: PV | O5: DEPTOS | P5: PLP | Q5: PE | S5: P2K | T5: PSP | U5: PRG | V5: PC | W5: PLA | X5: PSI | Y5: PPA | Z5: PPB | AA5: CBA | AB5: TORR | AC5: HOT | AD5: PV | AE5: DEPTOS | AF5: PLP | AG5: PE | AI5: TOTAL | AJ5: TOTAL
A6: 2026R | AI6: MENSUAL | AJ6: ACUMULADO
A8: INGRESOS BRUTOS
A10: Ingresos por Operación de Plazas: | C10: =+SUM(C11:C19) -> 16261771 | D10: =+SUM(D11:D19) -> 9457039.9 | E10: =+SUM(E11:E19) -> 10802671 | F10: =+SUM(F11:F19) -> 857264.25 | G10: =+SUM(G11:G19) -> 0 | H10: =+SUM(H11:H19) -> 5395703.8 | I10: =+SUM(I11:I19) -> 993670.92 | J10: =+SUM(J11:J19) -> 0 | ... Q10: =+SUM(Q11:Q19) -> 2222465.7 | S10: =+SUM(S11:S19) -> 94962221 | T10: =+SUM(T11:T19) -> 55997212 | U10: =+SUM(U11:U19) -> 65848762 | V10: =+SUM(V11:V19) -> 5198522.2 | W10: =+SUM(W11:W19) -> 0 | X10: =+SUM(X11:X19) -> 34333619 | Y10: =+SUM(Y11:Y19) -> 6014245.2 | Z10: =+SUM(Z11:Z19) -> 0 | ... AG10: =+SUM(AG11:AG19) -> 14235942 | AI10: =+SUM(AI11:AI19) -> 84164402 | AJ10: =+SUM(AJ11:AJ19) -> 4.7715293e+08
A11: Renta Mínima | C11: 10624960 | D11: 6502731.3 | E11: 8191397.2 | F11: 735279.23 | G11: 0 | H11: 4223243.9 | I11: 872047.28 | J11: 0 | K11: 7610603.7 | L11: 7256017.1 | M11: 166822.77 | N11: 9643025.2 | O11: 0 | P11: 1978265.4 | Q11: 1610604.8 | S11: 63008168 | T11: 39249345 | U11: 50265100 | V11: 4411601.7 | W11: 0 | X11: 26867364 | Y11: 5237999.2 | Z11: 0 | AA11: 42563517 | AB11: 43222989 | AC11: 994996.91 | AD11: 36263034 | AE11: 0 | AF11: 11791932 | AG11: 9658099 | AI11: =+SUM(C11:Q11) -> 59414998 | AJ11: =+SUM(S11:AG11) -> 3.3353415e+08
A12: Renta Variable | C12: 1096856.1 | D12: 354412.68 | E12: 154073.93 | F12: 30687.47 | G12: 0 | H12: 29414.38 | I12: 21969.12 | J12: 0 | K12: 3084110.3 | L12: 386300.98 | M12: 65333.84 | N12: 472988.09 | O12: 0 | P12: 56468.4 | Q12: 352526.19 | S12: 5936802 | T12: 2149334.7 | U12: 1601322.1 | V12: 237997.13 | W12: 0 | X12: 457853.33 | Y12: 184504.06 | Z12: 0 | AA12: 19593344 | AB12: 2316884 | AC12: 242195.82 | AD12: 2679393 | AE12: 0 | AF12: 342695.48 | AG12: 2955235.6 | AI12: =+SUM(C12:Q12) -> 6105141.4 | AJ12: =+SUM(S12:AG12) -> 38697561
A13: Cuota de Mantenimiento | C13: 1391476.5 | D13: 916164.79 | E13: 1104314.2 | F13: 88845.35 | G13: 0 | H13: 560791.49 | I13: 99654.52 | J13: 0 | K13: 1271254.2 | L13: 965185.71 | M13: 16682.28 | N13: 757344.31 | O13: 0 | P13: 299851.17 | Q13: 259334.7 | S13: 8458764.7 | T13: 5547740 | U13: 6800608.1 | V13: 534210.17 | W13: 0 | X13: 3723919.4 | Y13: 591742.03 | Z13: 0 | AA13: 7346878.5 | AB13: 5727815.6 | AC13: 99499.71 | AD13: 4491185.6 | AE13: 0 | AF13: 1779469.7 | AG13: 1622607.2 | AI13: =+SUM(C13:Q13) -> 7730899.1 | AJ13: =+SUM(S13:AG13) -> 46724441
A14: Publicidad | C14: 4990.32 | D14: 0 | E14: 13081.09 | F14: 2452.2 | G14: 0 | H14: 2899.78 | I14: 0 | J14: 0 | K14: 0 | L14: 0 | M14: 0 | N14: 0 | O14: 0 | P14: 523.19 | Q14: 0 | S14: 30319.17 | T14: 0 | U14: 78486.54 | V14: 14713.2 | W14: 0 | X14: 17398.68 | Y14: 0 | Z14: 0 | AA14: 0 | AB14: 0 | AC14: 0 | AD14: 0 | AE14: 0 | AF14: 3139.14 | AG14: 0 | AI14: =+SUM(C14:Q14) -> 23946.58 | AJ14: =+SUM(S14:AG14) -> 144056.73
A15: Estacionamiento | C15: 3046278.6 | D15: 1664810.2 | E15: 1297657.4 | F15: 0 | G15: 0 | H15: 573992.25 | I15: 0 | J15: 0 | K15: 2212106.1 | L15: 117739 | M15: 0 | N15: 1120573.3 | O15: 0 | P15: 0 | Q15: 0 | S15: 17133305 | T15: 8927194.6 | U15: 6964036 | V15: 0 | W15: 0 | X15: 2994929.3 | Y15: 0 | Z15: 0 | AA15: 11301441 | AB15: 706434 | AC15: 0 | AD15: 5922929.2 | AE15: 0 | AF15: 0 | AG15: 0 | AI15: =+SUM(C15:Q15) -> 10033157 | AJ15: =+SUM(S15:AG15) -> 53950270
A16: Cuotas Condominales | C16: 0 | D16: 0 | E16: 0 | F16: 0 | G16: 0 | H16: 0 | I16: 0 | J16: 0 | K16: 0 | L16: 0 | M16: 0 | N16: 44486.45 | O16: 112937 | P16: 133435.63 | Q16: 0 | S16: 0 | T16: 0 | U16: 0 | V16: 0 | W16: 0 | X16: 0 | Y16: 0 | Z16: 0 | AA16: 0 | AB16: 0 | AC16: 0 | AD16: 228384.81 | AE16: 456329 | AF16: 821048.09 | AG16: 0 | AI16: =+SUM(C16:Q16) -> 290859.08 | AJ16: =+SUM(S16:AG16) -> 1505761.9
A17: Guantes | C17: 58850.37 | D17: 18920.88 | E17: 16063.05 | F17: 0 | G17: 0 | H17: 5361.95 | I17: 0 | J17: 0 | K17: 210267.31 | L17: 0 | M17: 0 | N17: 19324.07 | O17: 0 | P17: 1967.82 | Q17: 0 | S17: 356502.43 | T17: 123597.55 | U17: 87040.4 | V17: 0 | W17: 0 | X17: 32171.7 | Y17: 0 | Z17: 0 | AA17: 1210903.1 | AB17: 0 | AC17: 0 | AD17: 120820.79 | AE17: 0 | AF17: 10649.58 | AG17: 0 | AI17: =+SUM(C17:Q17) -> 330755.45 | AJ17: =+SUM(S17:AG17) -> 1941685.5
A18: Penalizaciones | C18: 38359.08 | D18: 0 | E18: 26084.57 | F18: 0 | G18: 0 | H18: 0 | I18: 0 | J18: 0 | K18: 0 | L18: 0 | M18: 0 | N18: 0 | O18: 0 | P18: 43934.24 | Q18: 0 | S18: 38359.08 | T18: 0 | U18: 52169.14 | V18: 0 | W18: 0 | X18: 172414 | Y18: 0 | Z18: 0 | AA18: 0 | AB18: 0 | AC18: 0 | AD18: 0 | AE18: 0 | AF18: 43934.24 | AG18: 0 | AI18: =+SUM(C18:Q18) -> 108377.89 | AJ18: =+SUM(S18:AG18) -> 306876.46
A19: Otros Ingresos Operativos de Plazas | C19: 0 | D19: 0 | E19: 0 | F19: 0 | G19: 0 | H19: 0 | I19: 0 | J19: 0 | K19: 126268 | L19: 0 | M19: 0 | N19: 0 | O19: 0 | P19: 0 | Q19: 0 | S19: 0 | T19: 0 | U19: 0 | V19: 0 | W19: 0 | X19: 67568.96 | Y19: 0 | Z19: 0 | AA19: 280560.31 | AB19: 0 | AC19: 0 | AD19: 0 | AE19: 0 | AF19: 0 | AG19: 0 | AI19: =+SUM(C19:Q19) -> 126268 | AJ19: =+SUM(S19:AG19) -> 348129.27
A20: Ingresos por Servicios: | C20: =+SUM(C21:C29) -> 0 | D20: =+SUM(D21:D29) -> 0 | E20: =+SUM(E21:E29) -> 0 | F20: =+SUM(F21:F29) -> 0 | G20: =+SUM(G21:G29) -> 0 | H20: =+SUM(H21:H29) -> 0 | I20: =+SUM(I21:I29) -> 0 | J20: =+SUM(J21:J29) -> 0 | ... Q20: =+SUM(Q21:Q29) -> 0 | S20: =+SUM(S21:S29) -> 0 | T20: =+SUM(T21:T29) -> 0 | U20: =+SUM(U21:U29) -> 0 | V20: =+SUM(V21:V29) -> 0 | W20: =+SUM(W21:W29) -> 0 | X20: =+SUM(X21:X29) -> 0 | Y20: =+SUM(Y21:Y29) -> 0 | Z20: =+SUM(Z21:Z29) -> 0 | ... AG20: =+SUM(AG21:AG29) -> 0 | AI20: =+SUM(AI21:AI29) -> 0 | AJ20: =+SUM(AJ21:AJ29) -> 0
A21: Administración de Nómina | C21: 0 | D21: 0 | E21: 0 | F21: 0 | G21: 0 | H21: 0 | I21: 0 | J21: 0 | K21: 0 | L21: 0 | M21: 0 | N21: 0 | O21: 0 | P21: 0 | Q21: 0 | S21: 0 | T21: 0 | U21: 0 | V21: 0 | W21: 0 | X21: 0 | Y21: 0 | Z21: 0 | AA21: 0 | AB21: 0 | AC21: 0 | AD21: 0 | AE21: 0 | AF21: 0 | AG21: 0 | AI21: =+SUM(R21:AF21) -> 0 | AJ21: =+SUM(S21:AG21) -> 0
A22: Apertura/Cierre de Contratos | C22: 0 | D22: 0 | E22: 0 | F22: 0 | G22: 0 | H22: 0 | I22: 0 | J22: 0 | K22: 0 | L22: 0 | M22: 0 | N22: 0 | O22: 0 | P22: 0 | Q22: 0 | S22: 0 | T22: 0 | U22: 0 | V22: 0 | W22: 0 | X22: 0 | Y22: 0 | Z22: 0 | AA22: 0 | AB22: 0 | AC22: 0 | AD22: 0 | AE22: 0 | AF22: 0 | AG22: 0 | AI22: =+SUM(R22:AF22) -> 0 | AJ22: =+SUM(S22:AG22) -> 0
A23: Renovación de Contratos | C23: 0 | D23: 0 | E23: 0 | F23: 0 | G23: 0 | H23: 0 | I23: 0 | J23: 0 | K23: 0 | L23: 0 | M23: 0 | N23: 0 | O23: 0 | P23: 0 | Q23: 0 | S23: 0 | T23: 0 | U23: 0 | V23: 0 | W23: 0 | X23: 0 | Y23: 0 | Z23: 0 | AA23: 0 | AB23: 0 | AC23: 0 | AD23: 0 | AE23: 0 | AF23: 0 | AG23: 0 | AI23: =+SUM(R23:AF23) -> 0 | AJ23: =+SUM(S23:AG23) -> 0
A24: Administración de Obra | C24: 0 | D24: 0 | E24: 0 | F24: 0 | G24: 0 | H24: 0 | I24: 0 | J24: 0 | K24: 0 | L24: 0 | M24: 0 | N24: 0 | O24: 0 | P24: 0 | Q24: 0 | S24: 0 | T24: 0 | U24: 0 | V24: 0 | W24: 0 | X24: 0 | Y24: 0 | Z24: 0 | AA24: 0 | AB24: 0 | AC24: 0 | AD24: 0 | AE24: 0 | AF24: 0 | AG24: 0 | AI24: =+SUM(R24:AF24) -> 0 | AJ24: =+SUM(S24:AG24) -> 0
A25: Administración de Plaza | C25: 0 | D25: 0 | E25: 0 | F25: 0 | G25: 0 | H25: 0 | I25: 0 | J25: 0 | K25: 0 | L25: 0 | M25: 0 | N25: 0 | O25: 0 | P25: 0 | Q25: 0 | S25: 0 | T25: 0 | U25: 0 | V25: 0 | W25: 0 | X25: 0 | Y25: 0 | Z25: 0 | AA25: 0 | AB25: 0 | AC25: 0 | AD25: 0 | AE25: 0 | AF25: 0 | AG25: 0 | AI25: =+SUM(R25:AF25) -> 0 | AJ25: =+SUM(S25:AG25) -> 0
A26: Consultoría | C26: 0 | D26: 0 | E26: 0 | F26: 0 | G26: 0 | H26: 0 | I26: 0 | J26: 0 | K26: 0 | L26: 0 | M26: 0 | N26: 0 | O26: 0 | P26: 0 | Q26: 0 | S26: 0 | T26: 0 | U26: 0 | V26: 0 | W26: 0 | X26: 0 | Y26: 0 | Z26: 0 | AA26: 0 | AB26: 0 | AC26: 0 | AD26: 0 | AE26: 0 | AF26: 0 | AG26: 0 | AI26: =+SUM(R26:AF26) -> 0 | AJ26: =+SUM(S26:AG26) -> 0
A27: Renta de Terrenos | C27: 0 | D27: 0 | E27: 0 | F27: 0 | G27: 0 | H27: 0 | I27: 0 | J27: 0 | K27: 0 | L27: 0 | M27: 0 | N27: 0 | O27: 0 | P27: 0 | Q27: 0 | S27: 0 | T27: 0 | U27: 0 | V27: 0 | W27: 0 | X27: 0 | Y27: 0 | Z27: 0 | AA27: 0 | AB27: 0 | AC27: 0 | AD27: 0 | AE27: 0 | AF27: 0 | AG27: 0 | AI27: =+SUM(R27:AF27) -> 0 | AJ27: =+SUM(S27:AG27) -> 0
A28: Operación de Hotel | C28: 0 | D28: 0 | E28: 0 | F28: 0 | G28: 0 | H28: 0 | I28: 0 | J28: 0 | K28: 0 | L28: 0 | M28: 0 | N28: 0 | O28: 0 | P28: 0 | Q28: 0 | S28: 0 | T28: 0 | U28: 0 | V28: 0 | W28: 0 | X28: 0 | Y28: 0 | Z28: 0 | AA28: 0 | AB28: 0 | AC28: 0 | AD28: 0 | AE28: 0 | AF28: 0 | AG28: 0 | AI28: =+SUM(R28:AF28) -> 0 | AJ28: =+SUM(S28:AG28) -> 0
A29: Otros Servicios | C29: 0 | D29: 0 | E29: 0 | F29: 0 | G29: 0 | H29: 0 | I29: 0 | J29: 0 | K29: 0 | L29: 0 | M29: 0 | N29: 0 | O29: 0 | P29: 0 | Q29: 0 | S29: 0 | T29: 0 | U29: 0 | V29: 0 | W29: 0 | X29: 0 | Y29: 0 | Z29: 0 | AA29: 0 | AB29: 0 | AC29: 0 | AD29: 0 | AE29: 0 | AF29: 0 | AG29: 0 | AI29: =+SUM(R29:AF29) -> 0 | AJ29: =+SUM(S29:AG29) -> 0
A31: Total Ingresos Brutos | C31: =+C10+C20 -> 16261771 | D31: =+D10+D20 -> 9457039.9 | E31: =+E10+E20 -> 10802671 | F31: =+F10+F20 -> 857264.25 | G31: =+G10+G20 -> 0 | H31: =+H10+H20 -> 5395703.8 | I31: =+I10+I20 -> 993670.92 | J31: =+J10+J20 -> 0 | ... Q31: =+Q10+Q20 -> 2222465.7 | S31: =+S10+S20 -> 94962221 | T31: =+T10+T20 -> 55997212 | U31: =+U10+U20 -> 65848762 | V31: =+V10+V20 -> 5198522.2 | W31: =+W10+W20 -> 0 | X31: =+X10+X20 -> 34333619 | Y31: =+Y10+Y20 -> 6014245.2 | Z31: =+Z10+Z20 -> 0 | ... AG31: =+AG10+AG20 -> 14235942 | AI31: =+AI10+AI20 -> 84164402 | AJ31: =+AJ10+AJ20 -> 4.7715293e+08
A33: BONIFICACIONES SOBRE INGRESOS
A35: Ingresos por Operación de Plazas: | C35: =+SUM(C36:C44) -> 0 | D35: =+SUM(D36:D44) -> 8627.5 | E35: =+SUM(E36:E44) -> 36267.56 | F35: =+SUM(F36:F44) -> 0 | G35: =+SUM(G36:G44) -> 0 | H35: =+SUM(H36:H44) -> 142551.72 | I35: =+SUM(I36:I44) -> 0 | J35: =+SUM(J36:J44) -> 0 | ... Q35: =+SUM(Q36:Q44) -> 0 | S35: =+SUM(S36:S44) -> 203155.79 | T35: =+SUM(T36:T44) -> 70832.42 | U35: =+SUM(U36:U44) -> 179325.4 | V35: =+SUM(V36:V44) -> 9378.96 | W35: =+SUM(W36:W44) -> 0 | X35: =+SUM(X36:X44) -> 1294687.7 | Y35: =+SUM(Y36:Y44) -> 0 | Z35: =+SUM(Z36:Z44) -> 0 | ... AG35: =+SUM(AG36:AG44) -> 0 | AI35: =+SUM(AI36:AI44) -> 658832.06 | AJ35: =+SUM(AJ36:AJ44) -> 4250676.8
A36: Renta Mínima | C36: 0 | D36: 8627.5 | E36: 30222.97 | F36: 0 | G36: 0 | H36: 142551.72 | I36: 0 | J36: 0 | K36: 187032.51 | L36: 103013.9 | M36: 0 | N36: 167380.79 | O36: 0 | P36: 0 | Q36: 0 | S36: 202866.92 | T36: 66490.97 | U36: 119466.37 | V36: 0 | W36: 0 | X36: 1290478.6 | Y36: 0 | Z36: 0 | AA36: 777417.77 | AB36: 103013.9 | AC36: 0 | AD36: 1559634 | AE36: 0 | AF36: 4466.79 | AG36: 0 | AI36: =+SUM(C36:Q36) -> 638829.39 | AJ36: =+SUM(S36:AG36) -> 4123835.3
A37: Renta Variable | C37: 0 | D37: 0 | E37: 0 | F37: 0 | G37: 0 | H37: 0 | I37: 0 | J37: 0 | K37: 0 | L37: 0 | M37: 0 | N37: 0 | O37: 0 | P37: 0 | Q37: 0 | S37: 0 | T37: 0 | U37: 0 | V37: 0 | W37: 0 | X37: 0 | Y37: 0 | Z37: 0 | AA37: 0 | AB37: 0 | AC37: 11092.38 | AD37: 0 | AE37: 0 | AF37: 0 | AG37: 0 | AI37: =+SUM(C37:Q37) -> 0 | AJ37: =+SUM(S37:AG37) -> 11092.38
A38: Cuota de Mantenimiento | C38: 0 | D38: 0 | E38: 6044.59 | F38: 0 | G38: 0 | H38: 0 | I38: 0 | J38: 0 | K38: 1596.41 | L38: 12361.67 | M38: 0 | N38: 0 | O38: 0 | P38: 0 | Q38: 0 | S38: 288.87 | T38: 4341.45 | U38: 21170.43 | V38: 0 | W38: 0 | X38: 4209.09 | Y38: 0 | Z38: 0 | AA38: 10154.8 | AB38: 26781.67 | AC38: 0 | AD38: 735.23 | AE38: 0 | AF38: 0 | AG38: 0 | AI38: =+SUM(C38:Q38) -> 20002.67 | AJ38: =+SUM(S38:AG38) -> 67681.54
A39: Publicidad | C39: 0 | D39: 0 | E39: 0 | F39: 0 | G39: 0 | H39: 0 | I39: 0 | J39: 0 | K39: 0 | L39: 0 | M39: 0 | N39: 0 | O39: 0 | P39: 0 | Q39: 0 | S39: 0 | T39: 0 | U39: 0 | V39: 0 | W39: 0 | X39: 0 | Y39: 0 | Z39: 0 | AA39: 0 | AB39: 0 | AC39: 0 | AD39: 0 | AE39: 0 | AF39: 0 | AG39: 0 | AI39: =+SUM(C39:Q39) -> 0 | AJ39: =+SUM(S39:AG39) -> 0
A40: Estacionamiento | C40: 0 | D40: 0 | E40: 0 | F40: 0 | G40: 0 | H40: 0 | I40: 0 | J40: 0 | K40: 0 | L40: 0 | M40: 0 | N40: 0 | O40: 0 | P40: 0 | Q40: 0 | S40: 0 | T40: 0 | U40: 0 | V40: 0 | W40: 0 | X40: 0 | Y40: 0 | Z40: 0 | AA40: 0 | AB40: 0 | AC40: 0 | AD40: 0 | AE40: 0 | AF40: 0 | AG40: 0 | AI40: =+SUM(C40:Q40) -> 0 | AJ40: =+SUM(S40:AG40) -> 0
A41: Cuotas Condominales | C41: 0 | D41: 0 | E41: 0 | F41: 0 | G41: 0 | H41: 0 | I41: 0 | J41: 0 | K41: 0 | L41: 0 | M41: 0 | N41: 0 | O41: 0 | P41: 0 | Q41: 0 | S41: 0 | T41: 0 | U41: 0 | V41: 0 | W41: 0 | X41: 0 | Y41: 0 | Z41: 0 | AA41: 0 | AB41: 0 | AC41: 0 | AD41: 0 | AE41: 0 | AF41: 0 | AG41: 0 | AI41: =+SUM(C41:Q41) -> 0 | AJ41: =+SUM(S41:AG41) -> 0
A42: Guantes | C42: 0 | D42: 0 | E42: 0 | F42: 0 | G42: 0 | H42: 0 | I42: 0 | J42: 0 | K42: 0 | L42: 0 | M42: 0 | N42: 0 | O42: 0 | P42: 0 | Q42: 0 | S42: 0 | T42: 0 | U42: 0 | V42: 0 | W42: 0 | X42: 0 | Y42: 0 | Z42: 0 | AA42: 0 | AB42: 0 | AC42: 0 | AD42: 0 | AE42: 0 | AF42: 0 | AG42: 0 | AI42: =+SUM(C42:Q42) -> 0 | AJ42: =+SUM(S42:AG42) -> 0
A43: Penalizaciones | C43: 0 | D43: 0 | E43: 0 | F43: 0 | G43: 0 | H43: 0 | I43: 0 | J43: 0 | K43: 0 | L43: 0 | M43: 0 | N43: 0 | O43: 0 | P43: 0 | Q43: 0 | S43: 0 | T43: 0 | U43: 38688.6 | V43: 9378.96 | W43: 0 | X43: 0 | Y43: 0 | Z43: 0 | AA43: 0 | AB43: 0 | AC43: 0 | AD43: 0 | AE43: 0 | AF43: 0 | AG43: 0 | AI43: =+SUM(C43:Q43) -> 0 | AJ43: =+SUM(S43:AG43) -> 48067.56
A44: Otros Ingresos Operativos de Plazas | C44: 0 | D44: 0 | E44: 0 | F44: 0 | G44: 0 | H44: 0 | I44: 0 | J44: 0 | K44: 0 | L44: 0 | M44: 0 | N44: 0 | O44: 0 | P44: 0 | Q44: 0 | S44: 0 | T44: 0 | U44: 0 | V44: 0 | W44: 0 | X44: 0 | Y44: 0 | Z44: 0 | AA44: 0 | AB44: 0 | AC44: 0 | AD44: 0 | AE44: 0 | AF44: 0 | AG44: 0 | AI44: =+SUM(C44:Q44) -> 0 | AJ44: =+SUM(S44:AG44) -> 0
A45: Ingresos por Servicios: | C45: =+SUM(C46:C54) -> 0 | D45: =+SUM(D46:D54) -> 0 | E45: =+SUM(E46:E54) -> 0 | F45: =+SUM(F46:F54) -> 0 | G45: =+SUM(G46:G54) -> 0 | H45: =+SUM(H46:H54) -> 0 | I45: =+SUM(I46:I54) -> 0 | J45: =+SUM(J46:J54) -> 0 | ... Q45: =+SUM(Q46:Q54) -> 0 | S45: =+SUM(S46:S54) -> 0 | T45: =+SUM(T46:T54) -> 0 | U45: =+SUM(U46:U54) -> 0 | V45: =+SUM(V46:V54) -> 0 | W45: =+SUM(W46:W54) -> 0 | X45: =+SUM(X46:X54) -> 0 | Y45: =+SUM(Y46:Y54) -> 0 | Z45: =+SUM(Z46:Z54) -> 0 | ... AG45: =+SUM(AG46:AG54) -> 0 | AI45: =+SUM(AI46:AI54) -> 0 | AJ45: =+SUM(AJ46:AJ54) -> 0
A46: Administración de Nómina | C46: 0 | D46: 0 | E46: 0 | F46: 0 | G46: 0 | H46: 0 | I46: 0 | J46: 0 | K46: 0 | L46: 0 | M46: 0 | N46: 0 | O46: 0 | P46: 0 | Q46: 0 | S46: 0 | T46: 0 | U46: 0 | V46: 0 | W46: 0 | X46: 0 | Y46: 0 | Z46: 0 | AA46: 0 | AB46: 0 | AC46: 0 | AD46: 0 | AE46: 0 | AF46: 0 | AG46: 0 | AI46: =+SUM(R46:AF46) -> 0 | AJ46: =+SUM(S46:AG46) -> 0
A47: Apertura/Cierre de Contratos | C47: 0 | D47: 0 | E47: 0 | F47: 0 | G47: 0 | H47: 0 | I47: 0 | J47: 0 | K47: 0 | L47: 0 | M47: 0 | N47: 0 | O47: 0 | P47: 0 | Q47: 0 | S47: 0 | T47: 0 | U47: 0 | V47: 0 | W47: 0 | X47: 0 | Y47: 0 | Z47: 0 | AA47: 0 | AB47: 0 | AC47: 0 | AD47: 0 | AE47: 0 | AF47: 0 | AG47: 0 | AI47: =+SUM(R47:AF47) -> 0 | AJ47: =+SUM(S47:AG47) -> 0
A48: Renovación de Contratos | C48: 0 | D48: 0 | E48: 0 | F48: 0 | G48: 0 | H48: 0 | I48: 0 | J48: 0 | K48: 0 | L48: 0 | M48: 0 | N48: 0 | O48: 0 | P48: 0 | Q48: 0 | S48: 0 | T48: 0 | U48: 0 | V48: 0 | W48: 0 | X48: 0 | Y48: 0 | Z48: 0 | AA48: 0 | AB48: 0 | AC48: 0 | AD48: 0 | AE48: 0 | AF48: 0 | AG48: 0 | AI48: =+SUM(R48:AF48) -> 0 | AJ48: =+SUM(S48:AG48) -> 0
...

Sheet AAC
C2: ACUMULADO
A5: ESTADO DE RESULTADOS | C5: 45657 | D5: % | F5: =+EOMONTH(C5,-12) -> 45291 | G5: % | H5: DIFERENCIAS | I5: % | K5: =+EOMONTH(F5,-12) -> 44926 | L5: % | M5: DIFERENCIAS | N5: % | P5: =+EOMONTH(K5,-12) -> 44561 | Q5: % | R5: DIFERENCIAS | S5: % | U5: =+EOMONTH(P5,-24) -> 43830 | V5: % | W5: DIFERENCIAS | X5: %
A6: ARCO ÁREAS COMERCIALES | C6: PPTO | F6: REAL | H6: 2024P vs 2023R | K6: REAL | M6: 2024P vs 2022R | P6: REAL | R6: 2024P vs 2021R | U6: REAL | W6: 2024P vs 2019R
A8: INGRESOS BRUTOS
A10: Ingresos por Operación de Plazas: | C10: =+SUM(C11:C19) -> 3.5583403e+08 | D10: =+IF(ISERROR(C10/C31),"N. D.",C10/C31) -> 1 | F10: =+SUM(F11:F19) -> 3.5583403e+08 | G10: =+IF(ISERROR(F10/F31),"N. D.",F10/F31) -> 1 | H10: =+$C10-F10 -> 0 | I10: =+IF(ISERROR(H10/F10),"N. D.",H10/F10) -> 0 | K10: =+SUM(K11:K19) -> 3.3032255e+08 | L10: =+IF(ISERROR(K10/K31),"N. D.",K10/K31) -> 1 | M10: =+$C10-K10 -> 25511483 | N10: =+IF(ISERROR(M10/K10),"N. D.",M10/K10) -> 0.077232038 | P10: =+SUM(P11:P19) -> 3.084476e+08 | Q10: =+IF(ISERROR(P10/P31),"N. D.",P10/P31) -> 1 | R10: =+$C10-P10 -> 47386425 | S10: =+IF(ISERROR(R10/P10),"N. D.",R10/P10) -> 0.15362877 | U10: =+SUM(U11:U19) -> 2.7768113e+08 | V10: =+IF(ISERROR(U10/U31),"N. D.",U10/U31) -> 1 | W10: =+$C10-U10 -> 78152899 | X10: =+IF(ISERROR(W10/U10),"N. D.",W10/U10) -> 0.28144836
A11: Renta Mínima | C11: 2.523077e+08 | D11: =+IF(ISERROR(C11/C86),"N. D.",C11/C86) -> 1.0068414 | F11: 2.523077e+08 | G11: =+IF(ISERROR(F11/F86),"N. D.",F11/F86) -> 1.0068414 | H11: =+$C11-F11 -> 0 | I11: =+IF(ISERROR(H11/F11),"N. D.",H11/F11) -> 0 | K11: 2.3925162e+08 | L11: =+IF(ISERROR(K11/K86),"N. D.",K11/K86) -> 1.0173979 | M11: =+$C11-K11 -> 13056082 | N11: =+IF(ISERROR(M11/K11),"N. D.",M11/K11) -> 0.054570508 | P11: 2.2831932e+08 | Q11: =+IF(ISERROR(P11/P86),"N. D.",P11/P86) -> 1.1250227 | R11: =+$C11-P11 -> 23988377 | S11: =+IF(ISERROR(R11/P11),"N. D.",R11/P11) -> 0.10506503 | U11: 1.9936345e+08 | V11: =+IF(ISERROR(U11/U86),"N. D.",U11/U86) -> 1.0080862 | W11: =+$C11-U11 -> 52944250 | X11: =+IF(ISERROR(W11/U11),"N. D.",W11/U11) -> 0.26556648
A12: Renta Variable | C12: 19073723 | D12: =+IF(ISERROR(C12/C87),"N. D.",C12/C87) -> 1 | F12: 19073723 | G12: =+IF(ISERROR(F12/F87),"N. D.",F12/F87) -> 1 | H12: =+$C12-F12 -> 0 | I12: =+IF(ISERROR(H12/F12),"N. D.",H12/F12) -> 0 | K12: 16701280 | L12: =+IF(ISERROR(K12/K87),"N. D.",K12/K87) -> 1.0295517 | M12: =+$C12-K12 -> 2372443.4 | N12: =+IF(ISERROR(M12/K12),"N. D.",M12/K12) -> 0.1420516 | P12: 10644857 | Q12: =+IF(ISERROR(P12/P87),"N. D.",P12/P87) -> 1.0956618 | R12: =+$C12-P12 -> 8428866.3 | S12: =+IF(ISERROR(R12/P12),"N. D.",R12/P12) -> 0.79182524 | U12: 21509016 | V12: =+IF(ISERROR(U12/U87),"N. D.",U12/U87) -> 1 | W12: =+$C12-U12 -> -2435293.1 | X12: =+IF(ISERROR(W12/U12),"N. D.",W12/U12) -> -0.11322197
A13: Cuota de Mantenimiento | C13: 33058690 | D13: =+IF(ISERROR(C13/C88),"N. D.",C13/C88) -> 1.014248 | F13: 33058690 | G13: =+IF(ISERROR(F13/F88),"N. D.",F13/F88) -> 1.014248 | H13: =+$C13-F13 -> 0 | I13: =+IF(ISERROR(H13/F13),"N. D.",H13/F13) -> 0 | K13: 30271442 | L13: =+IF(ISERROR(K13/K88),"N. D.",K13/K88) -> 1.0135118 | M13: =+$C13-K13 -> 2787248 | N13: =+IF(ISERROR(M13/K13),"N. D.",M13/K13) -> 0.092075165 | P13: 28632576 | Q13: =+IF(ISERROR(P13/P88),"N. D.",P13/P88) -> 1.0165332 | R13: =+$C13-P13 -> 4426114.1 | S13: =+IF(ISERROR(R13/P13),"N. D.",R13/P13) -> 0.15458316 | U13: 22640054 | V13: =+IF(ISERROR(U13/U88),"N. D.",U13/U88) -> 1.0012074 | W13: =+$C13-U13 -> 10418636 | X13: =+IF(ISERROR(W13/U13),"N. D.",W13/U13) -> 0.46018598
A14: Publicidad | C14: 547963.6 | D14: =+IF(ISERROR(C14/C89),"N. D.",C14/C89) -> 1.0056995 | F14: 547963.6 | G14: =+IF(ISERROR(F14/F89),"N. D.",F14/F89) -> 1.0056995 | H14: =+$C14-F14 -> 0 | I14: =+IF(ISERROR(H14/F14),"N. D.",H14/F14) -> 0 | K14: 737968.82 | L14: =+IF(ISERROR(K14/K89),"N. D.",K14/K89) -> 1.0187545 | M14: =+$C14-K14 -> -190005.22 | N14: =+IF(ISERROR(M14/K14),"N. D.",M14/K14) -> -0.25747053 | P14: 838053.61 | Q14: =+IF(ISERROR(P14/P89),"N. D.",P14/P89) -> 1.0572143 | R14: =+$C14-P14 -> -290090.01 | S14: =+IF(ISERROR(R14/P14),"N. D.",R14/P14) -> -0.34614732 | U14: 1229834.1 | V14: =+IF(ISERROR(U14/U89),"N. D.",U14/U89) -> 1 | W14: =+$C14-U14 -> -681870.48 | X14: =+IF(ISERROR(W14/U14),"N. D.",W14/U14) -> -0.55444103
A15: Estacionamiento | C15: 50309657 | D15: =+IF(ISERROR(C15/C90),"N. D.",C15/C90) -> 1 | F15: 50309657 | G15: =+IF(ISERROR(F15/F90),"N. D.",F15/F90) -> 1 | H15: =+$C15-F15 -> 0 | I15: =+IF(ISERROR(H15/F15),"N. D.",H15/F15) -> 0 | K15: 42850646 | L15: =+IF(ISERROR(K15/K90),"N. D.",K15/K90) -> 1.0028667 | M15: =+$C15-K15 -> 7459011.3 | N15: =+IF(ISERROR(M15/K15),"N. D.",M15/K15) -> 0.17406998 | P15: 39926644 | Q15: =+IF(ISERROR(P15/P90),"N. D.",P15/P90) -> 1.0002545 | R15: =+$C15-P15 -> 10383013 | S15: =+IF(ISERROR(R15/P15),"N. D.",R15/P15) -> 0.26005223 | U15: 32829885 | V15: =+IF(ISERROR(U15/U90),"N. D.",U15/U90) -> 1 | W15: =+$C15-U15 -> 17479772 | X15: =+IF(ISERROR(W15/U15),"N. D.",W15/U15) -> 0.53243478
A16: Cuotas Condominales | C16: 0 | D16: =+IF(ISERROR(C16/C91),"N. D.",C16/C91) -> N. D. | F16: 0 | G16: =+IF(ISERROR(F16/F91),"N. D.",F16/F91) -> N. D. | H16: =+$C16-F16 -> 0 | I16: =+IF(ISERROR(H16/F16),"N. D.",H16/F16) -> N. D. | K16: 0 | L16: =+IF(ISERROR(K16/K91),"N. D.",K16/K91) -> N. D. | M16: =+$C16-K16 -> 0 | N16: =+IF(ISERROR(M16/K16),"N. D.",M16/K16) -> N. D. | P16: 0 | Q16: =+IF(ISERROR(P16/P91),"N. D.",P16/P91) -> N. D. | R16: =+$C16-P16 -> 0 | S16: =+IF(ISERROR(R16/P16),"N. D.",R16/P16) -> N. D. | U16: 0 | V16: =+IF(ISERROR(U16/U91),"N. D.",U16/U91) -> N. D. | W16: =+$C16-U16 -> 0 | X16: =+IF(ISERROR(W16/U16),"N. D.",W16/U16) -> N. D.
A17: Guantes | C17: 454591.36 | D17: =+IF(ISERROR(C17/C92),"N. D.",C17/C92) -> 1 | F17: 454591.36 | G17: =+IF(ISERROR(F17/F92),"N. D.",F17/F92) -> 1 | H17: =+$C17-F17 -> 0 | I17: =+IF(ISERROR(H17/F17),"N. D.",H17/F17) -> 0 | K17: 143423.73 | L17: =+IF(ISERROR(K17/K92),"N. D.",K17/K92) -> 1 | M17: =+$C17-K17 -> 311167.63 | N17: =+IF(ISERROR(M17/K17),"N. D.",M17/K17) -> 2.1695687 | P17: 8364 | Q17: =+IF(ISERROR(P17/P92),"N. D.",P17/P92) -> 1 | R17: =+$C17-P17 -> 446227.36 | S17: =+IF(ISERROR(R17/P17),"N. D.",R17/P17) -> 53.350952 | U17: 0 | V17: =+IF(ISERROR(U17/U92),"N. D.",U17/U92) -> N. D. | W17: =+$C17-U17 -> 454591.36 | X17: =+IF(ISERROR(W17/U17),"N. D.",W17/U17) -> N. D.
A18: Penalizaciones | C18: 81701.01 | D18: =+IF(ISERROR(C18/C93),"N. D.",C18/C93) -> 1 | F18: 81701.01 | G18: =+IF(ISERROR(F18/F93),"N. D.",F18/F93) -> 1 | H18: =+$C18-F18 -> 0 | I18: =+IF(ISERROR(H18/F18),"N. D.",H18/F18) -> 0 | K18: 366165.08 | L18: =+IF(ISERROR(K18/K93),"N. D.",K18/K93) -> 1 | M18: =+$C18-K18 -> -284464.07 | N18: =+IF(ISERROR(M18/K18),"N. D.",M18/K18) -> -0.77687384 | P18: 77784.11 | Q18: =+IF(ISERROR(P18/P93),"N. D.",P18/P93) -> 1 | R18: =+$C18-P18 -> 3916.9 | S18: =+IF(ISERROR(R18/P18),"N. D.",R18/P18) -> 0.050356043 | U18: 20713.8 | V18: =+IF(ISERROR(U18/U93),"N. D.",U18/U93) -> 1 | W18: =+$C18-U18 -> 60987.21 | X18: =+IF(ISERROR(W18/U18),"N. D.",W18/U18) -> 2.9442792
A19: Otros Ingresos Operativos de Plazas | C19: 0 | D19: =+IF(ISERROR(C19/C94),"N. D.",C19/C94) -> N. D. | F19: 0 | G19: =+IF(ISERROR(F19/F94),"N. D.",F19/F94) -> N. D. | H19: =+$C19-F19 -> 0 | I19: =+IF(ISERROR(H19/F19),"N. D.",H19/F19) -> N. D. | K19: 0 | L19: =+IF(ISERROR(K19/K94),"N. D.",K19/K94) -> N. D. | M19: =+$C19-K19 -> 0 | N19: =+IF(ISERROR(M19/K19),"N. D.",M19/K19) -> N. D. | P19: 0 | Q19: =+IF(ISERROR(P19/P94),"N. D.",P19/P94) -> N. D. | R19: =+$C19-P19 -> 0 | S19: =+IF(ISERROR(R19/P19),"N. D.",R19/P19) -> N. D. | U19: 88174.26 | V19: =+IF(ISERROR(U19/U94),"N. D.",U19/U94) -> 1 | W19: =+$C19-U19 -> -88174.26 | X19: =+IF(ISERROR(W19/U19),"N. D.",W19/U19) -> -1
A20: Ingresos por Servicios: | C20: =+SUM(C21:C29) -> 0 | D20: =+IF(ISERROR(C20/C31),"N. D.",C20/C31) -> 0 | F20: =+SUM(F21:F29) -> 0 | G20: =+IF(ISERROR(F20/F31),"N. D.",F20/F31) -> 0 | H20: =+$C20-F20 -> 0 | I20: =+IF(ISERROR(H20/F20),"N. D.",H20/F20) -> N. D. | K20: =+SUM(K21:K29) -> 0 | L20: =+IF(ISERROR(K20/K31),"N. D.",K20/K31) -> 0 | M20: =+$C20-K20 -> 0 | N20: =+IF(ISERROR(M20/K20),"N. D.",M20/K20) -> N. D. | P20: =+SUM(P21:P29) -> 0 | Q20: =+IF(ISERROR(P20/P31),"N. D.",P20/P31) -> 0 | R20: =+$C20-P20 -> 0 | S20: =+IF(ISERROR(R20/P20),"N. D.",R20/P20) -> N. D. | U20: =+SUM(U21:U29) -> 0 | V20: =+IF(ISERROR(U20/U31),"N. D.",U20/U31) -> 0 | W20: =+$C20-U20 -> 0 | X20: =+IF(ISERROR(W20/U20),"N. D.",W20/U20) -> N. D.
A21: Administración de Nómina | C21: 0 | D21: =+IF(ISERROR(C21/C96),"N. D.",C21/C96) -> N. D. | F21: 0 | G21: =+IF(ISERROR(F21/F96),"N. D.",F21/F96) -> N. D. | H21: =+$C21-F21 -> 0 | I21: =+IF(ISERROR(H21/F21),"N. D.",H21/F21) -> N. D. | K21: 0 | L21: =+IF(ISERROR(K21/K96),"N. D.",K21/K96) -> N. D. | M21: =+$C21-K21 -> 0 | N21: =+IF(ISERROR(M21/K21),"N. D.",M21/K21) -> N. D. | P21: 0 | Q21: =+IF(ISERROR(P21/P96),"N. D.",P21/P96) -> N. D. | R21: =+$C21-P21 -> 0 | S21: =+IF(ISERROR(R21/P21),"N. D.",R21/P21) -> N. D. | U21: 0 | V21: =+IF(ISERROR(U21/U96),"N. D.",U21/U96) -> N. D. | W21: =+$C21-U21 -> 0 | X21: =+IF(ISERROR(W21/U21),"N. D.",W21/U21) -> N. D.
A22: Apertura/Cierre de Contratos | C22: 0 | D22: =+IF(ISERROR(C22/C97),"N. D.",C22/C97) -> N. D. | F22: 0 | G22: =+IF(ISERROR(F22/F97),"N. D.",F22/F97) -> N. D. | H22: =+$C22-F22 -> 0 | I22: =+IF(ISERROR(H22/F22),"N. D.",H22/F22) -> N. D. | K22: 0 | L22: =+IF(ISERROR(K22/K97),"N. D.",K22/K97) -> N. D. | M22: =+$C22-K22 -> 0 | N22: =+IF(ISERROR(M22/K22),"N. D.",M22/K22) -> N. D. | P22: 0 | Q22: =+IF(ISERROR(P22/P97),"N. D.",P22/P97) -> N. D. | R22: =+$C22-P22 -> 0 | S22: =+IF(ISERROR(R22/P22),"N. D.",R22/P22) -> N. D. | U22: 0 | V22: =+IF(ISERROR(U22/U97),"N. D.",U22/U97) -> N. D. | W22: =+$C22-U22 -> 0 | X22: =+IF(ISERROR(W22/U22),"N. D.",W22/U22) -> N. D.
A23: Renovación de Contratos | C23: 0 | D23: =+IF(ISERROR(C23/C98),"N. D.",C23/C98) -> N. D. | F23: 0 | G23: =+IF(ISERROR(F23/F98),"N. D.",F23/F98) -> N. D. | H23: =+$C23-F23 -> 0 | I23: =+IF(ISERROR(H23/F23),"N. D.",H23/F23) -> N. D. | K23: 0 | L23: =+IF(ISERROR(K23/K98),"N. D.",K23/K98) -> N. D. | M23: =+$C23-K23 -> 0 | N23: =+IF(ISERROR(M23/K23),"N. D.",M23/K23) -> N. D. | P23: 0 | Q23: =+IF(ISERROR(P23/P98),"N. D.",P23/P98) -> N. D. | R23: =+$C23-P23 -> 0 | S23: =+IF(ISERROR(R23/P23),"N. D.",R23/P23) -> N. D. | U23: 0 | V23: =+IF(ISERROR(U23/U98),"N. D.",U23/U98) -> N. D. | W23: =+$C23-U23 -> 0 | X23: =+IF(ISERROR(W23/U23),"N. D.",W23/U23) -> N. D.
A24: Administración de Obra | C24: 0 | D24: =+IF(ISERROR(C24/C99),"N. D.",C24/C99) -> N. D. | F24: 0 | G24: =+IF(ISERROR(F24/F99),"N. D.",F24/F99) -> N. D. | H24: =+$C24-F24 -> 0 | I24: =+IF(ISERROR(H24/F24),"N. D.",H24/F24) -> N. D. | K24: 0 | L24: =+IF(ISERROR(K24/K99),"N. D.",K24/K99) -> N. D. | M24: =+$C24-K24 -> 0 | N24: =+IF(ISERROR(M24/K24),"N. D.",M24/K24) -> N. D. | P24: 0 | Q24: =+IF(ISERROR(P24/P99),"N. D.",P24/P99) -> N. D. | R24: =+$C24-P24 -> 0 | S24: =+IF(ISERROR(R24/P24),"N. D.",R24/P24) -> N. D. | U24: 0 | V24: =+IF(ISERROR(U24/U99),"N. D.",U24/U99) -> N. D. | W24: =+$C24-U24 -> 0 | X24: =+IF(ISERROR(W24/U24),"N. D.",W24/U24) -> N. D.
A25: Administración de Plaza | C25: 0 | D25: =+IF(ISERROR(C25/C100),"N. D.",C25/C100) -> N. D. | F25: 0 | G25: =+IF(ISERROR(F25/F100),"N. D.",F25/F100) -> N. D. | H25: =+$C25-F25 -> 0 | I25: =+IF(ISERROR(H25/F25),"N. D.",H25/F25) -> N. D. | K25: 0 | L25: =+IF(ISERROR(K25/K100),"N. D.",K25/K100) -> N. D. | M25: =+$C25-K25 -> 0 | N25: =+IF(ISERROR(M25/K25),"N. D.",M25/K25) -> N. D. | P25: 0 | Q25: =+IF(ISERROR(P25/P100),"N. D.",P25/P100) -> N. D. | R25: =+$C25-P25 -> 0 | S25: =+IF(ISERROR(R25/P25),"N. D.",R25/P25) -> N. D. | U25: 0 | V25: =+IF(ISERROR(U25/U100),"N. D.",U25/U100) -> N. D. | W25: =+$C25-U25 -> 0 | X25: =+IF(ISERROR(W25/U25),"N. D.",W25/U25) -> N. D.
A26: Consultoría | C26: 0 | D26: =+IF(ISERROR(C26/C101),"N. D.",C26/C101) -> N. D. | F26: 0 | G26: =+IF(ISERROR(F26/F101),"N. D.",F26/F101) -> N. D. | H26: =+$C26-F26 -> 0 | I26: =+IF(ISERROR(H26/F26),"N. D.",H26/F26) -> N. D. | K26: 0 | L26: =+IF(ISERROR(K26/K101),"N. D.",K26/K101) -> N. D. | M26: =+$C26-K26 -> 0 | N26: =+IF(ISERROR(M26/K26),"N. D.",M26/K26) -> N. D. | P26: 0 | Q26: =+IF(ISERROR(P26/P101),"N. D.",P26/P101) -> N. D. | R26: =+$C26-P26 -> 0 | S26: =+IF(ISERROR(R26/P26),"N. D.",R26/P26) -> N. D. | U26: 0 | V26: =+IF(ISERROR(U26/U101),"N. D.",U26/U101) -> N. D. | W26: =+$C26-U26 -> 0 | X26: =+IF(ISERROR(W26/U26),"N. D.",W26/U26) -> N. D.
A27: Renta de Terrenos | C27: 0 | D27: =+IF(ISERROR(C27/C102),"N. D.",C27/C102) -> N. D. | F27: 0 | G27: =+IF(ISERROR(F27/F102),"N. D.",F27/F102) -> N. D. | H27: =+$C27-F27 -> 0 | I27: =+IF(ISERROR(H27/F27),"N. D.",H27/F27) -> N. D. | K27: 0 | L27: =+IF(ISERROR(K27/K102),"N. D.",K27/K102) -> N. D. | M27: =+$C27-K27 -> 0 | N27: =+IF(ISERROR(M27/K27),"N. D.",M27/K27) -> N. D. | P27: 0 | Q27: =+IF(ISERROR(P27/P102),"N. D.",P27/P102) -> N. D. | R27: =+$C27-P27 -> 0 | S27: =+IF(ISERROR(R27/P27),"N. D.",R27/P27) -> N. D. | U27: 0 | V27: =+IF(ISERROR(U27/U102),"N. D.",U27/U102) -> N. D. | W27: =+$C27-U27 -> 0 | X27: =+IF(ISERROR(W27/U27),"N. D.",W27/U27) -> N. D.
A28: Operación de Hotel | C28: 0 | D28: =+IF(ISERROR(C28/C103),"N. D.",C28/C103) -> N. D. | F28: 0 | G28: =+IF(ISERROR(F28/F103),"N. D.",F28/F103) -> N. D. | H28: =+$C28-F28 -> 0 | I28: =+IF(ISERROR(H28/F28),"N. D.",H28/F28) -> N. D. | K28: 0 | L28: =+IF(ISERROR(K28/K103),"N. D.",K28/K103) -> N. D. | M28: =+$C28-K28 -> 0 | N28: =+IF(ISERROR(M28/K28),"N. D.",M28/K28) -> N. D. | P28: 0 | Q28: =+IF(ISERROR(P28/P103),"N. D.",P28/P103) -> N. D. | R28: =+$C28-P28 -> 0 | S28: =+IF(ISERROR(R28/P28),"N. D.",R28/P28) -> N. D. | U28: 0 | V28: =+IF(ISERROR(U28/U103),"N. D.",U28/U103) -> N. D. | W28: =+$C28-U28 -> 0 | X28: =+IF(ISERROR(W28/U28),"N. D.",W28/U28) -> N. D.
A29: Otros Servicios | C29: 0 | D29: =+IF(ISERROR(C29/C104),"N. D.",C29/C104) -> N. D. | F29: 0 | G29: =+IF(ISERROR(F29/F104),"N. D.",F29/F104) -> N. D. | H29: =+$C29-F29 -> 0 | I29: =+IF(ISERROR(H29/F29),"N. D.",H29/F29) -> N. D. | K29: 0 | L29: =+IF(ISERROR(K29/K104),"N. D.",K29/K104) -> N. D. | M29: =+$C29-K29 -> 0 | N29: =+IF(ISERROR(M29/K29),"N. D.",M29/K29) -> N. D. | P29: 0 | Q29: =+IF(ISERROR(P29/P104),"N. D.",P29/P104) -> N. D. | R29: =+$C29-P29 -> 0 | S29: =+IF(ISERROR(R29/P29),"N. D.",R29/P29) -> N. D. | U29: 0 | V29: =+IF(ISERROR(U29/U104),"N. D.",U29/U104) -> N. D. | W29: =+$C29-U29 -> 0 | X29: =+IF(ISERROR(W29/U29),"N. D.",W29/U29) -> N. D.
A31: Total Ingresos Brutos | C31: =+C10+C20 -> 3.5583403e+08 | D31: =+IF(ISERROR(C31/C106),"N. D.",C31/C106) -> 1.0061696 | F31: =+F10+F20 -> 3.5583403e+08 | G31: =+IF(ISERROR(F31/F106),"N. D.",F31/F106) -> 1.0061696 | H31: =+$C31-F31 -> 0 | I31: =+IF(ISERROR(H31/F31),"N. D.",H31/F31) -> 0 | K31: =+K10+K20 -> 3.3032255e+08 | L31: =+IF(ISERROR(K31/K106),"N. D.",K31/K106) -> 1.0157138 | M31: =+$C31-K31 -> 25511483 | N31: =+IF(ISERROR(M31/K31),"N. D.",M31/K31) -> 0.077232038 | P31: =+P10+P20 -> 3.084476e+08 | Q31: =+IF(ISERROR(P31/P106),"N. D.",P31/P106) -> 1.0952458 | R31: =+$C31-P31 -> 47386425 | S31: =+IF(ISERROR(R31/P31),"N. D.",R31/P31) -> 0.15362877 | U31: =+U10+U20 -> 2.7768113e+08 | V31: =+IF(ISERROR(U31/U106),"N. D.",U31/U106) -> 1.0058918 | W31: =+$C31-U31 -> 78152899 | X31: =+IF(ISERROR(W31/U31),"N. D.",W31/U31) -> 0.28144836
A33: BONIFICACIONES SOBRE INGRESOS
A35: Ingresos por Operación de Plazas: | C35: =+SUM(C36:C44) -> 1681687.5 | D35: =+IF(ISERROR(C35/C56),"N. D.",C35/C56) -> 1 | F35: =+SUM(F36:F44) -> 1681687.5 | G35: =+IF(ISERROR(F35/F56),"N. D.",F35/F56) -> 1 | H35: =+$C35-F35 -> 0 | I35: =+IF(ISERROR(H35/F35),"N. D.",H35/F35) -> 0 | K35: =+SUM(K36:K44) -> 3132840 | L35: =+IF(ISERROR(K35/K56),"N. D.",K35/K56) -> 1 | M35: =+$C35-K35 -> -1451152.4 | N35: =+IF(ISERROR(M35/K35),"N. D.",M35/K35) -> -0.46320669 | P35: =+SUM(P36:P44) -> 22645531 | Q35: =+IF(ISERROR(P35/P56),"N. D.",P35/P56) -> 1 | R35: =+$C35-P35 -> -20963843 | S35: =+IF(ISERROR(R35/P35),"N. D.",R35/P35) -> -0.92573866 | U35: =+SUM(U36:U44) -> 695225.11 | V35: =+IF(ISERROR(U35/U56),"N. D.",U35/U56) -> 1 | W35: =+$C35-U35 -> 986462.44 | X35: =+IF(ISERROR(W35/U35),"N. D.",W35/U35) -> 1.4189108
A36: Renta Mínima | C36: 1455699.4 | D36: =+IF(ISERROR(C36/C86),"N. D.",C36/C86) -> 0.0058090117 | F36: 1455699.4 | G36: =+IF(ISERROR(F36/F86),"N. D.",F36/F86) -> 0.0058090117 | H36: =+$C36-F36 -> 0 | I36: =+IF(ISERROR(H36/F36),"N. D.",H36/F36) -> 0 | K36: 2367187.9 | L36: =+IF(ISERROR(K36/K86),"N. D.",K36/K86) -> 0.010066272 | M36: =+$C36-K36 -> -911488.46 | N36: =+IF(ISERROR(M36/K36),"N. D.",M36/K36) -> -0.38505117 | P36: 22340768 | Q36: =+IF(ISERROR(P36/P86),"N. D.",P36/P86) -> 0.1100821 | R36: =+$C36-P36 -> -20885069 | S36: =+IF(ISERROR(R36/P36),"N. D.",R36/P36) -> -0.93484112 | U36: 667922.79 | V36: =+IF(ISERROR(U36/U86),"N. D.",U36/U86) -> 0.0033773681 | W36: =+$C36-U36 -> 787776.64 | X36: =+IF(ISERROR(W36/U36),"N. D.",W36/U36) -> 1.1794427
A37: Renta Variable | C37: 0 | D37: =+IF(ISERROR(C37/C87),"N. D.",C37/C87) -> 0 | F37: 0 | G37: =+IF(ISERROR(F37/F87),"N. D.",F37/F87) -> 0 | H37: =+$C37-F37 -> 0 | I37: =+IF(ISERROR(H37/F37),"N. D.",H37/F37) -> N. D. | K37: 479385.12 | L37: =+IF(ISERROR(K37/K87),"N. D.",K37/K87) -> 0.029551735 | M37: =+$C37-K37 -> -479385.12 | N37: =+IF(ISERROR(M37/K37),"N. D.",M37/K37) -> -1 | P37: 95928.15 | Q37: =+IF(ISERROR(P37/P87),"N. D.",P37/P87) -> 0.0098737648 | R37: =+$C37-P37 -> -95928.15 | S37: =+IF(ISERROR(R37/P37),"N. D.",R37/P37) -> -1 | U37: 0 | V37: =+IF(ISERROR(U37/U87),"N. D.",U37/U87) -> 0 | W37: =+$C37-U37 -> 0 | X37: =+IF(ISERROR(W37/U37),"N. D.",W37/U37) -> N. D.
A38: Cuota de Mantenimiento | C38: 222882.72 | D38: =+IF(ISERROR(C38/C88),"N. D.",C38/C88) -> 0.006838092 | F38: 222882.72 | G38: =+IF(ISERROR(F38/F88),"N. D.",F38/F88) -> 0.006838092 | H38: =+$C38-F38 -> 0 | I38: =+IF(ISERROR(H38/F38),"N. D.",H38/F38) -> 0 | K38: 150932.51 | L38: =+IF(ISERROR(K38/K88),"N. D.",K38/K88) -> 0.0050533396 | M38: =+$C38-K38 -> 71950.21 | N38: =+IF(ISERROR(M38/K38),"N. D.",M38/K38) -> 0.47670452 | P38: 193935.2 | Q38: =+IF(ISERROR(P38/P88),"N. D.",P38/P88) -> 0.0068852193 | R38: =+$C38-P38 -> 28947.52 | S38: =+IF(ISERROR(R38/P38),"N. D.",R38/P38) -> 0.14926388 | U38: 27302.32 | V38: =+IF(ISERROR(U38/U88),"N. D.",U38/U88) -> 0.001207386 | W38: =+$C38-U38 -> 195580.4 | X38: =+IF(ISERROR(W38/U38),"N. D.",W38/U38) -> 7.1635084
A39: Publicidad | C39: 3105.4 | D39: =+IF(ISERROR(C39/C89),"N. D.",C39/C89) -> 0.0056994646 | F39: 3105.4 | G39: =+IF(ISERROR(F39/F89),"N. D.",F39/F89) -> 0.0056994646 | H39: =+$C39-F39 -> 0 | I39: =+IF(ISERROR(H39/F39),"N. D.",H39/F39) -> 0 | K39: 13402.94 | L39: =+IF(ISERROR(K39/K89),"N. D.",K39/K89) -> 0.018502551 | M39: =+$C39-K39 -> -10297.54 | N39: =+IF(ISERROR(M39/K39),"N. D.",M39/K39) -> -0.76830457 | P39: 4742.48 | Q39: =+IF(ISERROR(P39/P89),"N. D.",P39/P89) -> 0.0059826935 | R39: =+$C39-P39 -> -1637.08 | S39: =+IF(ISERROR(R39/P39),"N. D.",R39/P39) -> -0.34519492 | U39: 0 | V39: =+IF(ISERROR(U39/U89),"N. D.",U39/U89) -> 0 | W39: =+$C39-U39 -> 3105.4 | X39: =+IF(ISERROR(W39/U39),"N. D.",W39/U39) -> N. D.
A40: Estacionamiento | C40: 0 | D40: =+IF(ISERROR(C40/C90),"N. D.",C40/C90) -> 0 | F40: 0 | G40: =+IF(ISERROR(F40/F90),"N. D.",F40/F90) -> 0 | H40: =+$C40-F40 -> 0 | I40: =+IF(ISERROR(H40/F40),"N. D.",H40/F40) -> N. D. | K40: 121931.53 | L40: =+IF(ISERROR(K40/K90),"N. D.",K40/K90) -> 0.0028536575 | M40: =+$C40-K40 -> -121931.53 | N40: =+IF(ISERROR(M40/K40),"N. D.",M40/K40) -> -1 | P40: 10156.91 | Q40: =+IF(ISERROR(P40/P90),"N. D.",P40/P90) -> 0.000254454 | R40: =+$C40-P40 -> -10156.91 | S40: =+IF(ISERROR(R40/P40),"N. D.",R40/P40) -> -1 | U40: 0 | V40: =+IF(ISERROR(U40/U90),"N. D.",U40/U90) -> 0 | W40: =+$C40-U40 -> 0 | X40: =+IF(ISERROR(W40/U40),"N. D.",W40/U40) -> N. D.
A41: Cuotas Condominales | C41: 0 | D41: =+IF(ISERROR(C41/C91),"N. D.",C41/C91) -> N. D. | F41: 0 | G41: =+IF(ISERROR(F41/F91),"N. D.",F41/F91) -> N. D. | H41: =+$C41-F41 -> 0 | I41: =+IF(ISERROR(H41/F41),"N. D.",H41/F41) -> N. D. | K41: 0 | L41: =+IF(ISERROR(K41/K91),"N. D.",K41/K91) -> N. D. | M41: =+$C41-K41 -> 0 | N41: =+IF(ISERROR(M41/K41),"N. D.",M41/K41) -> N. D. | P41: 0 | Q41: =+IF(ISERROR(P41/P91),"N. D.",P41/P91) -> N. D. | R41: =+$C41-P41 -> 0 | S41: =+IF(ISERROR(R41/P41),"N. D.",R41/P41) -> N. D. | U41: 0 | V41: =+IF(ISERROR(U41/U91),"N. D.",U41/U91) -> N. D. | W41: =+$C41-U41 -> 0 | X41: =+IF(ISERROR(W41/U41),"N. D.",W41/U41) -> N. D.
A42: Guantes | C42: 0 | D42: =+IF(ISERROR(C42/C92),"N. D.",C42/C92) -> 0 | F42: 0 | G42: =+IF(ISERROR(F42/F92),"N. D.",F42/F92) -> 0 | H42: =+$C42-F42 -> 0 | I42: =+IF(ISERROR(H42/F42),"N. D.",H42/F42) -> N. D. | K42: 0 | L42: =+IF(ISERROR(K42/K92),"N. D.",K42/K92) -> 0 | M42: =+$C42-K42 -> 0 | N42: =+IF(ISERROR(M42/K42),"N. D.",M42/K42) -> N. D. | P42: 0 | Q42: =+IF(ISERROR(P42/P92),"N. D.",P42/P92) -> 0 | R42: =+$C42-P42 -> 0 | S42: =+IF(ISERROR(R42/P42),"N. D.",R42/P42) -> N. D. | U42: 0 | V42: =+IF(ISERROR(U42/U92),"N. D.",U42/U92) -> N. D. | W42: =+$C42-U42 -> 0 | X42: =+IF(ISERROR(W42/U42),"N. D.",W42/U42) -> N. D.
A43: Penalizaciones | C43: 0 | D43: =+IF(ISERROR(C43/C93),"N. D.",C43/C93) -> 0 | F43: 0 | G43: =+IF(ISERROR(F43/F93),"N. D.",F43/F93) -> 0 | H43: =+$C43-F43 -> 0 | I43: =+IF(ISERROR(H43/F43),"N. D.",H43/F43) -> N. D. | K43: 0 | L43: =+IF(ISERROR(K43/K93),"N. D.",K43/K93) -> 0 | M43: =+$C43-K43 -> 0 | N43: =+IF(ISERROR(M43/K43),"N. D.",M43/K43) -> N. D. | P43: 0 | Q43: =+IF(ISERROR(P43/P93),"N. D.",P43/P93) -> 0 | R43: =+$C43-P43 -> 0 | S43: =+IF(ISERROR(R43/P43),"N. D.",R43/P43) -> N. D. | U43: 0 | V43: =+IF(ISERROR(U43/U93),"N. D.",U43/U93) -> 0 | W43: =+$C43-U43 -> 0 | X43: =+IF(ISERROR(W43/U43),"N. D.",W43/U43) -> N. D.
A44: Otros Ingresos Operativos de Plazas | C44: 0 | D44: =+IF(ISERROR(C44/C94),"N. D.",C44/C94) -> N. D. | F44: 0 | G44: =+IF(ISERROR(F44/F94),"N. D.",F44/F94) -> N. D. | H44: =+$C44-F44 -> 0 | I44: =+IF(ISERROR(H44/F44),"N. D.",H44/F44) -> N. D. | K44: 0 | L44: =+IF(ISERROR(K44/K94),"N. D.",K44/K94) -> N. D. | M44: =+$C44-K44 -> 0 | N44: =+IF(ISERROR(M44/K44),"N. D.",M44/K44) -> N. D. | P44: 0 | Q44: =+IF(ISERROR(P44/P94),"N. D.",P44/P94) -> N. D. | R44: =+$C44-P44 -> 0 | S44: =+IF(ISERROR(R44/P44),"N. D.",R44/P44) -> N. D. | U44: 0 | V44: =+IF(ISERROR(U44/U94),"N. D.",U44/U94) -> 0 | W44: =+$C44-U44 -> 0 | X44: =+IF(ISERROR(W44/U44),"N. D.",W44/U44) -> N. D.
A45: Ingresos por Servicios: | C45: =+SUM(C46:C54) -> 0 | D45: =+IF(ISERROR(C45/C56),"N. D.",C45/C56) -> 0 | F45: =+SUM(F46:F54) -> 0 | G45: =+IF(ISERROR(F45/F56),"N. D.",F45/F56) -> 0 | H45: =+$C45-F45 -> 0 | I45: =+IF(ISERROR(H45/F45),"N. D.",H45/F45) -> N. D. | K45: =+SUM(K46:K54) -> 0 | L45: =+IF(ISERROR(K45/K56),"N. D.",K45/K56) -> 0 | M45: =+$C45-K45 -> 0 | N45: =+IF(ISERROR(M45/K45),"N. D.",M45/K45) -> N. D. | P45: =+SUM(P46:P54) -> 0 | Q45: =+IF(ISERROR(P45/P56),"N. D.",P45/P56) -> 0 | R45: =+$C45-P45 -> 0 | S45: =+IF(ISERROR(R45/P45),"N. D.",R45/P45) -> N. D. | U45: =+SUM(U46:U54) -> 0 | V45: =+IF(ISERROR(U45/U56),"N. D.",U45/U56) -> 0 | W45: =+$C45-U45 -> 0 | X45: =+IF(ISERROR(W45/U45),"N. D.",W45/U45) -> N. D.
A46: Administración de Nómina | C46: 0 | D46: =+IF(ISERROR(C46/C96),"N. D.",C46/C96) -> N. D. | F46: 0 | G46: =+IF(ISERROR(F46/F96),"N. D.",F46/F96) -> N. D. | H46: =+$C46-F46 -> 0 | I46: =+IF(ISERROR(H46/F46),"N. D.",H46/F46) -> N. D. | K46: 0 | L46: =+IF(ISERROR(K46/K96),"N. D.",K46/K96) -> N. D. | M46: =+$C46-K46 -> 0 | N46: =+IF(ISERROR(M46/K46),"N. D.",M46/K46) -> N. D. | P46: 0 | Q46: =+IF(ISERROR(P46/P96),"N. D.",P46/P96) -> N. D. | R46: =+$C46-P46 -> 0 | S46: =+IF(ISERROR(R46/P46),"N. D.",R46/P46) -> N. D. | U46: 0 | V46: =+IF(ISERROR(U46/U96),"N. D.",U46/U96) -> N. D. | W46: =+$C46-U46 -> 0 | X46: =+IF(ISERROR(W46/U46),"N. D.",W46/U46) -> N. D.
A47: Apertura/Cierre de Contratos | C47: 0 | D47: =+IF(ISERROR(C47/C97),"N. D.",C47/C97) -> N. D. | F47: 0 | G47: =+IF(ISERROR(F47/F97),"N. D.",F47/F97) -> N. D. | H47: =+$C47-F47 -> 0 | I47: =+IF(ISERROR(H47/F47),"N. D.",H47/F47) -> N. D. | K47: 0 | L47: =+IF(ISERROR(K47/K97),"N. D.",K47/K97) -> N. D. | M47: =+$C47-K47 -> 0 | N47: =+IF(ISERROR(M47/K47),"N. D.",M47/K47) -> N. D. | P47: 0 | Q47: =+IF(ISERROR(P47/P97),"N. D.",P47/P97) -> N. D. | R47: =+$C47-P47 -> 0 | S47: =+IF(ISERROR(R47/P47),"N. D.",R47/P47) -> N. D. | U47: 0 | V47: =+IF(ISERROR(U47/U97),"N. D.",U47/U97) -> N. D. | W47: =+$C47-U47 -> 0 | X47: =+IF(ISERROR(W47/U47),"N. D.",W47/U47) -> N. D.
A48: Renovación de Contratos | C48: 0 | D48: =+IF(ISERROR(C48/C98),"N. D.",C48/C98) -> N. D. | F48: 0 | G48: =+IF(ISERROR(F48/F98),"N. D.",F48/F98) -> N. D. | H48: =+$C48-F48 -> 0 | I48: =+IF(ISERROR(H48/F48),"N. D.",H48/F48) -> N. D. | K48: 0 | L48: =+IF(ISERROR(K48/K98),"N. D.",K48/K98) -> N. D. | M48: =+$C48-K48 -> 0 | N48: =+IF(ISERROR(M48/K48),"N. D.",M48/K48) -> N. D. | P48: 0 | Q48: =+IF(ISERROR(P48/P98),"N. D.",P48/P98) -> N. D. | R48: =+$C48-P48 -> 0 | S48: =+IF(ISERROR(R48/P48),"N. D.",R48/P48) -> N. D. | U48: 0 | V48: =+IF(ISERROR(U48/U98),"N. D.",U48/U98) -> N. D. | W48: =+$C48-U48 -> 0 | X48: =+IF(ISERROR(W48/U48),"N. D.",W48/U48) -> N. D.
...

Sheet 2026P
C2: MENSUAL | S2: ACUMULADO
A5: ESTADO DE RESULTADOS | C5: P2K | D5: PSP | E5: PRG | F5: PC | G5: PLA | H5: PSI | I5: PPA | J5: PPB | K5: CBA | L5: TORR | M5: HOT | N5: PV | O5: DEPTOS | P5: PLP | Q5: PE | S5: P2K | T5: PSP | U5: PRG | V5: PC | W5: PLA | X5: PSI | Y5: PPA | Z5: PPB | AA5: CBA | AB5: TORR | AC5: HOT | AD5: PV | AE5: DEPTOS | AF5: PLP | AG5: PE | AI5: TOTAL | AJ5: TOTAL
A6: 2026P | AI6: MENSUAL | AJ6: ACUMULADO
A8: INGRESOS BRUTOS
A10: Ingresos por Operación de Plazas: | C10: =+SUM(C11:C19) -> 17030565 | D10: =+SUM(D11:D19) -> 10366156 | E10: =+SUM(E11:E19) -> 10888271 | F10: =+SUM(F11:F19) -> 878182.57 | G10: =+SUM(G11:G19) -> 0 | H10: =+SUM(H11:H19) -> 5814505.6 | I10: =+SUM(I11:I19) -> 1107544.9 | J10: =+SUM(J11:J19) -> 0 | ... Q10: =+SUM(Q11:Q19) -> 2316478.4 | S10: =+SUM(S11:S19) -> 96097240 | T10: =+SUM(T11:T19) -> 57983340 | U10: =+SUM(U11:U19) -> 63888277 | V10: =+SUM(V11:V19) -> 5158569.2 | W10: =+SUM(W11:W19) -> 0 | X10: =+SUM(X11:X19) -> 34142898 | Y10: =+SUM(Y11:Y19) -> 6041278.8 | Z10: =+SUM(Z11:Z19) -> 0 | ... AG10: =+SUM(AG11:AG19) -> 14408583 | AI10: =+SUM(AI11:AI19) -> 82481643 | AJ10: =+SUM(AJ11:AJ19) -> 4.7780709e+08
A11: Renta Mínima | C11: 10447173 | D11: 6660185 | E11: 8048538.4 | F11: 753371.17 | G11: 0 | H11: 4530714.4 | I11: 888433.2 | J11: 0 | K11: 7128167.8 | L11: 7150033 | M11: 416514.23 | N11: 5576387.1 | O11: 0 | P11: 1960687.3 | Q11: 1670117.6 | S11: 60754716 | T11: 38997584 | U11: 47740380 | V11: 4460732.8 | W11: 0 | X11: 26670084 | Y11: 5227015.1 | Z11: 0 | AA11: 41806192 | AB11: 42273569 | AC11: 2493454.5 | AD11: 32008726 | AE11: 0 | AF11: 11664485 | AG11: 9969443.3 | AI11: =+SUM(C11:Q11) -> 55230322 | AJ11: =+SUM(S11:AG11) -> 3.2406638e+08
A12: Renta Variable | C12: 1632424.5 | D12: 930917.75 | E12: 431731.42 | F12: 36095.693 | G12: 0 | H12: 50275.906 | I12: 116061.26 | J12: 0 | K12: 2951270.3 | L12: 405024.22 | M12: 462160 | N12: 811618.5 | O12: 0 | P12: 79138.997 | Q12: 375410.27 | S12: 6891213.6 | T12: 2947253.3 | U12: 2750351.5 | V12: 177440.95 | W12: 0 | X12: 566607.55 | Y12: 216084.25 | Z12: 0 | AA12: 18818463 | AB12: 2534091.2 | AC12: 3534533 | AD12: 2879190.6 | AE12: 0 | AF12: 440555.55 | AG12: 2776823.8 | AI12: =+SUM(C12:Q12) -> 8282128.9 | AJ12: =+SUM(S12:AG12) -> 44532608
A13: Cuota de Mantenimiento | C13: 1380058.4 | D13: 934548.12 | E13: 1093709.1 | F13: 86270.547 | G13: 0 | H13: 602917.35 | I13: 103050.48 | J13: 0 | K13: 1235489.8 | L13: 957861.69 | M13: 16651.423 | N13: 792080.76 | O13: 0 | P13: 300344 | Q13: 270950.55 | S13: 8033909 | T13: 5456779.4 | U13: 6482638.7 | V13: 505724.45 | W13: 0 | X13: 3581970.9 | Y13: 598179.49 | Z13: 0 | AA13: 7230183.9 | AB13: 5664654.4 | AC13: 99345.448 | AD13: 4532528.9 | AE13: 0 | AF13: 1769199.6 | AG13: 1662316.2 | AI13: =+SUM(C13:Q13) -> 7773932.2 | AJ13: =+SUM(S13:AG13) -> 45617430
A14: Publicidad | C14: 21434.397 | D14: 0 | E14: 13043.385 | F14: 2445.1647 | G14: 0 | H14: 2891.423 | I14: 0 | J14: 0 | K14: 0 | L14: 0 | M14: 0 | N14: 0 | O14: 0 | P14: 521.68626 | Q14: 0 | S14: 128606.38 | T14: 0 | U14: 78260.307 | V14: 14670.988 | W14: 0 | X14: 17348.538 | Y14: 0 | Z14: 0 | AA14: 0 | AB14: 0 | AC14: 0 | AD14: 0 | AE14: 0 | AF14: 3130.1176 | AG14: 0 | AI14: =+SUM(C14:Q14) -> 40336.055 | AJ14: =+SUM(S14:AG14) -> 242016.33
A15: Estacionamiento | C15: 3511434.6 | D15: 1826234.9 | E15: 1285428.9 | F15: 0 | G15: 0 | H15: 624489.6 | I15: 0 | J15: 0 | K15: 2210917 | L15: 0 | M15: 0 | N15: 1129810.5 | O15: 0 | P15: 0 | Q15: 0 | S15: 20041883 | T15: 10496100 | U15: 6741727.1 | V15: 0 | W15: 0 | X15: 3287585.2 | Y15: 0 | Z15: 0 | AA15: 12476577 | AB15: 0 | AC15: 0 | AD15: 6696350.6 | AE15: 0 | AF15: 0 | AG15: 0 | AI15: =+SUM(C15:Q15) -> 10588316 | AJ15: =+SUM(S15:AG15) -> 59740223
A16: Cuotas Condominales | C16: 0 | D16: 0 | E16: 0 | F16: 0 | G16: 0 | H16: 0 | I16: 0 | J16: 0 | K16: 0 | L16: 0 | M16: 0 | N16: 44486.447 | O16: 86447.167 | P16: 148558.08 | Q16: 0 | S16: 0 | T16: 0 | U16: 0 | V16: 0 | W16: 0 | X16: 0 | Y16: 0 | Z16: 0 | AA16: 0 | AB16: 0 | AC16: 0 | AD16: 270946.87 | AE16: 379212 | AF16: 981319.84 | AG16: 0 | AI16: =+SUM(C16:Q16) -> 279491.69 | AJ16: =+SUM(S16:AG16) -> 1631478.7
A17: Guantes | C17: 38040.223 | D17: 14270.551 | E17: 15819.824 | F17: 0 | G17: 0 | H17: 3216.9621 | I17: 0 | J17: 0 | K17: 163075.96 | L17: 0 | M17: 0 | N17: 1739.95 | O17: 0 | P17: 1452.4 | Q17: 0 | S17: 246912.44 | T17: 85623.306 | U17: 94918.943 | V17: 0 | W17: 0 | X17: 19301.773 | Y17: 0 | Z17: 0 | AA17: 978455.75 | AB17: 0 | AC17: 0 | AD17: 10439.7 | AE17: 0 | AF17: 8714.4 | AG17: 0 | AI17: =+SUM(C17:Q17) -> 237615.87 | AJ17: =+SUM(S17:AG17) -> 1444366.3
A18: Penalizaciones | C18: 0 | D18: 0 | E18: 0 | F18: 0 | G18: 0 | H18: 0 | I18: 0 | J18: 0 | K18: 0 | L18: 0 | M18: 0 | N18: 0 | O18: 0 | P18: 0 | Q18: 0 | S18: 0 | T18: 0 | U18: 0 | V18: 0 | W18: 0 | X18: 0 | Y18: 0 | Z18: 0 | AA18: 0 | AB18: 0 | AC18: 0 | AD18: 0 | AE18: 0 | AF18: 0 | AG18: 0 | AI18: =+SUM(C18:Q18) -> 0 | AJ18: =+SUM(S18:AG18) -> 0
A19: Otros Ingresos Operativos de Plazas | C19: 0 | D19: 0 | E19: 0 | F19: 0 | G19: 0 | H19: 0 | I19: 0 | J19: 0 | K19: 49500 | L19: 0 | M19: 0 | N19: 0 | O19: 0 | P19: 0 | Q19: 0 | S19: 0 | T19: 0 | U19: 0 | V19: 0 | W19: 0 | X19: 0 | Y19: 0 | Z19: 0 | AA19: 532588 | AB19: 0 | AC19: 0 | AD19: 0 | AE19: 0 | AF19: 0 | AG19: 0 | AI19: =+SUM(C19:Q19) -> 49500 | AJ19: =+SUM(S19:AG19) -> 532588
A20: Ingresos por Servicios: | C20: =+SUM(C21:C29) -> 0 | D20: =+SUM(D21:D29) -> 0 | E20: =+SUM(E21:E29) -> 0 | F20: =+SUM(F21:F29) -> 0 | G20: =+SUM(G21:G29) -> 0 | H20: =+SUM(H21:H29) -> 0 | I20: =+SUM(I21:I29) -> 0 | J20: =+SUM(J21:J29) -> 0 | ... Q20: =+SUM(Q21:Q29) -> 0 | S20: =+SUM(S21:S29) -> 0 | T20: =+SUM(T21:T29) -> 0 | U20: =+SUM(U21:U29) -> 0 | V20: =+SUM(V21:V29) -> 0 | W20: =+SUM(W21:W29) -> 0 | X20: =+SUM(X21:X29) -> 0 | Y20: =+SUM(Y21:Y29) -> 0 | Z20: =+SUM(Z21:Z29) -> 0 | ... AG20: =+SUM(AG21:AG29) -> 0 | AI20: =+SUM(AI21:AI29) -> 0 | AJ20: =+SUM(AJ21:AJ29) -> 0
A21: Administración de Nómina | C21: 0 | D21: 0 | E21: 0 | F21: 0 | G21: 0 | H21: 0 | I21: 0 | J21: 0 | K21: 0 | L21: 0 | M21: 0 | N21: 0 | O21: 0 | P21: 0 | Q21: 0 | S21: 0 | T21: 0 | U21: 0 | V21: 0 | W21: 0 | X21: 0 | Y21: 0 | Z21: 0 | AA21: 0 | AB21: 0 | AC21: 0 | AD21: 0 | AE21: 0 | AF21: 0 | AG21: 0 | AI21: =+SUM(R21:AF21) -> 0 | AJ21: =+SUM(S21:AG21) -> 0
A22: Apertura/Cierre de Contratos | C22: 0 | D22: 0 | E22: 0 | F22: 0 | G22: 0 | H22: 0 | I22: 0 | J22: 0 | K22: 0 | L22: 0 | M22: 0 | N22: 0 | O22: 0 | P22: 0 | Q22: 0 | S22: 0 | T22: 0 | U22: 0 | V22: 0 | W22: 0 | X22: 0 | Y22: 0 | Z22: 0 | AA22: 0 | AB22: 0 | AC22: 0 | AD22: 0 | AE22: 0 | AF22: 0 | AG22: 0 | AI22: =+SUM(R22:AF22) -> 0 | AJ22: =+SUM(S22:AG22) -> 0
A23: Renovación de Contratos | C23: 0 | D23: 0 | E23: 0 | F23: 0 | G23: 0 | H23: 0 | I23: 0 | J23: 0 | K23: 0 | L23: 0 | M23: 0 | N23: 0 | O23: 0 | P23: 0 | Q23: 0 | S23: 0 | T23: 0 | U23: 0 | V23: 0 | W23: 0 | X23: 0 | Y23: 0 | Z23: 0 | AA23: 0 | AB23: 0 | AC23: 0 | AD23: 0 | AE23: 0 | AF23: 0 | AG23: 0 | AI23: =+SUM(R23:AF23) -> 0 | AJ23: =+SUM(S23:AG23) -> 0
A24: Administración de Obra | C24: 0 | D24: 0 | E24: 0 | F24: 0 | G24: 0 | H24: 0 | I24: 0 | J24: 0 | K24: 0 | L24: 0 | M24: 0 | N24: 0 | O24: 0 | P24: 0 | Q24: 0 | S24: 0 | T24: 0 | U24: 0 | V24: 0 | W24: 0 | X24: 0 | Y24: 0 | Z24: 0 | AA24: 0 | AB24: 0 | AC24: 0 | AD24: 0 | AE24: 0 | AF24: 0 | AG24: 0 | AI24: =+SUM(R24:AF24) -> 0 | AJ24: =+SUM(S24:AG24) -> 0
A25: Administración de Plaza | C25: 0 | D25: 0 | E25: 0 | F25: 0 | G25: 0 | H25: 0 | I25: 0 | J25: 0 | K25: 0 | L25: 0 | M25: 0 | N25: 0 | O25: 0 | P25: 0 | Q25: 0 | S25: 0 | T25: 0 | U25: 0 | V25: 0 | W25: 0 | X25: 0 | Y25: 0 | Z25: 0 | AA25: 0 | AB25: 0 | AC25: 0 | AD25: 0 | AE25: 0 | AF25: 0 | AG25: 0 | AI25: =+SUM(R25:AF25) -> 0 | AJ25: =+SUM(S25:AG25) -> 0
A26: Consultoría | C26: 0 | D26: 0 | E26: 0 | F26: 0 | G26: 0 | H26: 0 | I26: 0 | J26: 0 | K26: 0 | L26: 0 | M26: 0 | N26: 0 | O26: 0 | P26: 0 | Q26: 0 | S26: 0 | T26: 0 | U26: 0 | V26: 0 | W26: 0 | X26: 0 | Y26: 0 | Z26: 0 | AA26: 0 | AB26: 0 | AC26: 0 | AD26: 0 | AE26: 0 | AF26: 0 | AG26: 0 | AI26: =+SUM(R26:AF26) -> 0 | AJ26: =+SUM(S26:AG26) -> 0
A27: Renta de Terrenos | C27: 0 | D27: 0 | E27: 0 | F27: 0 | G27: 0 | H27: 0 | I27: 0 | J27: 0 | K27: 0 | L27: 0 | M27: 0 | N27: 0 | O27: 0 | P27: 0 | Q27: 0 | S27: 0 | T27: 0 | U27: 0 | V27: 0 | W27: 0 | X27: 0 | Y27: 0 | Z27: 0 | AA27: 0 | AB27: 0 | AC27: 0 | AD27: 0 | AE27: 0 | AF27: 0 | AG27: 0 | AI27: =+SUM(R27:AF27) -> 0 | AJ27: =+SUM(S27:AG27) -> 0
A28: Operación de Hotel | C28: 0 | D28: 0 | E28: 0 | F28: 0 | G28: 0 | H28: 0 | I28: 0 | J28: 0 | K28: 0 | L28: 0 | M28: 0 | N28: 0 | O28: 0 | P28: 0 | Q28: 0 | S28: 0 | T28: 0 | U28: 0 | V28: 0 | W28: 0 | X28: 0 | Y28: 0 | Z28: 0 | AA28: 0 | AB28: 0 | AC28: 0 | AD28: 0 | AE28: 0 | AF28: 0 | AG28: 0 | AI28: =+SUM(R28:AF28) -> 0 | AJ28: =+SUM(S28:AG28) -> 0
A29: Otros Servicios | C29: 0 | D29: 0 | E29: 0 | F29: 0 | G29: 0 | H29: 0 | I29: 0 | J29: 0 | K29: 0 | L29: 0 | M29: 0 | N29: 0 | O29: 0 | P29: 0 | Q29: 0 | S29: 0 | T29: 0 | U29: 0 | V29: 0 | W29: 0 | X29: 0 | Y29: 0 | Z29: 0 | AA29: 0 | AB29: 0 | AC29: 0 | AD29: 0 | AE29: 0 | AF29: 0 | AG29: 0 | AI29: =+SUM(R29:AF29) -> 0 | AJ29: =+SUM(S29:AG29) -> 0
A31: Total Ingresos Brutos | C31: =+C10+C20 -> 17030565 | D31: =+D10+D20 -> 10366156 | E31: =+E10+E20 -> 10888271 | F31: =+F10+F20 -> 878182.57 | G31: =+G10+G20 -> 0 | H31: =+H10+H20 -> 5814505.6 | I31: =+I10+I20 -> 1107544.9 | J31: =+J10+J20 -> 0 | ... Q31: =+Q10+Q20 -> 2316478.4 | S31: =+S10+S20 -> 96097240 | T31: =+T10+T20 -> 57983340 | U31: =+U10+U20 -> 63888277 | V31: =+V10+V20 -> 5158569.2 | W31: =+W10+W20 -> 0 | X31: =+X10+X20 -> 34142898 | Y31: =+Y10+Y20 -> 6041278.8 | Z31: =+Z10+Z20 -> 0 | ... AG31: =+AG10+AG20 -> 14408583 | AI31: =+AI10+AI20 -> 82481643 | AJ31: =+AJ10+AJ20 -> 4.7780709e+08
A33: BONIFICACIONES SOBRE INGRESOS
A35: Ingresos por Operación de Plazas: | C35: =+SUM(C36:C44) -> 0 | D35: =+SUM(D36:D44) -> 0 | E35: =+SUM(E36:E44) -> 0 | F35: =+SUM(F36:F44) -> 0 | G35: =+SUM(G36:G44) -> 0 | H35: =+SUM(H36:H44) -> 15410 | I35: =+SUM(I36:I44) -> 0 | J35: =+SUM(J36:J44) -> 0 | ... Q35: =+SUM(Q36:Q44) -> 0 | S35: =+SUM(S36:S44) -> 0 | T35: =+SUM(T36:T44) -> 0 | U35: =+SUM(U36:U44) -> 0 | V35: =+SUM(V36:V44) -> 0 | W35: =+SUM(W36:W44) -> 0 | X35: =+SUM(X36:X44) -> 811348 | Y35: =+SUM(Y36:Y44) -> 0 | Z35: =+SUM(Z36:Z44) -> 0 | ... AG35: =+SUM(AG36:AG44) -> 0 | AI35: =+SUM(AI36:AI44) -> 182790.79 | AJ35: =+SUM(AJ36:AJ44) -> 2841644.6
A36: Renta Mínima | C36: 0 | D36: 0 | E36: 0 | F36: 0 | G36: 0 | H36: 15410 | I36: 0 | J36: 0 | K36: 0 | L36: 0 | M36: 0 | N36: 167380.79 | O36: 0 | P36: 0 | Q36: 0 | S36: 0 | T36: 0 | U36: 0 | V36: 0 | W36: 0 | X36: 811348 | Y36: 0 | Z36: 0 | AA36: 556490.16 | AB36: 0 | AC36: 0 | AD36: 1473806.5 | AE36: 0 | AF36: 0 | AG36: 0 | AI36: =+SUM(C36:Q36) -> 182790.79 | AJ36: =+SUM(S36:AG36) -> 2841644.6
A37: Renta Variable | C37: 0 | D37: 0 | E37: 0 | F37: 0 | G37: 0 | H37: 0 | I37: 0 | J37: 0 | K37: 0 | L37: 0 | M37: 0 | N37: 0 | O37: 0 | P37: 0 | Q37: 0 | S37: 0 | T37: 0 | U37: 0 | V37: 0 | W37: 0 | X37: 0 | Y37: 0 | Z37: 0 | AA37: 0 | AB37: 0 | AC37: 0 | AD37: 0 | AE37: 0 | AF37: 0 | AG37: 0 | AI37: =+SUM(C37:Q37) -> 0 | AJ37: =+SUM(S37:AG37) -> 0
A38: Cuota de Mantenimiento | C38: 0 | D38: 0 | E38: 0 | F38: 0 | G38: 0 | H38: 0 | I38: 0 | J38: 0 | K38: 0 | L38: 0 | M38: 0 | N38: 0 | O38: 0 | P38: 0 | Q38: 0 | S38: 0 | T38: 0 | U38: 0 | V38: 0 | W38: 0 | X38: 0 | Y38: 0 | Z38: 0 | AA38: 0 | AB38: 0 | AC38: 0 | AD38: 0 | AE38: 0 | AF38: 0 | AG38: 0 | AI38: =+SUM(C38:Q38) -> 0 | AJ38: =+SUM(S38:AG38) -> 0
A39: Publicidad | C39: 0 | D39: 0 | E39: 0 | F39: 0 | G39: 0 | H39: 0 | I39: 0 | J39: 0 | K39: 0 | L39: 0 | M39: 0 | N39: 0 | O39: 0 | P39: 0 | Q39: 0 | S39: 0 | T39: 0 | U39: 0 | V39: 0 | W39: 0 | X39: 0 | Y39: 0 | Z39: 0 | AA39: 0 | AB39: 0 | AC39: 0 | AD39: 0 | AE39: 0 | AF39: 0 | AG39: 0 | AI39: =+SUM(C39:Q39) -> 0 | AJ39: =+SUM(S39:AG39) -> 0
A40: Estacionamiento | C40: 0 | D40: 0 | E40: 0 | F40: 0 | G40: 0 | H40: 0 | I40: 0 | J40: 0 | K40: 0 | L40: 0 | M40: 0 | N40: 0 | O40: 0 | P40: 0 | Q40: 0 | S40: 0 | T40: 0 | U40: 0 | V40: 0 | W40: 0 | X40: 0 | Y40: 0 | Z40: 0 | AA40: 0 | AB40: 0 | AC40: 0 | AD40: 0 | AE40: 0 | AF40: 0 | AG40: 0 | AI40: =+SUM(C40:Q40) -> 0 | AJ40: =+SUM(S40:AG40) -> 0
A41: Cuotas Condominales | C41: 0 | D41: 0 | E41: 0 | F41: 0 | G41: 0 | H41: 0 | I41: 0 | J41: 0 | K41: 0 | L41: 0 | M41: 0 | N41: 0 | O41: 0 | P41: 0 | Q41: 0 | S41: 0 | T41: 0 | U41: 0 | V41: 0 | W41: 0 | X41: 0 | Y41: 0 | Z41: 0 | AA41: 0 | AB41: 0 | AC41: 0 | AD41: 0 | AE41: 0 | AF41: 0 | AG41: 0 | AI41: =+SUM(C41:Q41) -> 0 | AJ41: =+SUM(S41:AG41) -> 0
A42: Guantes | C42: 0 | D42: 0 | E42: 0 | F42: 0 | G42: 0 | H42: 0 | I42: 0 | J42: 0 | K42: 0 | L42: 0 | M42: 0 | N42: 0 | O42: 0 | P42: 0 | Q42: 0 | S42: 0 | T42: 0 | U42: 0 | V42: 0 | W42: 0 | X42: 0 | Y42: 0 | Z42: 0 | AA42: 0 | AB42: 0 | AC42: 0 | AD42: 0 | AE42: 0 | AF42: 0 | AG42: 0 | AI42: =+SUM(C42:Q42) -> 0 | AJ42: =+SUM(S42:AG42) -> 0
A43: Penalizaciones | C43: 0 | D43: 0 | E43: 0 | F43: 0 | G43: 0 | H43: 0 | I43: 0 | J43: 0 | K43: 0 | L43: 0 | M43: 0 | N43: 0 | O43: 0 | P43: 0 | Q43: 0 | S43: 0 | T43: 0 | U43: 0 | V43: 0 | W43: 0 | X43: 0 | Y43: 0 | Z43: 0 | AA43: 0 | AB43: 0 | AC43: 0 | AD43: 0 | AE43: 0 | AF43: 0 | AG43: 0 | AI43: =+SUM(C43:Q43) -> 0 | AJ43: =+SUM(S43:AG43) -> 0
A44: Otros Ingresos Operativos de Plazas | C44: 0 | D44: 0 | E44: 0 | F44: 0 | G44: 0 | H44: 0 | I44: 0 | J44: 0 | K44: 0 | L44: 0 | M44: 0 | N44: 0 | O44: 0 | P44: 0 | Q44: 0 | S44: 0 | T44: 0 | U44: 0 | V44: 0 | W44: 0 | X44: 0 | Y44: 0 | Z44: 0 | AA44: 0 | AB44: 0 | AC44: 0 | AD44: 0 | AE44: 0 | AF44: 0 | AG44: 0 | AI44: =+SUM(C44:Q44) -> 0 | AJ44: =+SUM(S44:AG44) -> 0
A45: Ingresos por Servicios: | C45: =+SUM(C46:C54) -> 0 | D45: =+SUM(D46:D54) -> 0 | E45: =+SUM(E46:E54) -> 0 | F45: =+SUM(F46:F54) -> 0 | G45: =+SUM(G46:G54) -> 0 | H45: =+SUM(H46:H54) -> 0 | I45: =+SUM(I46:I54) -> 0 | J45: =+SUM(J46:J54) -> 0 | ... Q45: =+SUM(Q46:Q54) -> 0 | S45: =+SUM(S46:S54) -> 0 | T45: =+SUM(T46:T54) -> 0 | U45: =+SUM(U46:U54) -> 0 | V45: =+SUM(V46:V54) -> 0 | W45: =+SUM(W46:W54) -> 0 | X45: =+SUM(X46:X54) -> 0 | Y45: =+SUM(Y46:Y54) -> 0 | Z45: =+SUM(Z46:Z54) -> 0 | ... AG45: =+SUM(AG46:AG54) -> 0 | AI45: =+SUM(AI46:AI54) -> 0 | AJ45: =+SUM(AJ46:AJ54) -> 0
A46: Administración de Nómina | C46: 0 | D46: 0 | E46: 0 | F46: 0 | G46: 0 | H46: 0 | I46: 0 | J46: 0 | K46: 0 | L46: 0 | M46: 0 | N46: 0 | O46: 0 | P46: 0 | Q46: 0 | S46: 0 | T46: 0 | U46: 0 | V46: 0 | W46: 0 | X46: 0 | Y46: 0 | Z46: 0 | AA46: 0 | AB46: 0 | AC46: 0 | AD46: 0 | AE46: 0 | AF46: 0 | AG46: 0 | AI46: =+SUM(R46:AF46) -> 0 | AJ46: =+SUM(S46:AG46) -> 0
A47: Apertura/Cierre de Contratos | C47: 0 | D47: 0 | E47: 0 | F47: 0 | G47: 0 | H47: 0 | I47: 0 | J47: 0 | K47: 0 | L47: 0 | M47: 0 | N47: 0 | O47: 0 | P47: 0 | Q47: 0 | S47: 0 | T47: 0 | U47: 0 | V47: 0 | W47: 0 | X47: 0 | Y47: 0 | Z47: 0 | AA47: 0 | AB47: 0 | AC47: 0 | AD47: 0 | AE47: 0 | AF47: 0 | AG47: 0 | AI47: =+SUM(R47:AF47) -> 0 | AJ47: =+SUM(S47:AG47) -> 0
A48: Renovación de Contratos | C48: 0 | D48: 0 | E48: 0 | F48: 0 | G48: 0 | H48: 0 | I48: 0 | J48: 0 | K48: 0 | L48: 0 | M48: 0 | N48: 0 | O48: 0 | P48: 0 | Q48: 0 | S48: 0 | T48: 0 | U48: 0 | V48: 0 | W48: 0 | X48: 0 | Y48: 0 | Z48: 0 | AA48: 0 | AB48: 0 | AC48: 0 | AD48: 0 | AE48: 0 | AF48: 0 | AG48: 0 | AI48: =+SUM(R48:AF48) -> 0 | AJ48: =+SUM(S48:AG48) -> 0
...

Sheet 2025R
C2: MENSUAL | S2: ACUMULADO
A5: ESTADO DE RESULTADOS | C5: P2K | D5: PSP | E5: PRG | F5: PC | G5: PLA | H5: PSI | I5: PPA | J5: PPB | K5: CBA | L5: TORR | M5: HOT | N5: PV | O5: DEPTOS | P5: PLP | Q5: PE | S5: P2K | T5: PSP | U5: PRG | V5: PC | W5: PLA | X5: PSI | Y5: PPA | Z5: PPB | AA5: CBA | AB5: TORR | AC5: HOT | AD5: PV | AE5: DEPTOS | AF5: PLP | AG5: PE | AI5: TOTAL | AJ5: TOTAL
A6: 2025R | AI6: MENSUAL | AJ6: ACUMULADO
A8: INGRESOS BRUTOS
A10: Ingresos por Operación de Plazas: | C10: =+SUM(C11:C19) -> 15568235 | D10: =+SUM(D11:D19) -> 9232008.4 | E10: =+SUM(E11:E19) -> 11497740 | F10: =+SUM(F11:F19) -> 620657.56 | G10: =+SUM(G11:G19) -> 0 | H10: =+SUM(H11:H19) -> 5217715.4 | I10: =+SUM(I11:I19) -> 1041623.9 | J10: =+SUM(J11:J19) -> 0 | ... Q10: =+SUM(Q11:Q19) -> 2204930.6 | S10: =+SUM(S11:S19) -> 88848494 | T10: =+SUM(T11:T19) -> 51757584 | U10: =+SUM(U11:U19) -> 59889617 | V10: =+SUM(V11:V19) -> 3718216.2 | W10: =+SUM(W11:W19) -> 0 | X10: =+SUM(X11:X19) -> 32212173 | Y10: =+SUM(Y11:Y19) -> 5764997 | Z10: =+SUM(Z11:Z19) -> 0 | ... AG10: =+SUM(AG11:AG19) -> 13896058 | AI10: =+SUM(AI11:AI19) -> 75483465 | AJ10: =+SUM(AJ11:AJ19) -> 4.3424599e+08
